Workbook
Name AJUSTE_MANUAL_VTA: MEMORIA_RESULTADOS!$B$24
Name AJUSTES_DEVIDOS: RESULTADOS!$B$84
Name AUDITORIA_ABERTURA_STATUS: RESULTADOS!$H$11
Name AUDITORIA_COMPARATIVO_INTEGRAL: comparativo_VTA!$B$208
Name AUDITORIA_CONFERENCIA_STATUS: MEMORIA_RESULTADOS!$W$52
Name AUDITORIA_DIFERENCA_REFERENCIAS: MEMORIA_RESULTADOS!$W$51
Name AUDITORIA_SITUACAO_ATUAL_CONTRATO: MEMORIA_RESULTADOS!$W$50
Name AUDITORIA_SITUACAO_ATUAL_STATUS: RESULTADOS!$H$10
Name AUDITORIA_ULTIMA_REFERENCIA_ABERTURA: MEMORIA_RESULTADOS!$W$48
Name CICLO_EM_EXECUCAO_LAYOUT_VERSION: CICLO_EM_EXECUCAO!$H$2
Name CONFERENCIA_FORMACAO_VTA: RESULTADOS!$B$87
Name EXECUCAO_ATUALIZADA_CICLO: RESULTADOS!$B$36
Name EXECUTADO_APURADO: RESULTADOS!$B$83
Name JUSTIFICATIVA_RETRO: MEMORIA_RESULTADOS!$D$5
Name METODO_RETROATIVO: MEMORIA_RESULTADOS!$B$4
Name OPCOES_APLICAR_MANUAL: RESULTADOS!$J$2:$J$3
Name OPCOES_SIM_NAO: parametros!$T$2:$T$3
Name OPCOES_SIM_NAO_NA: parametros!$T$2:$T$4
Name PC_TOTAL_ATE_CORTE: MEMORIA_RESULTADOS!$T$34
Name PC_TOTAL_CADASTRADO: MEMORIA_RESULTADOS!$T$33
Name PC_TOTAL_COM_EFEITO: MEMORIA_RESULTADOS!$T$36
Name PC_TOTAL_SEM_EFEITO: MEMORIA_RESULTADOS!$T$37
Name QTD_REM_OFICIAL: MEMORIA_RESULTADOS!$B$35
Name REM_ATUALIZADO_OFICIAL: MEMORIA_RESULTADOS!$D$35
Name REM_BASE_OFICIAL: MEMORIA_RESULTADOS!$C$35
Name RETRO_FIN: MEMORIA_RESULTADOS!$B$15
Name RETRO_ITENS: MEMORIA_RESULTADOS!$D$15
Name RETRO_OFICIAL: MEMORIA_RESULTADOS!$B$16
Name RETRO_PC: MEMORIA_RESULTADOS!$C$15
Name RETROATIVO_POTENCIAL_APURADO: MEMORIA_RESULTADOS!$T$41
Name RETROATIVO_POTENCIAL_NEGATIVO: MEMORIA_RESULTADOS!$T$47
Name RETROATIVO_POTENCIAL_PC: MEMORIA_RESULTADOS!$T$38
Name RETROATIVO_POTENCIAL_VTA: MEMORIA_RESULTADOS!$T$39
Name SALDO_REMANESCENTE_ATUAL: RESULTADOS!$B$38
Name STATUS_RESULTADOS: RESULTADOS!$B$3
Name TOLERANCIA_DIVERGENCIA: MEMORIA_RESULTADOS!$D$4
Name VALOR_MANUAL_RETRO: MEMORIA_RESULTADOS!$B$5
Name VTA_ATUALIZACAO_CHEIA: RESULTADOS!$B$12
Name VTA_CALCULADO: MEMORIA_RESULTADOS!$B$23
Name VTA_FINAL: MEMORIA_RESULTADOS!$B$26
Name VTA_MANUAL_OFICIAL: MEMORIA_RESULTADOS!$B$25
Name VTA_SEM_POTENCIAL: MEMORIA_RESULTADOS!$T$40

Sheet comparativo_VTA
A1: comparativo_VTA - REFERENCIA (nao aparece na web; nao e VTA de pagamento)
A2: BLOCO 1 - EVOLUCAO DO REMANESCENTE A PRECOS ORIGINAIS (sem reajuste)
A3: ITEM | B3: VU_ORIGINAL | C3: C0 | D3: C1 | E3: C2 | F3: C3 | G3: C4
A4: =IF(posicao_contratual!A2="","",posicao_contratual!A2) -> ITEM-001 | B4: =IF(posicao_contratual!A2="","",posicao_contratual!B2) -> 250 | C4: =IF(OR(posicao_contratual!A2="",NOT(ISNUMBER(posicao_contratual!B2)),NOT(ISNUMBER(posicao_contratual!G2))),"",ROUND(posicao_contratual!B2*posicao_contratual!G2,2)) -> 30000 | D4: =IF(OR(posicao_contratual!A2="",NOT(ISNUMBER(posicao_contratual!B2)),NOT(ISNUMBER(posicao_contratual!K2))),"",ROUND(posicao_contratual!B2*posicao_contratual!K2,2)) -> 30000 | E4: =IF(OR(posicao_contratual!A2="",NOT(ISNUMBER(posicao_contratual!B2)),NOT(ISNUMBER(posicao_contratual!O2))),"",ROUND(posicao_contratual!B2*posicao_contratual!O2,2)) -> 30000 | F4: =IF(OR(posicao_contratual!A2="",NOT(ISNUMBER(posicao_contratual!B2)),NOT(ISNUMBER(posicao_contratual!S2))),"",ROUND(posicao_contratual!B2*posicao_contratual!S2,2)) -> 30000 | G4: =IF(OR(posicao_contratual!A2="",NOT(ISNUMBER(posicao_contratual!B2)),NOT(ISNUMBER(posicao_contratual!W2))),"",ROUND(posicao_contratual!B2*posicao_contratual!W2,2)) -> 30000
A5: =IF(posicao_contratual!A3="","",posicao_contratual!A3) -> ITEM-002 | B5: =IF(posicao_contratual!A3="","",posicao_contratual!B3) -> 1500 | C5: =IF(OR(posicao_contratual!A3="",NOT(ISNUMBER(posicao_contratual!B3)),NOT(ISNUMBER(posicao_contratual!G3))),"",ROUND(posicao_contratual!B3*posicao_contratual!G3,2)) -> 120000 | D5: =IF(OR(posicao_contratual!A3="",NOT(ISNUMBER(posicao_contratual!B3)),NOT(ISNUMBER(posicao_contratual!K3))),"",ROUND(posicao_contratual!B3*posicao_contratual!K3,2)) -> 120000 | E5: =IF(OR(posicao_contratual!A3="",NOT(ISNUMBER(posicao_contratual!B3)),NOT(ISNUMBER(posicao_contratual!O3))),"",ROUND(posicao_contratual!B3*posicao_contratual!O3,2)) -> 120000 | F5: =IF(OR(posicao_contratual!A3="",NOT(ISNUMBER(posicao_contratual!B3)),NOT(ISNUMBER(posicao_contratual!S3))),"",ROUND(posicao_contratual!B3*posicao_contratual!S3,2)) -> 120000 | G5: =IF(OR(posicao_contratual!A3="",NOT(ISNUMBER(posicao_contratual!B3)),NOT(ISNUMBER(posicao_contratual!W3))),"",ROUND(posicao_contratual!B3*posicao_contratual!W3,2)) -> 120000
A6: =IF(posicao_contratual!A4="","",posicao_contratual!A4) -> ITEM-003 | B6: =IF(posicao_contratual!A4="","",posicao_contratual!B4) -> 3200 | C6: =IF(OR(posicao_contratual!A4="",NOT(ISNUMBER(posicao_contratual!B4)),NOT(ISNUMBER(posicao_contratual!G4))),"",ROUND(posicao_contratual!B4*posicao_contratual!G4,2)) -> 128000 | D6: =IF(OR(posicao_contratual!A4="",NOT(ISNUMBER(posicao_contratual!B4)),NOT(ISNUMBER(posicao_contratual!K4))),"",ROUND(posicao_contratual!B4*posicao_contratual!K4,2)) -> 128000 | E6: =IF(OR(posicao_contratual!A4="",NOT(ISNUMBER(posicao_contratual!B4)),NOT(ISNUMBER(posicao_contratual!O4))),"",ROUND(posicao_contratual!B4*posicao_contratual!O4,2)) -> 128000 | F6: =IF(OR(posicao_contratual!A4="",NOT(ISNUMBER(posicao_contratual!B4)),NOT(ISNUMBER(posicao_contratual!S4))),"",ROUND(posicao_contratual!B4*posicao_contratual!S4,2)) -> 128000 | G6: =IF(OR(posicao_contratual!A4="",NOT(ISNUMBER(posicao_contratual!B4)),NOT(ISNUMBER(posicao_contratual!W4))),"",ROUND(posicao_contratual!B4*posicao_contratual!W4,2)) -> 128000
A7: =IF(posicao_contratual!A5="","",posicao_contratual!A5) | B7: =IF(posicao_contratual!A5="","",posicao_contratual!B5) | C7: =IF(OR(posicao_contratual!A5="",NOT(ISNUMBER(posicao_contratual!B5)),NOT(ISNUMBER(posicao_contratual!G5))),"",ROUND(posicao_contratual!B5*posicao_contratual!G5,2)) | D7: =IF(OR(posicao_contratual!A5="",NOT(ISNUMBER(posicao_contratual!B5)),NOT(ISNUMBER(posicao_contratual!K5))),"",ROUND(posicao_contratual!B5*posicao_contratual!K5,2)) | E7: =IF(OR(posicao_contratual!A5="",NOT(ISNUMBER(posicao_contratual!B5)),NOT(ISNUMBER(posicao_contratual!O5))),"",ROUND(posicao_contratual!B5*posicao_contratual!O5,2)) | F7: =IF(OR(posicao_contratual!A5="",NOT(ISNUMBER(posicao_contratual!B5)),NOT(ISNUMBER(posicao_contratual!S5))),"",ROUND(posicao_contratual!B5*posicao_contratual!S5,2)) | G7: =IF(OR(posicao_contratual!A5="",NOT(ISNUMBER(posicao_contratual!B5)),NOT(ISNUMBER(posicao_contratual!W5))),"",ROUND(posicao_contratual!B5*posicao_contratual!W5,2))
A8: =IF(posicao_contratual!A6="","",posicao_contratual!A6) | B8: =IF(posicao_contratual!A6="","",posicao_contratual!B6) | C8: =IF(OR(posicao_contratual!A6="",NOT(ISNUMBER(posicao_contratual!B6)),NOT(ISNUMBER(posicao_contratual!G6))),"",ROUND(posicao_contratual!B6*posicao_contratual!G6,2)) | D8: =IF(OR(posicao_contratual!A6="",NOT(ISNUMBER(posicao_contratual!B6)),NOT(ISNUMBER(posicao_contratual!K6))),"",ROUND(posicao_contratual!B6*posicao_contratual!K6,2)) | E8: =IF(OR(posicao_contratual!A6="",NOT(ISNUMBER(posicao_contratual!B6)),NOT(ISNUMBER(posicao_contratual!O6))),"",ROUND(posicao_contratual!B6*posicao_contratual!O6,2)) | F8: =IF(OR(posicao_contratual!A6="",NOT(ISNUMBER(posicao_contratual!B6)),NOT(ISNUMBER(posicao_contratual!S6))),"",ROUND(posicao_contratual!B6*posicao_contratual!S6,2)) | G8: =IF(OR(posicao_contratual!A6="",NOT(ISNUMBER(posicao_contratual!B6)),NOT(ISNUMBER(posicao_contratual!W6))),"",ROUND(posicao_contratual!B6*posicao_contratual!W6,2))
A9: =IF(posicao_contratual!A7="","",posicao_contratual!A7) | B9: =IF(posicao_contratual!A7="","",posicao_contratual!B7) | C9: =IF(OR(posicao_contratual!A7="",NOT(ISNUMBER(posicao_contratual!B7)),NOT(ISNUMBER(posicao_contratual!G7))),"",ROUND(posicao_contratual!B7*posicao_contratual!G7,2)) | D9: =IF(OR(posicao_contratual!A7="",NOT(ISNUMBER(posicao_contratual!B7)),NOT(ISNUMBER(posicao_contratual!K7))),"",ROUND(posicao_contratual!B7*posicao_contratual!K7,2)) | E9: =IF(OR(posicao_contratual!A7="",NOT(ISNUMBER(posicao_contratual!B7)),NOT(ISNUMBER(posicao_contratual!O7))),"",ROUND(posicao_contratual!B7*posicao_contratual!O7,2)) | F9: =IF(OR(posicao_contratual!A7="",NOT(ISNUMBER(posicao_contratual!B7)),NOT(ISNUMBER(posicao_contratual!S7))),"",ROUND(posicao_contratual!B7*posicao_contratual!S7,2)) | G9: =IF(OR(posicao_contratual!A7="",NOT(ISNUMBER(posicao_contratual!B7)),NOT(ISNUMBER(posicao_contratual!W7))),"",ROUND(posicao_contratual!B7*posicao_contratual!W7,2))
A10: =IF(posicao_contratual!A8="","",posicao_contratual!A8) | B10: =IF(posicao_contratual!A8="","",posicao_contratual!B8) | C10: =IF(OR(posicao_contratual!A8="",NOT(ISNUMBER(posicao_contratual!B8)),NOT(ISNUMBER(posicao_contratual!G8))),"",ROUND(posicao_contratual!B8*posicao_contratual!G8,2)) | D10: =IF(OR(posicao_contratual!A8="",NOT(ISNUMBER(posicao_contratual!B8)),NOT(ISNUMBER(posicao_contratual!K8))),"",ROUND(posicao_contratual!B8*posicao_contratual!K8,2)) | E10: =IF(OR(posicao_contratual!A8="",NOT(ISNUMBER(posicao_contratual!B8)),NOT(ISNUMBER(posicao_contratual!O8))),"",ROUND(posicao_contratual!B8*posicao_contratual!O8,2)) | F10: =IF(OR(posicao_contratual!A8="",NOT(ISNUMBER(posicao_contratual!B8)),NOT(ISNUMBER(posicao_contratual!S8))),"",ROUND(posicao_contratual!B8*posicao_contratual!S8,2)) | G10: =IF(OR(posicao_contratual!A8="",NOT(ISNUMBER(posicao_contratual!B8)),NOT(ISNUMBER(posicao_contratual!W8))),"",ROUND(posicao_contratual!B8*posicao_contratual!W8,2))
A11: =IF(posicao_contratual!A9="","",posicao_contratual!A9) | B11: =IF(posicao_contratual!A9="","",posicao_contratual!B9) | C11: =IF(OR(posicao_contratual!A9="",NOT(ISNUMBER(posicao_contratual!B9)),NOT(ISNUMBER(posicao_contratual!G9))),"",ROUND(posicao_contratual!B9*posicao_contratual!G9,2)) | D11: =IF(OR(posicao_contratual!A9="",NOT(ISNUMBER(posicao_contratual!B9)),NOT(ISNUMBER(posicao_contratual!K9))),"",ROUND(posicao_contratual!B9*posicao_contratual!K9,2)) | E11: =IF(OR(posicao_contratual!A9="",NOT(ISNUMBER(posicao_contratual!B9)),NOT(ISNUMBER(posicao_contratual!O9))),"",ROUND(posicao_contratual!B9*posicao_contratual!O9,2)) | F11: =IF(OR(posicao_contratual!A9="",NOT(ISNUMBER(posicao_contratual!B9)),NOT(ISNUMBER(posicao_contratual!S9))),"",ROUND(posicao_contratual!B9*posicao_contratual!S9,2)) | G11: =IF(OR(posicao_contratual!A9="",NOT(ISNUMBER(posicao_contratual!B9)),NOT(ISNUMBER(posicao_contratual!W9))),"",ROUND(posicao_contratual!B9*posicao_contratual!W9,2))
A12: =IF(posicao_contratual!A10="","",posicao_contratual!A10) | B12: =IF(posicao_contratual!A10="","",posicao_contratual!B10) | C12: =IF(OR(posicao_contratual!A10="",NOT(ISNUMBER(posicao_contratual!B10)),NOT(ISNUMBER(posicao_contratual!G10))),"",ROUND(posicao_contratual!B10*posicao_contratual!G10,2)) | D12: =IF(OR(posicao_contratual!A10="",NOT(ISNUMBER(posicao_contratual!B10)),NOT(ISNUMBER(posicao_contratual!K10))),"",ROUND(posicao_contratual!B10*posicao_contratual!K10,2)) | E12: =IF(OR(posicao_contratual!A10="",NOT(ISNUMBER(posicao_contratual!B10)),NOT(ISNUMBER(posicao_contratual!O10))),"",ROUND(posicao_contratual!B10*posicao_contratual!O10,2)) | F12: =IF(OR(posicao_contratual!A10="",NOT(ISNUMBER(posicao_contratual!B10)),NOT(ISNUMBER(posicao_contratual!S10))),"",ROUND(posicao_contratual!B10*posicao_contratual!S10,2)) | G12: =IF(OR(posicao_contratual!A10="",NOT(ISNUMBER(posicao_contratual!B10)),NOT(ISNUMBER(posicao_contratual!W10))),"",ROUND(posicao_contratual!B10*posicao_contratual!W10,2))
A13: =IF(posicao_contratual!A11="","",posicao_contratual!A11) | B13: =IF(posicao_contratual!A11="","",posicao_contratual!B11) | C13: =IF(OR(posicao_contratual!A11="",NOT(ISNUMBER(posicao_contratual!B11)),NOT(ISNUMBER(posicao_contratual!G11))),"",ROUND(posicao_contratual!B11*posicao_contratual!G11,2)) | D13: =IF(OR(posicao_contratual!A11="",NOT(ISNUMBER(posicao_contratual!B11)),NOT(ISNUMBER(posicao_contratual!K11))),"",ROUND(posicao_contratual!B11*posicao_contratual!K11,2)) | E13: =IF(OR(posicao_contratual!A11="",NOT(ISNUMBER(posicao_contratual!B11)),NOT(ISNUMBER(posicao_contratual!O11))),"",ROUND(posicao_contratual!B11*posicao_contratual!O11,2)) | F13: =IF(OR(posicao_contratual!A11="",NOT(ISNUMBER(posicao_contratual!B11)),NOT(ISNUMBER(posicao_contratual!S11))),"",ROUND(posicao_contratual!B11*posicao_contratual!S11,2)) | G13: =IF(OR(posicao_contratual!A11="",NOT(ISNUMBER(posicao_contratual!B11)),NOT(ISNUMBER(posicao_contratual!W11))),"",ROUND(posicao_contratual!B11*posicao_contratual!W11,2))
A14: =IF(posicao_contratual!A12="","",posicao_contratual!A12) | B14: =IF(posicao_contratual!A12="","",posicao_contratual!B12) | C14: =IF(OR(posicao_contratual!A12="",NOT(ISNUMBER(posicao_contratual!B12)),NOT(ISNUMBER(posicao_contratual!G12))),"",ROUND(posicao_contratual!B12*posicao_contratual!G12,2)) | D14: =IF(OR(posicao_contratual!A12="",NOT(ISNUMBER(posicao_contratual!B12)),NOT(ISNUMBER(posicao_contratual!K12))),"",ROUND(posicao_contratual!B12*posicao_contratual!K12,2)) | E14: =IF(OR(posicao_contratual!A12="",NOT(ISNUMBER(posicao_contratual!B12)),NOT(ISNUMBER(posicao_contratual!O12))),"",ROUND(posicao_contratual!B12*posicao_contratual!O12,2)) | F14: =IF(OR(posicao_contratual!A12="",NOT(ISNUMBER(posicao_contratual!B12)),NOT(ISNUMBER(posicao_contratual!S12))),"",ROUND(posicao_contratual!B12*posicao_contratual!S12,2)) | G14: =IF(OR(posicao_contratual!A12="",NOT(ISNUMBER(posicao_contratual!B12)),NOT(ISNUMBER(posicao_contratual!W12))),"",ROUND(posicao_contratual!B12*posicao_contratual!W12,2))
A15: =IF(posicao_contratual!A13="","",posicao_contratual!A13) | B15: =IF(posicao_contratual!A13="","",posicao_contratual!B13) | C15: =IF(OR(posicao_contratual!A13="",NOT(ISNUMBER(posicao_contratual!B13)),NOT(ISNUMBER(posicao_contratual!G13))),"",ROUND(posicao_contratual!B13*posicao_contratual!G13,2)) | D15: =IF(OR(posicao_contratual!A13="",NOT(ISNUMBER(posicao_contratual!B13)),NOT(ISNUMBER(posicao_contratual!K13))),"",ROUND(posicao_contratual!B13*posicao_contratual!K13,2)) | E15: =IF(OR(posicao_contratual!A13="",NOT(ISNUMBER(posicao_contratual!B13)),NOT(ISNUMBER(posicao_contratual!O13))),"",ROUND(posicao_contratual!B13*posicao_contratual!O13,2)) | F15: =IF(OR(posicao_contratual!A13="",NOT(ISNUMBER(posicao_contratual!B13)),NOT(ISNUMBER(posicao_contratual!S13))),"",ROUND(posicao_contratual!B13*posicao_contratual!S13,2)) | G15: =IF(OR(posicao_contratual!A13="",NOT(ISNUMBER(posicao_contratual!B13)),NOT(ISNUMBER(posicao_contratual!W13))),"",ROUND(posicao_contratual!B13*posicao_contratual!W13,2))
... A203: =IF(posicao_contratual!A201="","",posicao_contratual!A201) | B203: =IF(posicao_contratual!A201="","",posicao_contratual!B201) | C203: =IF(OR(posicao_contratual!A201="",NOT(ISNUMBER(posicao_contratual!B201)),NOT(ISNUMBER(posicao_contratual!G201))),"",ROUND(posicao_contratual!B201*posicao_contratual!G201,2)) | D203: =IF(OR(posicao_contratual!A201="",NOT(ISNUMBER(posicao_contratual!B201)),NOT(ISNUMBER(posicao_contratual!K201))),"",ROUND(posicao_contratual!B201*posicao_contratual!K201,2)) | E203: =IF(OR(posicao_contratual!A201="",NOT(ISNUMBER(posicao_contratual!B201)),NOT(ISNUMBER(posicao_contratual!O201))),"",ROUND(posicao_contratual!B201*posicao_contratual!O201,2)) | F203: =IF(OR(posicao_contratual!A201="",NOT(ISNUMBER(posicao_contratual!B201)),NOT(ISNUMBER(posicao_contratual!S201))),"",ROUND(posicao_contratual!B201*posicao_contratual!S201,2)) | G203: =IF(OR(posicao_contratual!A201="",NOT(ISNUMBER(posicao_contratual!B201)),NOT(ISNUMBER(posicao_contratual!W201))),"",ROUND(posicao_contratual!B201*posicao_contratual!W201,2))
A204: TOTAL | C204: =ROUND(SUM(C4:C203),2) -> 278000 | D204: =ROUND(SUM(D4:D203),2) -> 278000 | E204: =ROUND(SUM(E4:E203),2) -> 278000 | F204: =ROUND(SUM(F4:F203),2) -> 278000 | G204: =ROUND(SUM(G4:G203),2) -> 278000
A206: BLOCO 2 - COMPARACAO DE REFERENCIA - NAO UTILIZAR COMO VTA OU VALOR DE PAGAMENTO
A207: VTA pelo metodo aplicado | B207: =MEMORIA_RESULTADOS!$B$26 -> 299670.4
A208: Contrato original integralmente reajustado ate o ciclo atual - REFERENCIA APENAS | B208: =IFERROR(ROUND(SUMPRODUCT(posicao_contratual!$B$2:$B$201,posicao_contratual!$C$2:$C$201)*RESULTADOS!$H$5,2),"") -> 292233.6
A210: O valor integralmente reajustado e apenas um cenario comparativo. Ele pressupoe que todo o contrato original permanecesse sujeito ao fator acumulado final, desconsiderando a execucao ocorrida em ciclos distintos e a reducao do saldo remanescente. Nao utilizar este valor como VTA, retroativo ou base de pagamento.

Sheet CONTROLE
A1: MODO DE LEITURA | B1: PC (Pedidos de Compra)
A2: Ciclo vigente (em execução) | B2: C1
A3: DATA DE CORTE DA APURAÇÃO | B3: 45657 | C3: Última data considerada nos cálculos, PCs, competências e resultados da apuração.
A4: C0 e ciclos fora da analise | B4: Preencher FINANCEIRO: coluna B com o nome do ciclo (ex: c0, c1), coluna C com o valor efetivamente pago. Se vazio, o sistema usa calculo por itens/estoque.
A6: RESUMO DO REAJUSTE | B6: VALOR
A7: Índice utilizado | B7: IST (Anatel)
A8: Data-base original | B8: 44927
A9: Quantidade de ciclos desta análise | B9: =COUNTIF(parametros!A2:A6,"Sim") -> 1
A10: Variação histórica integral até o ciclo vigente | B10: =IF(ISNUMBER(B11),B11-1,"") -> 0.0512
A11: Fator histórico integral (até o ciclo vigente) | B11: =IFERROR(IF(UPPER($B$2)="C0",1,IF(UPPER($B$2)="C1",IF(COUNT(parametros!$E$3:$E$3)=1,parametros!$F$3,""),IF(UPPER($B$2)="C2",IF(COUNT(parametros!$E$3:$E$4)=2,parametros!$F$4,""),IF(UPPER($B$2)="C3",IF(COUNT(parametros!$E$3:$E$5)=3,parametros!$F$5,""),IF(UPPER($B$2)="C4",IF(COUNT(parametros!$E$3:$E$6)=4,parametros!$F$6,""),""))))),"") -> 1.0512
A12: Último ciclo considerado nesta apuração | B12: =IFERROR(IF(parametros!A6="Sim",parametros!B6,IF(parametros!A5="Sim",parametros!B5,IF(parametros!A4="Sim",parametros!B4,IF(parametros!A3="Sim",parametros!B3,IF(parametros!A2="Sim",parametros!B2,"Nenhum"))))),"Nenhum") -> C1
A13: Início do último ciclo considerado | B13: =IFERROR(IF(parametros!A6="Sim",parametros!C6,IF(parametros!A5="Sim",parametros!C5,IF(parametros!A4="Sim",parametros!C4,IF(parametros!A3="Sim",parametros!C3,IF(parametros!A2="Sim",parametros!C2,""))))),"") -> 45292
A14: Data de geracao do arquivo | B14: =NOW() -> 46295.818
A24: Modelo de Coleta | B24: 11.0
A25: Gerado pelo Cl8us | B25: 11.0

Sheet parametros
A1: COMPUTAR_NESTA_APURACAO | B1: CICLO | C1: DATA_INICIO | D1: DATA_FIM | E1: PERCENTUAL_DO_CICLO | F1: FATOR_ACUMULADO | G1: SITUACAO | H1: INICIO_EFEITO_FINANCEIRO | J1: CICLO | K1: TIPO_REGISTRO | L1: ORDEM | M1: COMPETENCIA | N1: VALOR_INDICE | O1: FATOR_MENSAL | P1: FATOR_ACUMULADO | Q1: VARIACAO_FINAL | R1: METODO_FONTE
A2: Nao | B2: C0 | C2: 44927 | D2: 45291 | F2: =1 -> 1 | T2: Sim
A3: Sim | B3: C1 | C3: 45292 | D3: 45657 | E3: 0.0512 | F3: =IF(E3="","",IF(NOT(ISNUMBER(E3)),"",IF(NOT(ISNUMBER(F2)),"",F2*(1+E3)))) -> 1.0512 | G3: TEMPESTIVO | H3: 45292 | T3: Nao | U3: 45270
A4: Nao | B4: C2 | C4: 45658 | D4: 46022 | E4: 0.0374 | F4: =IF(E4="","",IF(NOT(ISNUMBER(E4)),"",IF(NOT(ISNUMBER(F3)),"",F3*(1+E4)))) -> 1.0905149 | G4: TEMPESTIVO | H4: 45658 | T4: N/A | U4: 45638
A5: Nao | B5: C3 | C5: 46023 | D5: 46387 | E5: 0.0289 | F5: =IF(E5="","",IF(NOT(ISNUMBER(E5)),"",IF(NOT(ISNUMBER(F4)),"",F4*(1+E5)))) -> 1.1220308 | G5: TEMPESTIVO | H5: 46023 | U5: 46006
A6: Nao | B6: C4 | C6: 46388 | D6: 46752 | F6: =IF(E6="","",IF(NOT(ISNUMBER(E6)),"",IF(NOT(ISNUMBER(F5)),"",F5*(1+E6))))
A9: MEMORIA DO FATOR APLICAVEL A APURACAO
A10: CICLO | B10: COMPUTA? | C10: PERCENTUAL | D10: FATOR | E10: FATOR_ACUMULADO_APURACAO | F10: STATUS | G10: EXISTE REAJUSTE ANTERIOR FORMALIZADO? (Sim/Não; vazio=não comprovado)
A11: C0 | B11: =A2 -> Nao | C11: =IF(B11="Sim",E2,"") | D11: =1 -> 1 | E11: =1 -> 1 | F11: Base
A12: C1 | B12: =A3 -> Sim | C12: =IF(B12="Sim",E3,"") -> 0.0512 | D12: =IF(C12="","",1+C12) -> 1.0512 | E12: =IF(B12="Sim",E11*D12,E11) -> 1.0512 | F12: =IF(B12="Sim","Aplicado","Fora da apuracao") -> Aplicado
A13: C2 | B13: =A4 -> Nao | C13: =IF(B13="Sim",E4,"") | D13: =IF(C13="","",1+C13) | E13: =IF(B13="Sim",E12*D13,E12) -> 1.0512 | F13: =IF(B13="Sim","Aplicado","Fora da apuracao") -> Fora da apuracao
A14: C3 | B14: =A5 -> Nao | C14: =IF(B14="Sim",E5,"") | D14: =IF(C14="","",1+C14) | E14: =IF(B14="Sim",E13*D14,E13) -> 1.0512 | F14: =IF(B14="Sim","Aplicado","Fora da apuracao") -> Fora da apuracao
A15: C4 | B15: =A6 -> Nao | C15: =IF(B15="Sim",E6,"") | D15: =IF(C15="","",1+C15) | E15: =IF(B15="Sim",E14*D15,E14) -> 1.0512 | F15: =IF(B15="Sim","Aplicado","Fora da apuracao") -> Fora da apuracao
A16: TOTAL APURACAO | D16: =E15 -> 1.0512 | E16: =E15 -> 1.0512 | F16: =E16-1 -> 0.0512

Sheet financeiro
A1: COMPETENCIA | B1: CICLO | C1: VALOR_PAGO | D1: FATOR_APLICAVEL | E1: VALOR_ATUALIZADO | F1: DELTA | G1: EFEITO_FINANCEIRO
B2: =IF($A2="","",IF(NOT(ISNUMBER(parametros!$C$2)),"Fora dos ciclos",IF(OR($A2<parametros!$C$2,(YEAR($A2)-YEAR(parametros!$C$2))*12+MONTH($A2)-MONTH(parametros!$C$2)>59),"Fora dos ciclos","c"&INT(((YEAR($A2)-YEAR(parametros!$C$2))*12+MONTH($A2)-MONTH(parametros!$C$2))/12)))) | D2: =IF(B2="","",IF(B2="c0",1,IF(B2="c1",IF(parametros!$A$3<>"Sim","",IF(NOT(ISNUMBER(parametros!$E$3)),"",1+parametros!$E$3)),IF(B2="c2",IF(parametros!$A$4<>"Sim","",IF(NOT(ISNUMBER(parametros!$E$4)),"",IF(parametros!$A$3="Sim",1+parametros!$E$3,1)*(1+parametros!$E$4))),IF(B2="c3",IF(parametros!$A$5<>"Sim","",IF(NOT(ISNUMBER(parametros!$E$5)),"",IF(parametros!$A$3="Sim",1+parametros!$E$3,1)*IF(parametros!$A$4="Sim",1+parametros!$E$4,1)*(1+parametros!$E$5))),IF(B2="c4",IF(parametros!$A$6<>"Sim","",IF(NOT(ISNUMBER(parametros!$E$6)),"",IF(parametros!$A$3="Sim",1+parametros!$E$3,1)*IF(parametros!$A$4="Sim",1+parametros!$E$4,1)*IF(parametros!$A$5="Sim",1+parametros!$E$5,1)*(1+parametros!$E$6))),"")))))) | E2: =IF(C2="","",IF(G2="","",IF(G2="Sim",IF(NOT(ISNUMBER(D2)),"",ROUND(C2*D2,2)),C2))) | F2: =IF(C2="","",IF(G2="","",IF(G2="Sim",IF(E2="","",ROUND(E2-C2,2)),0)))
B3: =IF($A3="","",IF(NOT(ISNUMBER(parametros!$C$2)),"Fora dos ciclos",IF(OR($A3<parametros!$C$2,(YEAR($A3)-YEAR(parametros!$C$2))*12+MONTH($A3)-MONTH(parametros!$C$2)>59),"Fora dos ciclos","c"&INT(((YEAR($A3)-YEAR(parametros!$C$2))*12+MONTH($A3)-MONTH(parametros!$C$2))/12)))) | D3: =IF(B3="","",IF(B3="c0",1,IF(B3="c1",IF(parametros!$A$3<>"Sim","",IF(NOT(ISNUMBER(parametros!$E$3)),"",1+parametros!$E$3)),IF(B3="c2",IF(parametros!$A$4<>"Sim","",IF(NOT(ISNUMBER(parametros!$E$4)),"",IF(parametros!$A$3="Sim",1+parametros!$E$3,1)*(1+parametros!$E$4))),IF(B3="c3",IF(parametros!$A$5<>"Sim","",IF(NOT(ISNUMBER(parametros!$E$5)),"",IF(parametros!$A$3="Sim",1+parametros!$E$3,1)*IF(parametros!$A$4="Sim",1+parametros!$E$4,1)*(1+parametros!$E$5))),IF(B3="c4",IF(parametros!$A$6<>"Sim","",IF(NOT(ISNUMBER(parametros!$E$6)),"",IF(parametros!$A$3="Sim",1+parametros!$E$3,1)*IF(parametros!$A$4="Sim",1+parametros!$E$4,1)*IF(parametros!$A$5="Sim",1+parametros!$E$5,1)*(1+parametros!$E$6))),"")))))) | E3: =IF(C3="","",IF(G3="","",IF(G3="Sim",IF(NOT(ISNUMBER(D3)),"",ROUND(C3*D3,2)),C3))) | F3: =IF(C3="","",IF(G3="","",IF(G3="Sim",IF(E3="","",ROUND(E3-C3,2)),0)))
B4: =IF($A4="","",IF(NOT(ISNUMBER(parametros!$C$2)),"Fora dos ciclos",IF(OR($A4<parametros!$C$2,(YEAR($A4)-YEAR(parametros!$C$2))*12+MONTH($A4)-MONTH(parametros!$C$2)>59),"Fora dos ciclos","c"&INT(((YEAR($A4)-YEAR(parametros!$C$2))*12+MONTH($A4)-MONTH(parametros!$C$2))/12)))) | D4: =IF(B4="","",IF(B4="c0",1,IF(B4="c1",IF(parametros!$A$3<>"Sim","",IF(NOT(ISNUMBER(parametros!$E$3)),"",1+parametros!$E$3)),IF(B4="c2",IF(parametros!$A$4<>"Sim","",IF(NOT(ISNUMBER(parametros!$E$4)),"",IF(parametros!$A$3="Sim",1+parametros!$E$3,1)*(1+parametros!$E$4))),IF(B4="c3",IF(parametros!$A$5<>"Sim","",IF(NOT(ISNUMBER(parametros!$E$5)),"",IF(parametros!$A$3="Sim",1+parametros!$E$3,1)*IF(parametros!$A$4="Sim",1+parametros!$E$4,1)*(1+parametros!$E$5))),IF(B4="c4",IF(parametros!$A$6<>"Sim","",IF(NOT(ISNUMBER(parametros!$E$6)),"",IF(parametros!$A$3="Sim",1+parametros!$E$3,1)*IF(parametros!$A$4="Sim",1+parametros!$E$4,1)*IF(parametros!$A$5="Sim",1+parametros!$E$5,1)*(1+parametros!$E$6))),"")))))) | E4: =IF(C4="","",IF(G4="","",IF(G4="Sim",IF(NOT(ISNUMBER(D4)),"",ROUND(C4*D4,2)),C4))) | F4: =IF(C4="","",IF(G4="","",IF(G4="Sim",IF(E4="","",ROUND(E4-C4,2)),0)))
B5: =IF($A5="","",IF(NOT(ISNUMBER(parametros!$C$2)),"Fora dos ciclos",IF(OR($A5<parametros!$C$2,(YEAR($A5)-YEAR(parametros!$C$2))*12+MONTH($A5)-MONTH(parametros!$C$2)>59),"Fora dos ciclos","c"&INT(((YEAR($A5)-YEAR(parametros!$C$2))*12+MONTH($A5)-MONTH(parametros!$C$2))/12)))) | D5: =IF(B5="","",IF(B5="c0",1,IF(B5="c1",IF(parametros!$A$3<>"Sim","",IF(NOT(ISNUMBER(parametros!$E$3)),"",1+parametros!$E$3)),IF(B5="c2",IF(parametros!$A$4<>"Sim","",IF(NOT(ISNUMBER(parametros!$E$4)),"",IF(parametros!$A$3="Sim",1+parametros!$E$3,1)*(1+parametros!$E$4))),IF(B5="c3",IF(parametros!$A$5<>"Sim","",IF(NOT(ISNUMBER(parametros!$E$5)),"",IF(parametros!$A$3="Sim",1+parametros!$E$3,1)*IF(parametros!$A$4="Sim",1+parametros!$E$4,1)*(1+parametros!$E$5))),IF(B5="c4",IF(parametros!$A$6<>"Sim","",IF(NOT(ISNUMBER(parametros!$E$6)),"",IF(parametros!$A$3="Sim",1+parametros!$E$3,1)*IF(parametros!$A$4="Sim",1+parametros!$E$4,1)*IF(parametros!$A$5="Sim",1+parametros!$E$5,1)*(1+parametros!$E$6))),"")))))) | E5: =IF(C5="","",IF(G5="","",IF(G5="Sim",IF(NOT(ISNUMBER(D5)),"",ROUND(C5*D5,2)),C5))) | F5: =IF(C5="","",IF(G5="","",IF(G5="Sim",IF(E5="","",ROUND(E5-C5,2)),0)))
B6: =IF($A6="","",IF(NOT(ISNUMBER(parametros!$C$2)),"Fora dos ciclos",IF(OR($A6<parametros!$C$2,(YEAR($A6)-YEAR(parametros!$C$2))*12+MONTH($A6)-MONTH(parametros!$C$2)>59),"Fora dos ciclos","c"&INT(((YEAR($A6)-YEAR(parametros!$C$2))*12+MONTH($A6)-MONTH(parametros!$C$2))/12)))) | D6: =IF(B6="","",IF(B6="c0",1,IF(B6="c1",IF(parametros!$A$3<>"Sim","",IF(NOT(ISNUMBER(parametros!$E$3)),"",1+parametros!$E$3)),IF(B6="c2",IF(parametros!$A$4<>"Sim","",IF(NOT(ISNUMBER(parametros!$E$4)),"",IF(parametros!$A$3="Sim",1+parametros!$E$3,1)*(1+parametros!$E$4))),IF(B6="c3",IF(parametros!$A$5<>"Sim","",IF(NOT(ISNUMBER(parametros!$E$5)),"",IF(parametros!$A$3="Sim",1+parametros!$E$3,1)*IF(parametros!$A$4="Sim",1+parametros!$E$4,1)*(1+parametros!$E$5))),IF(B6="c4",IF(parametros!$A$6<>"Sim","",IF(NOT(ISNUMBER(parametros!$E$6)),"",IF(parametros!$A$3="Sim",1+parametros!$E$3,1)*IF(parametros!$A$4="Sim",1+parametros!$E$4,1)*IF(parametros!$A$5="Sim",1+parametros!$E$5,1)*(1+parametros!$E$6))),"")))))) | E6: =IF(C6="","",IF(G6="","",IF(G6="Sim",IF(NOT(ISNUMBER(D6)),"",ROUND(C6*D6,2)),C6))) | F6: =IF(C6="","",IF(G6="","",IF(G6="Sim",IF(E6="","",ROUND(E6-C6,2)),0)))
B7: =IF($A7="","",IF(NOT(ISNUMBER(parametros!$C$2)),"Fora dos ciclos",IF(OR($A7<parametros!$C$2,(YEAR($A7)-YEAR(parametros!$C$2))*12+MONTH($A7)-MONTH(parametros!$C$2)>59),"Fora dos ciclos","c"&INT(((YEAR($A7)-YEAR(parametros!$C$2))*12+MONTH($A7)-MONTH(parametros!$C$2))/12)))) | D7: =IF(B7="","",IF(B7="c0",1,IF(B7="c1",IF(parametros!$A$3<>"Sim","",IF(NOT(ISNUMBER(parametros!$E$3)),"",1+parametros!$E$3)),IF(B7="c2",IF(parametros!$A$4<>"Sim","",IF(NOT(ISNUMBER(parametros!$E$4)),"",IF(parametros!$A$3="Sim",1+parametros!$E$3,1)*(1+parametros!$E$4))),IF(B7="c3",IF(parametros!$A$5<>"Sim","",IF(NOT(ISNUMBER(parametros!$E$5)),"",IF(parametros!$A$3="Sim",1+parametros!$E$3,1)*IF(parametros!$A$4="Sim",1+parametros!$E$4,1)*(1+parametros!$E$5))),IF(B7="c4",IF(parametros!$A$6<>"Sim","",IF(NOT(ISNUMBER(parametros!$E$6)),"",IF(parametros!$A$3="Sim",1+parametros!$E$3,1)*IF(parametros!$A$4="Sim",1+parametros!$E$4,1)*IF(parametros!$A$5="Sim",1+parametros!$E$5,1)*(1+parametros!$E$6))),"")))))) | E7: =IF(C7="","",IF(G7="","",IF(G7="Sim",IF(NOT(ISNUMBER(D7)),"",ROUND(C7*D7,2)),C7))) | F7: =IF(C7="","",IF(G7="","",IF(G7="Sim",IF(E7="","",ROUND(E7-C7,2)),0)))
B8: =IF($A8="","",IF(NOT(ISNUMBER(parametros!$C$2)),"Fora dos ciclos",IF(OR($A8<parametros!$C$2,(YEAR($A8)-YEAR(parametros!$C$2))*12+MONTH($A8)-MONTH(parametros!$C$2)>59),"Fora dos ciclos","c"&INT(((YEAR($A8)-YEAR(parametros!$C$2))*12+MONTH($A8)-MONTH(parametros!$C$2))/12)))) | D8: =IF(B8="","",IF(B8="c0",1,IF(B8="c1",IF(parametros!$A$3<>"Sim","",IF(NOT(ISNUMBER(parametros!$E$3)),"",1+parametros!$E$3)),IF(B8="c2",IF(parametros!$A$4<>"Sim","",IF(NOT(ISNUMBER(parametros!$E$4)),"",IF(parametros!$A$3="Sim",1+parametros!$E$3,1)*(1+parametros!$E$4))),IF(B8="c3",IF(parametros!$A$5<>"Sim","",IF(NOT(ISNUMBER(parametros!$E$5)),"",IF(parametros!$A$3="Sim",1+parametros!$E$3,1)*IF(parametros!$A$4="Sim",1+parametros!$E$4,1)*(1+parametros!$E$5))),IF(B8="c4",IF(parametros!$A$6<>"Sim","",IF(NOT(ISNUMBER(parametros!$E$6)),"",IF(parametros!$A$3="Sim",1+parametros!$E$3,1)*IF(parametros!$A$4="Sim",1+parametros!$E$4,1)*IF(parametros!$A$5="Sim",1+parametros!$E$5,1)*(1+parametros!$E$6))),"")))))) | E8: =IF(C8="","",IF(G8="","",IF(G8="Sim",IF(NOT(ISNUMBER(D8)),"",ROUND(C8*D8,2)),C8))) | F8: =IF(C8="","",IF(G8="","",IF(G8="Sim",IF(E8="","",ROUND(E8-C8,2)),0)))
B9: =IF($A9="","",IF(NOT(ISNUMBER(parametros!$C$2)),"Fora dos ciclos",IF(OR($A9<parametros!$C$2,(YEAR($A9)-YEAR(parametros!$C$2))*12+MONTH($A9)-MONTH(parametros!$C$2)>59),"Fora dos ciclos","c"&INT(((YEAR($A9)-YEAR(parametros!$C$2))*12+MONTH($A9)-MONTH(parametros!$C$2))/12)))) | D9: =IF(B9="","",IF(B9="c0",1,IF(B9="c1",IF(parametros!$A$3<>"Sim","",IF(NOT(ISNUMBER(parametros!$E$3)),"",1+parametros!$E$3)),IF(B9="c2",IF(parametros!$A$4<>"Sim","",IF(NOT(ISNUMBER(parametros!$E$4)),"",IF(parametros!$A$3="Sim",1+parametros!$E$3,1)*(1+parametros!$E$4))),IF(B9="c3",IF(parametros!$A$5<>"Sim","",IF(NOT(ISNUMBER(parametros!$E$5)),"",IF(parametros!$A$3="Sim",1+parametros!$E$3,1)*IF(parametros!$A$4="Sim",1+parametros!$E$4,1)*(1+parametros!$E$5))),IF(B9="c4",IF(parametros!$A$6<>"Sim","",IF(NOT(ISNUMBER(parametros!$E$6)),"",IF(parametros!$A$3="Sim",1+parametros!$E$3,1)*IF(parametros!$A$4="Sim",1+parametros!$E$4,1)*IF(parametros!$A$5="Sim",1+parametros!$E$5,1)*(1+parametros!$E$6))),"")))))) | E9: =IF(C9="","",IF(G9="","",IF(G9="Sim",IF(NOT(ISNUMBER(D9)),"",ROUND(C9*D9,2)),C9))) | F9: =IF(C9="","",IF(G9="","",IF(G9="Sim",IF(E9="","",ROUND(E9-C9,2)),0)))
B10: =IF($A10="","",IF(NOT(ISNUMBER(parametros!$C$2)),"Fora dos ciclos",IF(OR($A10<parametros!$C$2,(YEAR($A10)-YEAR(parametros!$C$2))*12+MONTH($A10)-MONTH(parametros!$C$2)>59),"Fora dos ciclos","c"&INT(((YEAR($A10)-YEAR(parametros!$C$2))*12+MONTH($A10)-MONTH(parametros!$C$2))/12)))) | D10: =IF(B10="","",IF(B10="c0",1,IF(B10="c1",IF(parametros!$A$3<>"Sim","",IF(NOT(ISNUMBER(parametros!$E$3)),"",1+parametros!$E$3)),IF(B10="c2",IF(parametros!$A$4<>"Sim","",IF(NOT(ISNUMBER(parametros!$E$4)),"",IF(parametros!$A$3="Sim",1+parametros!$E$3,1)*(1+parametros!$E$4))),IF(B10="c3",IF(parametros!$A$5<>"Sim","",IF(NOT(ISNUMBER(parametros!$E$5)),"",IF(parametros!$A$3="Sim",1+parametros!$E$3,1)*IF(parametros!$A$4="Sim",1+parametros!$E$4,1)*(1+parametros!$E$5))),IF(B10="c4",IF(parametros!$A$6<>"Sim","",IF(NOT(ISNUMBER(parametros!$E$6)),"",IF(parametros!$A$3="Sim",1+parametros!$E$3,1)*IF(parametros!$A$4="Sim",1+parametros!$E$4,1)*IF(parametros!$A$5="Sim",1+parametros!$E$5,1)*(1+parametros!$E$6))),"")))))) | E10: =IF(C10="","",IF(G10="","",IF(G10="Sim",IF(NOT(ISNUMBER(D10)),"",ROUND(C10*D10,2)),C10))) | F10: =IF(C10="","",IF(G10="","",IF(G10="Sim",IF(E10="","",ROUND(E10-C10,2)),0)))
B11: =IF($A11="","",IF(NOT(ISNUMBER(parametros!$C$2)),"Fora dos ciclos",IF(OR($A11<parametros!$C$2,(YEAR($A11)-YEAR(parametros!$C$2))*12+MONTH($A11)-MONTH(parametros!$C$2)>59),"Fora dos ciclos","c"&INT(((YEAR($A11)-YEAR(parametros!$C$2))*12+MONTH($A11)-MONTH(parametros!$C$2))/12)))) | D11: =IF(B11="","",IF(B11="c0",1,IF(B11="c1",IF(parametros!$A$3<>"Sim","",IF(NOT(ISNUMBER(parametros!$E$3)),"",1+parametros!$E$3)),IF(B11="c2",IF(parametros!$A$4<>"Sim","",IF(NOT(ISNUMBER(parametros!$E$4)),"",IF(parametros!$A$3="Sim",1+parametros!$E$3,1)*(1+parametros!$E$4))),IF(B11="c3",IF(parametros!$A$5<>"Sim","",IF(NOT(ISNUMBER(parametros!$E$5)),"",IF(parametros!$A$3="Sim",1+parametros!$E$3,1)*IF(parametros!$A$4="Sim",1+parametros!$E$4,1)*(1+parametros!$E$5))),IF(B11="c4",IF(parametros!$A$6<>"Sim","",IF(NOT(ISNUMBER(parametros!$E$6)),"",IF(parametros!$A$3="Sim",1+parametros!$E$3,1)*IF(parametros!$A$4="Sim",1+parametros!$E$4,1)*IF(parametros!$A$5="Sim",1+parametros!$E$5,1)*(1+parametros!$E$6))),"")))))) | E11: =IF(C11="","",IF(G11="","",IF(G11="Sim",IF(NOT(ISNUMBER(D11)),"",ROUND(C11*D11,2)),C11))) | F11: =IF(C11="","",IF(G11="","",IF(G11="Sim",IF(E11="","",ROUND(E11-C11,2)),0)))
B12: =IF($A12="","",IF(NOT(ISNUMBER(parametros!$C$2)),"Fora dos ciclos",IF(OR($A12<parametros!$C$2,(YEAR($A12)-YEAR(parametros!$C$2))*12+MONTH($A12)-MONTH(parametros!$C$2)>59),"Fora dos ciclos","c"&INT(((YEAR($A12)-YEAR(parametros!$C$2))*12+MONTH($A12)-MONTH(parametros!$C$2))/12)))) | D12: =IF(B12="","",IF(B12="c0",1,IF(B12="c1",IF(parametros!$A$3<>"Sim","",IF(NOT(ISNUMBER(parametros!$E$3)),"",1+parametros!$E$3)),IF(B12="c2",IF(parametros!$A$4<>"Sim","",IF(NOT(ISNUMBER(parametros!$E$4)),"",IF(parametros!$A$3="Sim",1+parametros!$E$3,1)*(1+parametros!$E$4))),IF(B12="c3",IF(parametros!$A$5<>"Sim","",IF(NOT(ISNUMBER(parametros!$E$5)),"",IF(parametros!$A$3="Sim",1+parametros!$E$3,1)*IF(parametros!$A$4="Sim",1+parametros!$E$4,1)*(1+parametros!$E$5))),IF(B12="c4",IF(parametros!$A$6<>"Sim","",IF(NOT(ISNUMBER(parametros!$E$6)),"",IF(parametros!$A$3="Sim",1+parametros!$E$3,1)*IF(parametros!$A$4="Sim",1+parametros!$E$4,1)*IF(parametros!$A$5="Sim",1+parametros!$E$5,1)*(1+parametros!$E$6))),"")))))) | E12: =IF(C12="","",IF(G12="","",IF(G12="Sim",IF(NOT(ISNUMBER(D12)),"",ROUND(C12*D12,2)),C12))) | F12: =IF(C12="","",IF(G12="","",IF(G12="Sim",IF(E12="","",ROUND(E12-C12,2)),0)))
B13: =IF($A13="","",IF(NOT(ISNUMBER(parametros!$C$2)),"Fora dos ciclos",IF(OR($A13<parametros!$C$2,(YEAR($A13)-YEAR(parametros!$C$2))*12+MONTH($A13)-MONTH(parametros!$C$2)>59),"Fora dos ciclos","c"&INT(((YEAR($A13)-YEAR(parametros!$C$2))*12+MONTH($A13)-MONTH(parametros!$C$2))/12)))) | D13: =IF(B13="","",IF(B13="c0",1,IF(B13="c1",IF(parametros!$A$3<>"Sim","",IF(NOT(ISNUMBER(parametros!$E$3)),"",1+parametros!$E$3)),IF(B13="c2",IF(parametros!$A$4<>"Sim","",IF(NOT(ISNUMBER(parametros!$E$4)),"",IF(parametros!$A$3="Sim",1+parametros!$E$3,1)*(1+parametros!$E$4))),IF(B13="c3",IF(parametros!$A$5<>"Sim","",IF(NOT(ISNUMBER(parametros!$E$5)),"",IF(parametros!$A$3="Sim",1+parametros!$E$3,1)*IF(parametros!$A$4="Sim",1+parametros!$E$4,1)*(1+parametros!$E$5))),IF(B13="c4",IF(parametros!$A$6<>"Sim","",IF(NOT(ISNUMBER(parametros!$E$6)),"",IF(parametros!$A$3="Sim",1+parametros!$E$3,1)*IF(parametros!$A$4="Sim",1+parametros!$E$4,1)*IF(parametros!$A$5="Sim",1+parametros!$E$5,1)*(1+parametros!$E$6))),"")))))) | E13: =IF(C13="","",IF(G13="","",IF(G13="Sim",IF(NOT(ISNUMBER(D13)),"",ROUND(C13*D13,2)),C13))) | F13: =IF(C13="","",IF(G13="","",IF(G13="Sim",IF(E13="","",ROUND(E13-C13,2)),0)))
... B73: =IF($A73="","",IF(NOT(ISNUMBER(parametros!$C$2)),"Fora dos ciclos",IF(OR($A73<parametros!$C$2,(YEAR($A73)-YEAR(parametros!$C$2))*12+MONTH($A73)-MONTH(parametros!$C$2)>59),"Fora dos ciclos","c"&INT(((YEAR($A73)-YEAR(parametros!$C$2))*12+MONTH($A73)-MONTH(parametros!$C$2))/12)))) | D73: =IF(B73="","",IF(B73="c0",1,IF(B73="c1",IF(parametros!$A$3<>"Sim","",IF(NOT(ISNUMBER(parametros!$E$3)),"",1+parametros!$E$3)),IF(B73="c2",IF(parametros!$A$4<>"Sim","",IF(NOT(ISNUMBER(parametros!$E$4)),"",IF(parametros!$A$3="Sim",1+parametros!$E$3,1)*(1+parametros!$E$4))),IF(B73="c3",IF(parametros!$A$5<>"Sim","",IF(NOT(ISNUMBER(parametros!$E$5)),"",IF(parametros!$A$3="Sim",1+parametros!$E$3,1)*IF(parametros!$A$4="Sim",1+parametros!$E$4,1)*(1+parametros!$E$5))),IF(B73="c4",IF(parametros!$A$6<>"Sim","",IF(NOT(ISNUMBER(parametros!$E$6)),"",IF(parametros!$A$3="Sim",1+parametros!$E$3,1)*IF(parametros!$A$4="Sim",1+parametros!$E$4,1)*IF(parametros!$A$5="Sim",1+parametros!$E$5,1)*(1+parametros!$E$6))),"")))))) | E73: =IF(C73="","",IF(G73="","",IF(G73="Sim",IF(NOT(ISNUMBER(D73)),"",ROUND(C73*D73,2)),C73))) | F73: =IF(C73="","",IF(G73="","",IF(G73="Sim",IF(E73="","",ROUND(E73-C73,2)),0)))
B74: TOTAL | C74: =SUM(C2:C73) -> 0 | E74: =SUM(E2:E73) -> 0 | F74: =SUM(F2:F73) -> 0

Sheet itens_Remanesc
A1: ITEM (NOVO ITEM: use N001, N002...; QTD_BASE_ORIGINAL fica 0 automaticamente - nao digite; informe o VU_ORIGINAL) | B1: QTD_BASE_ORIGINAL (NOVO ITEM: deixar vazio - assume 0 automaticamente) | C1: VU_ORIGINAL | D1: VALOR_TOTAL | E1: =IF(parametros!$I$3="","QTD. REMANESCENTE - C1","QTD. REMANESCENTE - C1"&CHAR(10)&"Informe a quantidade existente em "&RIGHT("0"&DAY(parametros!$I$3),2)&"/"&RIGHT("0"&MONTH(parametros!$I$3),2)&"/"&YEAR(parametros!$I$3)) -> QTD. REMANESCENTE - C1 | F1: ="VALOR REMANESCENTE - C1"&CHAR(10)&"Calculado automaticamente" -> VALOR REMANESCENTE - C1 Calculado automaticamente | G1: =IF(parametros!$I$4="","QTD. REMANESCENTE - C2","QTD. REMANESCENTE - C2"&CHAR(10)&"Informe a quantidade existente em "&RIGHT("0"&DAY(parametros!$I$4),2)&"/"&RIGHT("0"&MONTH(parametros!$I$4),2)&"/"&YEAR(parametros!$I$4)) -> QTD. REMANESCENTE - C2 | H1: ="VALOR REMANESCENTE - C2"&CHAR(10)&"Calculado automaticamente" -> VALOR REMANESCENTE - C2 Calculado automaticamente | I1: =IF(parametros!$I$5="","QTD. REMANESCENTE - C3","QTD. REMANESCENTE - C3"&CHAR(10)&"Informe a quantidade existente em "&RIGHT("0"&DAY(parametros!$I$5),2)&"/"&RIGHT("0"&MONTH(parametros!$I$5),2)&"/"&YEAR(parametros!$I$5)) -> QTD. REMANESCENTE - C3 | J1: ="VALOR REMANESCENTE - C3"&CHAR(10)&"Calculado automaticamente" -> VALOR REMANESCENTE - C3 Calculado automaticamente | K1: =IF(parametros!$I$6="","QTD. REMANESCENTE - C4","QTD. REMANESCENTE - C4"&CHAR(10)&"Informe a quantidade existente em "&RIGHT("0"&DAY(parametros!$I$6),2)&"/"&RIGHT("0"&MONTH(parametros!$I$6),2)&"/"&YEAR(parametros!$I$6)) -> QTD. REMANESCENTE - C4 | L1: ="VALOR REMANESCENTE - C4"&CHAR(10)&"Calculado automaticamente" -> VALOR REMANESCENTE - C4 Calculado automaticamente | M1: ="QTD. EXECUTADA - C1"&CHAR(10)&"Calculada automaticamente" -> QTD. EXECUTADA - C1 Calculada automaticamente | N1: ="VALOR EXECUTADO - C1"&CHAR(10)&"Calculado automaticamente" -> VALOR EXECUTADO - C1 Calculado automaticamente | O1: ="QTD. EXECUTADA - C2"&CHAR(10)&"Calculada automaticamente" -> QTD. EXECUTADA - C2 Calculada automaticamente | P1: ="VALOR EXECUTADO - C2"&CHAR(10)&"Calculado automaticamente" -> VALOR EXECUTADO - C2 Calculado automaticamente | Q1: ="QTD. EXECUTADA - C3"&CHAR(10)&"Calculada automaticamente" -> QTD. EXECUTADA - C3 Calculada automaticamente | R1: ="VALOR EXECUTADO - C3"&CHAR(10)&"Calculado automaticamente" -> VALOR EXECUTADO - C3 Calculado automaticamente | S1: ="QTD. EXECUTADA - C4"&CHAR(10)&"Calculada automaticamente" -> QTD. EXECUTADA - C4 Calculada automaticamente | T1: ="VALOR EXECUTADO - C4"&CHAR(10)&"Calculado automaticamente" -> VALOR EXECUTADO - C4 Calculado automaticamente | U1: CHECK | V1: CHECK_QTD | W1: CICLO | X1: COMPUTAR_NESTA_APURACAO | Y1: FATOR_PROPRIO | Z1: FATOR_ACUMULADO | AA1: EXECUÇÃO IMPLÍCITA C0 — INFORMATIVO | AB1: QTD_EXECUTADA_C0 | AC1: VALOR_EXECUTADO_C0 | AD1: QTD_CONTRATADA_VIGENTE_C0 | AE1: QTD_CONTRATADA_VIGENTE_C1 | AF1: QTD_CONTRATADA_VIGENTE_C2 | AG1: QTD_CONTRATADA_VIGENTE_C3 | AH1: QTD_CONTRATADA_VIGENTE_C4 | AI1: QTD_REM_AJUSTADA_C0 | AJ1: QTD_REM_AJUSTADA_C1 | AK1: QTD_REM_AJUSTADA_C2 | AL1: QTD_REM_AJUSTADA_C3 | AM1: QTD_REM_AJUSTADA_C4 | AN1: CHECK_POSICAO_CONTRATUAL | AO1: QTD_COBERTA_C0 | AP1: QTD_NAO_COBERTA_C0 | AQ1: PARCELA_A_C0 | AR1: PARCELA_B_C0 | AS1: QTD_COBERTA_C1 | AT1: QTD_NAO_COBERTA_C1 | AU1: PARCELA_A_C1 | AV1: PARCELA_B_C1 | AW1: QTD_COBERTA_C2 | AX1: QTD_NAO_COBERTA_C2 | AY1: PARCELA_A_C2 | AZ1: PARCELA_B_C2 | BA1: QTD_COBERTA_C3 | BB1: QTD_NAO_COBERTA_C3 | BC1: PARCELA_A_C3 | BD1: PARCELA_B_C3 | BE1: QTD_COBERTA_C4 | BF1: QTD_NAO_COBERTA_C4 | BG1: PARCELA_A_C4 | BH1: PARCELA_B_C4 | BI1: CICLO_NASCIMENTO_DATA (AUTO)
A2: ITEM-001 | B2: 120 | C2: 250 | D2: =IF(FALSE,ROUND(SUMIF($A1:A$2,"<>",$D1:D$2),2),IF(OR(A2="",B2="",C2=""),"",ROUND(B2*C2,2))) -> 30000 | E2: 120 | F2: =IF(OR(A2="",AND(ISNUMBER(posicao_contratual!$AL2),posicao_contratual!$AL2>1),posicao_contratual!K2="",NOT(ISNUMBER(historico_VU!D2))),"",ROUND(posicao_contratual!K2*historico_VU!D2,2)) -> 31536 | G2: 120 | H2: =IF(OR(A2="",AND(ISNUMBER(posicao_contratual!$AL2),posicao_contratual!$AL2>2),posicao_contratual!O2="",NOT(ISNUMBER(historico_VU!E2))),"",ROUND(posicao_contratual!O2*historico_VU!E2,2)) -> 32715.6 | I2: 120 | J2: =IF(OR(A2="",AND(ISNUMBER(posicao_contratual!$AL2),posicao_contratual!$AL2>3),posicao_contratual!S2="",NOT(ISNUMBER(historico_VU!F2))),"",ROUND(posicao_contratual!S2*historico_VU!F2,2)) -> 33661.2 | K2: 120 | L2: =IF(OR(A2="",AND(ISNUMBER(posicao_contratual!$AL2),posicao_contratual!$AL2>4),posicao_contratual!W2="",NOT(ISNUMBER(historico_VU!G2))),"",ROUND(posicao_contratual!W2*historico_VU!G2,2)) | M2: 120 | N2: =IF(OR(M2="",NOT(ISNUMBER(historico_VU!D2))),"",ROUND(M2*historico_VU!D2,2)) -> 31536 | O2: =IF(OR(posicao_contratual!N2="",posicao_contratual!R2=""),"",ROUND(MAX(posicao_contratual!N2+posicao_contratual!L2-posicao_contratual!R2,0),2)) -> 0 | P2: =IF(OR(O2="",NOT(ISNUMBER(historico_VU!E2))),"",ROUND(O2*historico_VU!E2,2)) -> 0 | Q2: =IF(OR(posicao_contratual!R2="",posicao_contratual!V2=""),"",ROUND(MAX(posicao_contratual!R2+posicao_contratual!P2-posicao_contratual!V2,0),2)) -> 0 | R2: =IF(OR(Q2="",NOT(ISNUMBER(historico_VU!F2))),"",ROUND(Q2*historico_VU!F2,2)) -> 0 | T2: =IF(OR(S2="",NOT(ISNUMBER(historico_VU!G2))),"",ROUND(S2*historico_VU!G2,2)) | U2: =IF(A2="","",posicao_contratual!X2) -> OK | V2: =IF(A2="","",posicao_contratual!X2) -> OK | W2: C0 | X2: =parametros!$A$2 -> Nao | Y2: =IF(ISNUMBER(parametros!$E$2),parametros!$E$2,"") | Z2: =IF(ISNUMBER(parametros!$F$2),parametros!$F$2,"") -> 1 | AB2: =IF(OR(A2="",posicao_contratual!E2="",posicao_contratual!J2=""),"",ROUND(MAX(posicao_contratual!E2-posicao_contratual!J2,0),2)) -> 0 | AC2: =IF(OR(AB2="",NOT(ISNUMBER(historico_VU!C2))),"",ROUND(AB2*historico_VU!C2,2)) -> 0 | AD2: =IF(A2="","",posicao_contratual!E2) -> 120 | AE2: =IF(A2="","",posicao_contratual!I2) -> 120 | AF2: =IF(A2="","",posicao_contratual!M2) -> 120 | AG2: =IF(A2="","",posicao_contratual!Q2) -> 120 | AH2: =IF(A2="","",posicao_contratual!U2) -> 120 | AI2: =IF(A2="","",posicao_contratual!G2) -> 120 | AJ2: =IF(A2="","",posicao_contratual!K2) -> 120 | AK2: =IF(A2="","",posicao_contratual!O2) -> 120 | AL2: =IF(A2="","",posicao_contratual!S2) -> 120 | AM2: =IF(A2="","",posicao_contratual!W2) -> 120 | AN2: =IF(A2="","",posicao_contratual!X2) -> OK | AO2: =IF($A2="","",ROUND(SUMIFS(itens_Consumidos!$E$2:$E$200,itens_Consumidos!$A$2:$A$200,$A2),2)) -> 0 | AP2: =IF(OR($A2="",AB2=""),"",ROUND(MAX(AB2-AO2,0),2)) -> 0 | AQ2: =IF(OR($A2="",AB2="",MEMORIA_RESULTADOS!$I$258=""),"",ROUND(AB2*$C2*(MEMORIA_RESULTADOS!$I$258-1),2)) -> 0 | AR2: =IF(OR($A2="",AP2="",MEMORIA_RESULTADOS!$I$258=""),"",ROUND(AP2*$C2*(parametros!$F$2-MEMORIA_RESULTADOS!$I$258),2)) -> 0 | AS2: =IF($A2="","",ROUND(SUMIFS(itens_Consumidos!$G$2:$G$200,itens_Consumidos!$A$2:$A$200,$A2),2)) -> 0 | AT2: =IF(OR($A2="",M2=""),"",ROUND(MAX(M2-AS2,0),2)) -> 120 | AU2: =IF(OR($A2="",M2="",MEMORIA_RESULTADOS!$I$259=""),"",ROUND(M2*$C2*(MEMORIA_RESULTADOS!$I$259-1),2)) -> 0 | AV2: =IF(OR($A2="",AT2="",MEMORIA_RESULTADOS!$I$259=""),"",ROUND(AT2*$C2*(parametros!$F$3-MEMORIA_RESULTADOS!$I$259),2)) -> 1536 | AW2: =IF($A2="","",ROUND(SUMIFS(itens_Consumidos!$I$2:$I$200,itens_Consumidos!$A$2:$A$200,$A2),2)) -> 0 | AX2: =IF(OR($A2="",O2=""),"",ROUND(MAX(O2-AW2,0),2)) -> 0 | AY2: =IF(OR($A2="",O2="",MEMORIA_RESULTADOS!$I$260=""),"",ROUND(O2*$C2*(MEMORIA_RESULTADOS!$I$260-1),2)) | AZ2: =IF(OR($A2="",AX2="",MEMORIA_RESULTADOS!$I$260=""),"",ROUND(AX2*$C2*(parametros!$F$4-MEMORIA_RESULTADOS!$I$260),2)) | BA2: =IF($A2="","",ROUND(SUMIFS(itens_Consumidos!$K$2:$K$200,itens_Consumidos!$A$2:$A$200,$A2),2)) -> 0 | BB2: =IF(OR($A2="",Q2=""),"",ROUND(MAX(Q2-BA2,0),2)) -> 0 | BC2: =IF(OR($A2="",Q2="",MEMORIA_RESULTADOS!$I$261=""),"",ROUND(Q2*$C2*(MEMORIA_RESULTADOS!$I$261-1),2)) | BD2: =IF(OR($A2="",BB2="",MEMORIA_RESULTADOS!$I$261=""),"",ROUND(BB2*$C2*(parametros!$F$5-MEMORIA_RESULTADOS!$I$261),2)) | BE2: =IF($A2="","",ROUND(SUMIFS(itens_Consumidos!$M$2:$M$200,itens_Consumidos!$A$2:$A$200,$A2),2)) -> 0 | BF2: =IF(OR($A2="",S2=""),"",ROUND(MAX(S2-BE2,0),2)) | BG2: =IF(OR($A2="",S2="",MEMORIA_RESULTADOS!$I$262=""),"",ROUND(S2*$C2*(MEMORIA_RESULTADOS!$I$262-1),2)) | BH2: =IF(OR($A2="",BF2="",MEMORIA_RESULTADOS!$I$262=""),"",ROUND(BF2*$C2*(parametros!$F$6-MEMORIA_RESULTADOS!$I$262),2)) | BI2: =IF($A2="","",IF(posicao_contratual!$AL2="","",posicao_contratual!$AL2)) -> 0
A3: ITEM-002 | B3: 80 | C3: 1500 | D3: =IF(AND(A3="",A2<>"",COUNTIF(A4:$A$200,"<>")=0),ROUND(SUMIF($A$2:A2,"<>",$D$2:D2),2),IF(OR(A3="",B3="",C3=""),"",ROUND(B3*C3,2))) -> 120000 | E3: 80 | F3: =IF(AND(A3="",A2<>"",COUNTIF(A4:$A$200,"<>")=0),IF(COUNT(F$2:F2)=0,"",ROUND(SUMIF($A$2:A2,"<>",F$2:F2),2)),IF(OR(A3="",AND(ISNUMBER(posicao_contratual!$AL3),posicao_contratual!$AL3>1),posicao_contratual!K3="",NOT(ISNUMBER(historico_VU!D3))),"",ROUND(posicao_contratual!K3*historico_VU!D3,2))) -> 126144 | G3: 80 | H3: =IF(AND(A3="",A2<>"",COUNTIF(A4:$A$200,"<>")=0),IF(COUNT(H$2:H2)=0,"",ROUND(SUMIF($A$2:A2,"<>",H$2:H2),2)),IF(OR(A3="",AND(ISNUMBER(posicao_contratual!$AL3),posicao_contratual!$AL3>2),posicao_contratual!O3="",NOT(ISNUMBER(historico_VU!E3))),"",ROUND(posicao_contratual!O3*historico_VU!E3,2))) -> 130861.6 | I3: 80 | J3: =IF(AND(A3="",A2<>"",COUNTIF(A4:$A$200,"<>")=0),IF(COUNT(J$2:J2)=0,"",ROUND(SUMIF($A$2:A2,"<>",J$2:J2),2)),IF(OR(A3="",AND(ISNUMBER(posicao_contratual!$AL3),posicao_contratual!$AL3>3),posicao_contratual!S3="",NOT(ISNUMBER(historico_VU!F3))),"",ROUND(posicao_contratual!S3*historico_VU!F3,2))) -> 134644 | K3: 80 | L3: =IF(AND(A3="",A2<>"",COUNTIF(A4:$A$200,"<>")=0),IF(COUNT(L$2:L2)=0,"",ROUND(SUMIF($A$2:A2,"<>",L$2:L2),2)),IF(OR(A3="",AND(ISNUMBER(posicao_contratual!$AL3),posicao_contratual!$AL3>4),posicao_contratual!W3="",NOT(ISNUMBER(historico_VU!G3))),"",ROUND(posicao_contratual!W3*historico_VU!G3,2))) | M3: 80 | N3: =IF(AND(A3="",A2<>"",COUNTIF(A4:$A$200,"<>")=0),IF(COUNT(N$2:N2)=0,"",ROUND(SUMIF($A$2:A2,"<>",N$2:N2),2)),IF(OR(M3="",NOT(ISNUMBER(historico_VU!D3))),"",ROUND(M3*historico_VU!D3,2))) -> 126144 | O3: =IF(OR(posicao_contratual!N3="",posicao_contratual!R3=""),"",ROUND(MAX(posicao_contratual!N3+posicao_contratual!L3-posicao_contratual!R3,0),2)) -> 0 | P3: =IF(AND(A3="",A2<>"",COUNTIF(A4:$A$200,"<>")=0),IF(COUNT(P$2:P2)=0,"",ROUND(SUMIF($A$2:A2,"<>",P$2:P2),2)),IF(OR(O3="",NOT(ISNUMBER(historico_VU!E3))),"",ROUND(O3*historico_VU!E3,2))) -> 0 | Q3: =IF(OR(posicao_contratual!R3="",posicao_contratual!V3=""),"",ROUND(MAX(posicao_contratual!R3+posicao_contratual!P3-posicao_contratual!V3,0),2)) -> 0 | R3: =IF(AND(A3="",A2<>"",COUNTIF(A4:$A$200,"<>")=0),IF(COUNT(R$2:R2)=0,"",ROUND(SUMIF($A$2:A2,"<>",R$2:R2),2)),IF(OR(Q3="",NOT(ISNUMBER(historico_VU!F3))),"",ROUND(Q3*historico_VU!F3,2))) -> 0 | T3: =IF(AND(A3="",A2<>"",COUNTIF(A4:$A$200,"<>")=0),IF(COUNT(T$2:T2)=0,"",ROUND(SUMIF($A$2:A2,"<>",T$2:T2),2)),IF(OR(S3="",NOT(ISNUMBER(historico_VU!G3))),"",ROUND(S3*historico_VU!G3,2))) | U3: =IF(AND(A3="",A2<>"",COUNTIF(A4:$A$200,"<>")=0),"TOTAL",IF(A3="","",posicao_contratual!X3)) -> OK | V3: =IF(A3="","",posicao_contratual!X3) -> OK | W3: C1 | X3: =parametros!$A$3 -> Sim | Y3: =IF(ISNUMBER(parametros!$E$3),parametros!$E$3,"") -> 0.0512 | Z3: =IF(ISNUMBER(parametros!$F$3),parametros!$F$3,"") -> 1.0512 | AB3: =IF(OR(A3="",posicao_contratual!E3="",posicao_contratual!J3=""),"",ROUND(MAX(posicao_contratual!E3-posicao_contratual!J3,0),2)) -> 0 | AC3: =IF(AND(A3="",A2<>"",COUNTIF(A4:$A$200,"<>")=0),IF(COUNT(AC$2:AC2)=0,"",ROUND(SUMIF($A$2:A2,"<>",AC$2:AC2),2)),IF(OR(AB3="",NOT(ISNUMBER(historico_VU!C3))),"",ROUND(AB3*historico_VU!C3,2))) -> 0 | AD3: =IF(A3="","",posicao_contratual!E3) -> 80 | AE3: =IF(A3="","",posicao_contratual!I3) -> 80 | AF3: =IF(A3="","",posicao_contratual!M3) -> 80 | AG3: =IF(A3="","",posicao_contratual!Q3) -> 80 | AH3: =IF(A3="","",posicao_contratual!U3) -> 80 | AI3: =IF(A3="","",posicao_contratual!G3) -> 80 | AJ3: =IF(A3="","",posicao_contratual!K3) -> 80 | AK3: =IF(A3="","",posicao_contratual!O3) -> 80 | AL3: =IF(A3="","",posicao_contratual!S3) -> 80 | AM3: =IF(A3="","",posicao_contratual!W3) -> 80 | AN3: =IF(A3="","",posicao_contratual!X3) -> OK | AO3: =IF($A3="","",ROUND(SUMIFS(itens_Consumidos!$E$2:$E$200,itens_Consumidos!$A$2:$A$200,$A3),2)) -> 0 | AP3: =IF(OR($A3="",AB3=""),"",ROUND(MAX(AB3-AO3,0),2)) -> 0 | AQ3: =IF(OR($A3="",AB3="",MEMORIA_RESULTADOS!$I$258=""),"",ROUND(AB3*$C3*(MEMORIA_RESULTADOS!$I$258-1),2)) -> 0 | AR3: =IF(OR($A3="",AP3="",MEMORIA_RESULTADOS!$I$258=""),"",ROUND(AP3*$C3*(parametros!$F$2-MEMORIA_RESULTADOS!$I$258),2)) -> 0 | AS3: =IF($A3="","",ROUND(SUMIFS(itens_Consumidos!$G$2:$G$200,itens_Consumidos!$A$2:$A$200,$A3),2)) -> 0 | AT3: =IF(OR($A3="",M3=""),"",ROUND(MAX(M3-AS3,0),2)) -> 80 | AU3: =IF(OR($A3="",M3="",MEMORIA_RESULTADOS!$I$259=""),"",ROUND(M3*$C3*(MEMORIA_RESULTADOS!$I$259-1),2)) -> 0 | AV3: =IF(OR($A3="",AT3="",MEMORIA_RESULTADOS!$I$259=""),"",ROUND(AT3*$C3*(parametros!$F$3-MEMORIA_RESULTADOS!$I$259),2)) -> 6144 | AW3: =IF($A3="","",ROUND(SUMIFS(itens_Consumidos!$I$2:$I$200,itens_Consumidos!$A$2:$A$200,$A3),2)) -> 0 | AX3: =IF(OR($A3="",O3=""),"",ROUND(MAX(O3-AW3,0),2)) -> 0 | AY3: =IF(OR($A3="",O3="",MEMORIA_RESULTADOS!$I$260=""),"",ROUND(O3*$C3*(MEMORIA_RESULTADOS!$I$260-1),2)) | AZ3: =IF(OR($A3="",AX3="",MEMORIA_RESULTADOS!$I$260=""),"",ROUND(AX3*$C3*(parametros!$F$4-MEMORIA_RESULTADOS!$I$260),2)) | BA3: =IF($A3="","",ROUND(SUMIFS(itens_Consumidos!$K$2:$K$200,itens_Consumidos!$A$2:$A$200,$A3),2)) -> 0 | BB3: =IF(OR($A3="",Q3=""),"",ROUND(MAX(Q3-BA3,0),2)) -> 0 | BC3: =IF(OR($A3="",Q3="",MEMORIA_RESULTADOS!$I$261=""),"",ROUND(Q3*$C3*(MEMORIA_RESULTADOS!$I$261-1),2)) | BD3: =IF(OR($A3="",BB3="",MEMORIA_RESULTADOS!$I$261=""),"",ROUND(BB3*$C3*(parametros!$F$5-MEMORIA_RESULTADOS!$I$261),2)) | BE3: =IF($A3="","",ROUND(SUMIFS(itens_Consumidos!$M$2:$M$200,itens_Consumidos!$A$2:$A$200,$A3),2)) -> 0 | BF3: =IF(OR($A3="",S3=""),"",ROUND(MAX(S3-BE3,0),2)) | BG3: =IF(OR($A3="",S3="",MEMORIA_RESULTADOS!$I$262=""),"",ROUND(S3*$C3*(MEMORIA_RESULTADOS!$I$262-1),2)) | BH3: =IF(OR($A3="",BF3="",MEMORIA_RESULTADOS!$I$262=""),"",ROUND(BF3*$C3*(parametros!$F$6-MEMORIA_RESULTADOS!$I$262),2)) | BI3: =IF($A3="","",IF(posicao_contratual!$AL3="","",posicao_contratual!$AL3)) -> 0
A4: ITEM-003 | B4: 40 | C4: 3200 | D4: =IF(AND(A4="",A3<>"",COUNTIF(A5:$A$200,"<>")=0),ROUND(SUMIF($A$2:A3,"<>",$D$2:D3),2),IF(OR(A4="",B4="",C4=""),"",ROUND(B4*C4,2))) -> 128000 | E4: 40 | F4: =IF(AND(A4="",A3<>"",COUNTIF(A5:$A$200,"<>")=0),IF(COUNT(F$2:F3)=0,"",ROUND(SUMIF($A$2:A3,"<>",F$2:F3),2)),IF(OR(A4="",AND(ISNUMBER(posicao_contratual!$AL4),posicao_contratual!$AL4>1),posicao_contratual!K4="",NOT(ISNUMBER(historico_VU!D4))),"",ROUND(posicao_contratual!K4*historico_VU!D4,2))) -> 134553.6 | G4: 40 | H4: =IF(AND(A4="",A3<>"",COUNTIF(A5:$A$200,"<>")=0),IF(COUNT(H$2:H3)=0,"",ROUND(SUMIF($A$2:A3,"<>",H$2:H3),2)),IF(OR(A4="",AND(ISNUMBER(posicao_contratual!$AL4),posicao_contratual!$AL4>2),posicao_contratual!O4="",NOT(ISNUMBER(historico_VU!E4))),"",ROUND(posicao_contratual!O4*historico_VU!E4,2))) -> 139586 | I4: 40 | J4: =IF(AND(A4="",A3<>"",COUNTIF(A5:$A$200,"<>")=0),IF(COUNT(J$2:J3)=0,"",ROUND(SUMIF($A$2:A3,"<>",J$2:J3),2)),IF(OR(A4="",AND(ISNUMBER(posicao_contratual!$AL4),posicao_contratual!$AL4>3),posicao_contratual!S4="",NOT(ISNUMBER(historico_VU!F4))),"",ROUND(posicao_contratual!S4*historico_VU!F4,2))) -> 143620 | K4: 40 | L4: =IF(AND(A4="",A3<>"",COUNTIF(A5:$A$200,"<>")=0),IF(COUNT(L$2:L3)=0,"",ROUND(SUMIF($A$2:A3,"<>",L$2:L3),2)),IF(OR(A4="",AND(ISNUMBER(posicao_contratual!$AL4),posicao_contratual!$AL4>4),posicao_contratual!W4="",NOT(ISNUMBER(historico_VU!G4))),"",ROUND(posicao_contratual!W4*historico_VU!G4,2))) | M4: 40 | N4: =IF(AND(A4="",A3<>"",COUNTIF(A5:$A$200,"<>")=0),IF(COUNT(N$2:N3)=0,"",ROUND(SUMIF($A$2:A3,"<>",N$2:N3),2)),IF(OR(M4="",NOT(ISNUMBER(historico_VU!D4))),"",ROUND(M4*historico_VU!D4,2))) -> 134553.6 | O4: =IF(OR(posicao_contratual!N4="",posicao_contratual!R4=""),"",ROUND(MAX(posicao_contratual!N4+posicao_contratual!L4-posicao_contratual!R4,0),2)) -> 0 | P4: =IF(AND(A4="",A3<>"",COUNTIF(A5:$A$200,"<>")=0),IF(COUNT(P$2:P3)=0,"",ROUND(SUMIF($A$2:A3,"<>",P$2:P3),2)),IF(OR(O4="",NOT(ISNUMBER(historico_VU!E4))),"",ROUND(O4*historico_VU!E4,2))) -> 0 | Q4: =IF(OR(posicao_contratual!R4="",posicao_contratual!V4=""),"",ROUND(MAX(posicao_contratual!R4+posicao_contratual!P4-posicao_contratual!V4,0),2)) -> 0 | R4: =IF(AND(A4="",A3<>"",COUNTIF(A5:$A$200,"<>")=0),IF(COUNT(R$2:R3)=0,"",ROUND(SUMIF($A$2:A3,"<>",R$2:R3),2)),IF(OR(Q4="",NOT(ISNUMBER(historico_VU!F4))),"",ROUND(Q4*historico_VU!F4,2))) -> 0 | T4: =IF(AND(A4="",A3<>"",COUNTIF(A5:$A$200,"<>")=0),IF(COUNT(T$2:T3)=0,"",ROUND(SUMIF($A$2:A3,"<>",T$2:T3),2)),IF(OR(S4="",NOT(ISNUMBER(historico_VU!G4))),"",ROUND(S4*historico_VU!G4,2))) | U4: =IF(AND(A4="",A3<>"",COUNTIF(A5:$A$200,"<>")=0),"TOTAL",IF(A4="","",posicao_contratual!X4)) -> OK | V4: =IF(A4="","",posicao_contratual!X4) -> OK | W4: C2 | X4: =parametros!$A$4 -> Nao | Y4: =IF(ISNUMBER(parametros!$E$4),parametros!$E$4,"") -> 0.0374 | Z4: =IF(ISNUMBER(parametros!$F$4),parametros!$F$4,"") -> 1.0905149 | AB4: =IF(OR(A4="",posicao_contratual!E4="",posicao_contratual!J4=""),"",ROUND(MAX(posicao_contratual!E4-posicao_contratual!J4,0),2)) -> 0 | AC4: =IF(AND(A4="",A3<>"",COUNTIF(A5:$A$200,"<>")=0),IF(COUNT(AC$2:AC3)=0,"",ROUND(SUMIF($A$2:A3,"<>",AC$2:AC3),2)),IF(OR(AB4="",NOT(ISNUMBER(historico_VU!C4))),"",ROUND(AB4*historico_VU!C4,2))) -> 0 | AD4: =IF(A4="","",posicao_contratual!E4) -> 40 | AE4: =IF(A4="","",posicao_contratual!I4) -> 40 | AF4: =IF(A4="","",posicao_contratual!M4) -> 40 | AG4: =IF(A4="","",posicao_contratual!Q4) -> 40 | AH4: =IF(A4="","",posicao_contratual!U4) -> 40 | AI4: =IF(A4="","",posicao_contratual!G4) -> 40 | AJ4: =IF(A4="","",posicao_contratual!K4) -> 40 | AK4: =IF(A4="","",posicao_contratual!O4) -> 40 | AL4: =IF(A4="","",posicao_contratual!S4) -> 40 | AM4: =IF(A4="","",posicao_contratual!W4) -> 40 | AN4: =IF(A4="","",posicao_contratual!X4) -> OK | AO4: =IF($A4="","",ROUND(SUMIFS(itens_Consumidos!$E$2:$E$200,itens_Consumidos!$A$2:$A$200,$A4),2)) -> 0 | AP4: =IF(OR($A4="",AB4=""),"",ROUND(MAX(AB4-AO4,0),2)) -> 0 | AQ4: =IF(OR($A4="",AB4="",MEMORIA_RESULTADOS!$I$258=""),"",ROUND(AB4*$C4*(MEMORIA_RESULTADOS!$I$258-1),2)) -> 0 | AR4: =IF(OR($A4="",AP4="",MEMORIA_RESULTADOS!$I$258=""),"",ROUND(AP4*$C4*(parametros!$F$2-MEMORIA_RESULTADOS!$I$258),2)) -> 0 | AS4: =IF($A4="","",ROUND(SUMIFS(itens_Consumidos!$G$2:$G$200,itens_Consumidos!$A$2:$A$200,$A4),2)) -> 0 | AT4: =IF(OR($A4="",M4=""),"",ROUND(MAX(M4-AS4,0),2)) -> 40 | AU4: =IF(OR($A4="",M4="",MEMORIA_RESULTADOS!$I$259=""),"",ROUND(M4*$C4*(MEMORIA_RESULTADOS!$I$259-1),2)) -> 0 | AV4: =IF(OR($A4="",AT4="",MEMORIA_RESULTADOS!$I$259=""),"",ROUND(AT4*$C4*(parametros!$F$3-MEMORIA_RESULTADOS!$I$259),2)) -> 6553.6 | AW4: =IF($A4="","",ROUND(SUMIFS(itens_Consumidos!$I$2:$I$200,itens_Consumidos!$A$2:$A$200,$A4),2)) -> 0 | AX4: =IF(OR($A4="",O4=""),"",ROUND(MAX(O4-AW4,0),2)) -> 0 | AY4: =IF(OR($A4="",O4="",MEMORIA_RESULTADOS!$I$260=""),"",ROUND(O4*$C4*(MEMORIA_RESULTADOS!$I$260-1),2)) | AZ4: =IF(OR($A4="",AX4="",MEMORIA_RESULTADOS!$I$260=""),"",ROUND(AX4*$C4*(parametros!$F$4-MEMORIA_RESULTADOS!$I$260),2)) | BA4: =IF($A4="","",ROUND(SUMIFS(itens_Consumidos!$K$2:$K$200,itens_Consumidos!$A$2:$A$200,$A4),2)) -> 0 | BB4: =IF(OR($A4="",Q4=""),"",ROUND(MAX(Q4-BA4,0),2)) -> 0 | BC4: =IF(OR($A4="",Q4="",MEMORIA_RESULTADOS!$I$261=""),"",ROUND(Q4*$C4*(MEMORIA_RESULTADOS!$I$261-1),2)) | BD4: =IF(OR($A4="",BB4="",MEMORIA_RESULTADOS!$I$261=""),"",ROUND(BB4*$C4*(parametros!$F$5-MEMORIA_RESULTADOS!$I$261),2)) | BE4: =IF($A4="","",ROUND(SUMIFS(itens_Consumidos!$M$2:$M$200,itens_Consumidos!$A$2:$A$200,$A4),2)) -> 0 | BF4: =IF(OR($A4="",S4=""),"",ROUND(MAX(S4-BE4,0),2)) | BG4: =IF(OR($A4="",S4="",MEMORIA_RESULTADOS!$I$262=""),"",ROUND(S4*$C4*(MEMORIA_RESULTADOS!$I$262-1),2)) | BH4: =IF(OR($A4="",BF4="",MEMORIA_RESULTADOS!$I$262=""),"",ROUND(BF4*$C4*(parametros!$F$6-MEMORIA_RESULTADOS!$I$262),2)) | BI4: =IF($A4="","",IF(posicao_contratual!$AL4="","",posicao_contratual!$AL4)) -> 0
