Workbook
Name AJUSTE_MANUAL_VTA: MEMORIA_RESULTADOS!$B$24
Name AJUSTES_DEVIDOS: RESULTADOS!$B$84
Name AUDITORIA_ABERTURA_STATUS: RESULTADOS!$H$11
Name AUDITORIA_COMPARATIVO_INTEGRAL: comparativo_VTA!$B$208
Name AUDITORIA_CONFERENCIA_STATUS: MEMORIA_RESULTADOS!$W$52
Name AUDITORIA_DIFERENCA_REFERENCIAS: MEMORIA_RESULTADOS!$W$51
Name AUDITORIA_SITUACAO_ATUAL_CONTRATO: MEMORIA_RESULTADOS!$W$50
Name AUDITORIA_SITUACAO_ATUAL_STATUS: RESULTADOS!$H$10
Name AUDITORIA_ULTIMA_REFERENCIA_ABERTURA: MEMORIA_RESULTADOS!$W$48
Name CICLO_EM_EXECUCAO_LAYOUT_VERSION: CICLO_EM_EXECUCAO!$H$2
Name CONFERENCIA_FORMACAO_VTA: RESULTADOS!$B$87
Name EXECUCAO_ATUALIZADA_CICLO: RESULTADOS!$B$36
Name EXECUTADO_APURADO: RESULTADOS!$B$83
Name JUSTIFICATIVA_RETRO: MEMORIA_RESULTADOS!$D$5
Name METODO_RETROATIVO: MEMORIA_RESULTADOS!$B$4
Name OPCOES_APLICAR_MANUAL: RESULTADOS!$J$2:$J$3
Name OPCOES_SIM_NAO: parametros!$T$2:$T$3
Name OPCOES_SIM_NAO_NA: parametros!$T$2:$T$4
Name PC_TOTAL_ATE_CORTE: MEMORIA_RESULTADOS!$T$34
Name PC_TOTAL_CADASTRADO: MEMORIA_RESULTADOS!$T$33
Name PC_TOTAL_COM_EFEITO: MEMORIA_RESULTADOS!$T$36
Name PC_TOTAL_SEM_EFEITO: MEMORIA_RESULTADOS!$T$37
Name QTD_REM_OFICIAL: MEMORIA_RESULTADOS!$B$35
Name REM_ATUALIZADO_OFICIAL: MEMORIA_RESULTADOS!$D$35
Name REM_BASE_OFICIAL: MEMORIA_RESULTADOS!$C$35
Name RETRO_FIN: MEMORIA_RESULTADOS!$B$15
Name RETRO_ITENS: MEMORIA_RESULTADOS!$D$15
Name RETRO_OFICIAL: MEMORIA_RESULTADOS!$B$16
Name RETRO_PC: MEMORIA_RESULTADOS!$C$15
Name RETROATIVO_POTENCIAL_APURADO: MEMORIA_RESULTADOS!$T$41
Name RETROATIVO_POTENCIAL_NEGATIVO: MEMORIA_RESULTADOS!$T$47
Name RETROATIVO_POTENCIAL_PC: MEMORIA_RESULTADOS!$T$38
Name RETROATIVO_POTENCIAL_VTA: MEMORIA_RESULTADOS!$T$39
Name SALDO_REMANESCENTE_ATUAL: RESULTADOS!$B$38
Name STATUS_RESULTADOS: RESULTADOS!$B$3
Name TOLERANCIA_DIVERGENCIA: MEMORIA_RESULTADOS!$D$4
Name VALOR_MANUAL_RETRO: MEMORIA_RESULTADOS!$B$5
Name VTA_ATUALIZACAO_CHEIA: RESULTADOS!$B$12
Name VTA_CALCULADO: MEMORIA_RESULTADOS!$B$23
Name VTA_FINAL: MEMORIA_RESULTADOS!$B$26
Name VTA_MANUAL_OFICIAL: MEMORIA_RESULTADOS!$B$25
Name VTA_SEM_POTENCIAL: MEMORIA_RESULTADOS!$T$40

Sheet comparativo_VTA
A1: comparativo_VTA - REFERENCIA (nao aparece na web; nao e VTA de pagamento)
A2: BLOCO 1 - EVOLUCAO DO REMANESCENTE A PRECOS ORIGINAIS (sem reajuste)
A3: ITEM | B3: VU_ORIGINAL | C3: C0 | D3: C1 | E3: C2 | F3: C3 | G3: C4
A4: =IF(posicao_contratual!A2="","",posicao_contratual!A2) -> ITEM-001 | B4: =IF(posicao_contratual!A2="","",posicao_contratual!B2) -> 250 | C4: =IF(OR(posicao_contratual!A2="",NOT(ISNUMBER(posicao_contratual!B2)),NOT(ISNUMBER(posicao_contratual!G2))),"",ROUND(posicao_contratual!B2*posicao_contratual!G2,2)) -> 30000 | D4: =IF(OR(posicao_contratual!A2="",NOT(ISNUMBER(posicao_contratual!B2)),NOT(ISNUMBER(posicao_contratual!K2))),"",ROUND(posicao_contratual!B2*posicao_contratual!K2,2)) -> 32500 | E4: =IF(OR(posicao_contratual!A2="",NOT(ISNUMBER(posicao_contratual!B2)),NOT(ISNUMBER(posicao_contratual!O2))),"",ROUND(posicao_contratual!B2*posicao_contratual!O2,2)) -> 30000 | F4: =IF(OR(posicao_contratual!A2="",NOT(ISNUMBER(posicao_contratual!B2)),NOT(ISNUMBER(posicao_contratual!S2))),"",ROUND(posicao_contratual!B2*posicao_contratual!S2,2)) -> 30000 | G4: =IF(OR(posicao_contratual!A2="",NOT(ISNUMBER(posicao_contratual!B2)),NOT(ISNUMBER(posicao_contratual!W2))),"",ROUND(posicao_contratual!B2*posicao_contratual!W2,2)) -> 30000
A5: =IF(posicao_contratual!A3="","",posicao_contratual!A3) -> ITEM-002 | B5: =IF(posicao_contratual!A3="","",posicao_contratual!B3) -> 1500 | C5: =IF(OR(posicao_contratual!A3="",NOT(ISNUMBER(posicao_contratual!B3)),NOT(ISNUMBER(posicao_contratual!G3))),"",ROUND(posicao_contratual!B3*posicao_contratual!G3,2)) -> 120000 | D5: =IF(OR(posicao_contratual!A3="",NOT(ISNUMBER(posicao_contratual!B3)),NOT(ISNUMBER(posicao_contratual!K3))),"",ROUND(posicao_contratual!B3*posicao_contratual!K3,2)) -> 120000 | E5: =IF(OR(posicao_contratual!A3="",NOT(ISNUMBER(posicao_contratual!B3)),NOT(ISNUMBER(posicao_contratual!O3))),"",ROUND(posicao_contratual!B3*posicao_contratual!O3,2)) -> 120000 | F5: =IF(OR(posicao_contratual!A3="",NOT(ISNUMBER(posicao_contratual!B3)),NOT(ISNUMBER(posicao_contratual!S3))),"",ROUND(posicao_contratual!B3*posicao_contratual!S3,2)) -> 120000 | G5: =IF(OR(posicao_contratual!A3="",NOT(ISNUMBER(posicao_contratual!B3)),NOT(ISNUMBER(posicao_contratual!W3))),"",ROUND(posicao_contratual!B3*posicao_contratual!W3,2)) -> 120000
A6: =IF(posicao_contratual!A4="","",posicao_contratual!A4) -> ITEM-003 | B6: =IF(posicao_contratual!A4="","",posicao_contratual!B4) -> 3200 | C6: =IF(OR(posicao_contratual!A4="",NOT(ISNUMBER(posicao_contratual!B4)),NOT(ISNUMBER(posicao_contratual!G4))),"",ROUND(posicao_contratual!B4*posicao_contratual!G4,2)) -> 128000 | D6: =IF(OR(posicao_contratual!A4="",NOT(ISNUMBER(posicao_contratual!B4)),NOT(ISNUMBER(posicao_contratual!K4))),"",ROUND(posicao_contratual!B4*posicao_contratual!K4,2)) -> 128000 | E6: =IF(OR(posicao_contratual!A4="",NOT(ISNUMBER(posicao_contratual!B4)),NOT(ISNUMBER(posicao_contratual!O4))),"",ROUND(posicao_contratual!B4*posicao_contratual!O4,2)) -> 128000 | F6: =IF(OR(posicao_contratual!A4="",NOT(ISNUMBER(posicao_contratual!B4)),NOT(ISNUMBER(posicao_contratual!S4))),"",ROUND(posicao_contratual!B4*posicao_contratual!S4,2)) -> 128000 | G6: =IF(OR(posicao_contratual!A4="",NOT(ISNUMBER(posicao_contratual!B4)),NOT(ISNUMBER(posicao_contratual!W4))),"",ROUND(posicao_contratual!B4*posicao_contratual!W4,2)) -> 128000
A7: =IF(posicao_contratual!A5="","",posicao_contratual!A5) | B7: =IF(posicao_contratual!A5="","",posicao_contratual!B5) | C7: =IF(OR(posicao_contratual!A5="",NOT(ISNUMBER(posicao_contratual!B5)),NOT(ISNUMBER(posicao_contratual!G5))),"",ROUND(posicao_contratual!B5*posicao_contratual!G5,2)) | D7: =IF(OR(posicao_contratual!A5="",NOT(ISNUMBER(posicao_contratual!B5)),NOT(ISNUMBER(posicao_contratual!K5))),"",ROUND(posicao_contratual!B5*posicao_contratual!K5,2)) | E7: =IF(OR(posicao_contratual!A5="",NOT(ISNUMBER(posicao_contratual!B5)),NOT(ISNUMBER(posicao_contratual!O5))),"",ROUND(posicao_contratual!B5*posicao_contratual!O5,2)) | F7: =IF(OR(posicao_contratual!A5="",NOT(ISNUMBER(posicao_contratual!B5)),NOT(ISNUMBER(posicao_contratual!S5))),"",ROUND(posicao_contratual!B5*posicao_contratual!S5,2)) | G7: =IF(OR(posicao_contratual!A5="",NOT(ISNUMBER(posicao_contratual!B5)),NOT(ISNUMBER(posicao_contratual!W5))),"",ROUND(posicao_contratual!B5*posicao_contratual!W5,2))
A8: =IF(posicao_contratual!A6="","",posicao_contratual!A6) | B8: =IF(posicao_contratual!A6="","",posicao_contratual!B6) | C8: =IF(OR(posicao_contratual!A6="",NOT(ISNUMBER(posicao_contratual!B6)),NOT(ISNUMBER(posicao_contratual!G6))),"",ROUND(posicao_contratual!B6*posicao_contratual!G6,2)) | D8: =IF(OR(posicao_contratual!A6="",NOT(ISNUMBER(posicao_contratual!B6)),NOT(ISNUMBER(posicao_contratual!K6))),"",ROUND(posicao_contratual!B6*posicao_contratual!K6,2)) | E8: =IF(OR(posicao_contratual!A6="",NOT(ISNUMBER(posicao_contratual!B6)),NOT(ISNUMBER(posicao_contratual!O6))),"",ROUND(posicao_contratual!B6*posicao_contratual!O6,2)) | F8: =IF(OR(posicao_contratual!A6="",NOT(ISNUMBER(posicao_contratual!B6)),NOT(ISNUMBER(posicao_contratual!S6))),"",ROUND(posicao_contratual!B6*posicao_contratual!S6,2)) | G8: =IF(OR(posicao_contratual!A6="",NOT(ISNUMBER(posicao_contratual!B6)),NOT(ISNUMBER(posicao_contratual!W6))),"",ROUND(posicao_contratual!B6*posicao_contratual!W6,2))
A9: =IF(posicao_contratual!A7="","",posicao_contratual!A7) | B9: =IF(posicao_contratual!A7="","",posicao_contratual!B7) | C9: =IF(OR(posicao_contratual!A7="",NOT(ISNUMBER(posicao_contratual!B7)),NOT(ISNUMBER(posicao_contratual!G7))),"",ROUND(posicao_contratual!B7*posicao_contratual!G7,2)) | D9: =IF(OR(posicao_contratual!A7="",NOT(ISNUMBER(posicao_contratual!B7)),NOT(ISNUMBER(posicao_contratual!K7))),"",ROUND(posicao_contratual!B7*posicao_contratual!K7,2)) | E9: =IF(OR(posicao_contratual!A7="",NOT(ISNUMBER(posicao_contratual!B7)),NOT(ISNUMBER(posicao_contratual!O7))),"",ROUND(posicao_contratual!B7*posicao_contratual!O7,2)) | F9: =IF(OR(posicao_contratual!A7="",NOT(ISNUMBER(posicao_contratual!B7)),NOT(ISNUMBER(posicao_contratual!S7))),"",ROUND(posicao_contratual!B7*posicao_contratual!S7,2)) | G9: =IF(OR(posicao_contratual!A7="",NOT(ISNUMBER(posicao_contratual!B7)),NOT(ISNUMBER(posicao_contratual!W7))),"",ROUND(posicao_contratual!B7*posicao_contratual!W7,2))
A10: =IF(posicao_contratual!A8="","",posicao_contratual!A8) | B10: =IF(posicao_contratual!A8="","",posicao_contratual!B8) | C10: =IF(OR(posicao_contratual!A8="",NOT(ISNUMBER(posicao_contratual!B8)),NOT(ISNUMBER(posicao_contratual!G8))),"",ROUND(posicao_contratual!B8*posicao_contratual!G8,2)) | D10: =IF(OR(posicao_contratual!A8="",NOT(ISNUMBER(posicao_contratual!B8)),NOT(ISNUMBER(posicao_contratual!K8))),"",ROUND(posicao_contratual!B8*posicao_contratual!K8,2)) | E10: =IF(OR(posicao_contratual!A8="",NOT(ISNUMBER(posicao_contratual!B8)),NOT(ISNUMBER(posicao_contratual!O8))),"",ROUND(posicao_contratual!B8*posicao_contratual!O8,2)) | F10: =IF(OR(posicao_contratual!A8="",NOT(ISNUMBER(posicao_contratual!B8)),NOT(ISNUMBER(posicao_contratual!S8))),"",ROUND(posicao_contratual!B8*posicao_contratual!S8,2)) | G10: =IF(OR(posicao_contratual!A8="",NOT(ISNUMBER(posicao_contratual!B8)),NOT(ISNUMBER(posicao_contratual!W8))),"",ROUND(posicao_contratual!B8*posicao_contratual!W8,2))
A11: =IF(posicao_contratual!A9="","",posicao_contratual!A9) | B11: =IF(posicao_contratual!A9="","",posicao_contratual!B9) | C11: =IF(OR(posicao_contratual!A9="",NOT(ISNUMBER(posicao_contratual!B9)),NOT(ISNUMBER(posicao_contratual!G9))),"",ROUND(posicao_contratual!B9*posicao_contratual!G9,2)) | D11: =IF(OR(posicao_contratual!A9="",NOT(ISNUMBER(posicao_contratual!B9)),NOT(ISNUMBER(posicao_contratual!K9))),"",ROUND(posicao_contratual!B9*posicao_contratual!K9,2)) | E11: =IF(OR(posicao_contratual!A9="",NOT(ISNUMBER(posicao_contratual!B9)),NOT(ISNUMBER(posicao_contratual!O9))),"",ROUND(posicao_contratual!B9*posicao_contratual!O9,2)) | F11: =IF(OR(posicao_contratual!A9="",NOT(ISNUMBER(posicao_contratual!B9)),NOT(ISNUMBER(posicao_contratual!S9))),"",ROUND(posicao_contratual!B9*posicao_contratual!S9,2)) | G11: =IF(OR(posicao_contratual!A9="",NOT(ISNUMBER(posicao_contratual!B9)),NOT(ISNUMBER(posicao_contratual!W9))),"",ROUND(posicao_contratual!B9*posicao_contratual!W9,2))
A12: =IF(posicao_contratual!A10="","",posicao_contratual!A10) | B12: =IF(posicao_contratual!A10="","",posicao_contratual!B10) | C12: =IF(OR(posicao_contratual!A10="",NOT(ISNUMBER(posicao_contratual!B10)),NOT(ISNUMBER(posicao_contratual!G10))),"",ROUND(posicao_contratual!B10*posicao_contratual!G10,2)) | D12: =IF(OR(posicao_contratual!A10="",NOT(ISNUMBER(posicao_contratual!B10)),NOT(ISNUMBER(posicao_contratual!K10))),"",ROUND(posicao_contratual!B10*posicao_contratual!K10,2)) | E12: =IF(OR(posicao_contratual!A10="",NOT(ISNUMBER(posicao_contratual!B10)),NOT(ISNUMBER(posicao_contratual!O10))),"",ROUND(posicao_contratual!B10*posicao_contratual!O10,2)) | F12: =IF(OR(posicao_contratual!A10="",NOT(ISNUMBER(posicao_contratual!B10)),NOT(ISNUMBER(posicao_contratual!S10))),"",ROUND(posicao_contratual!B10*posicao_contratual!S10,2)) | G12: =IF(OR(posicao_contratual!A10="",NOT(ISNUMBER(posicao_contratual!B10)),NOT(ISNUMBER(posicao_contratual!W10))),"",ROUND(posicao_contratual!B10*posicao_contratual!W10,2))
A13: =IF(posicao_contratual!A11="","",posicao_contratual!A11) | B13: =IF(posicao_contratual!A11="","",posicao_contratual!B11) | C13: =IF(OR(posicao_contratual!A11="",NOT(ISNUMBER(posicao_contratual!B11)),NOT(ISNUMBER(posicao_contratual!G11))),"",ROUND(posicao_contratual!B11*posicao_contratual!G11,2)) | D13: =IF(OR(posicao_contratual!A11="",NOT(ISNUMBER(posicao_contratual!B11)),NOT(ISNUMBER(posicao_contratual!K11))),"",ROUND(posicao_contratual!B11*posicao_contratual!K11,2)) | E13: =IF(OR(posicao_contratual!A11="",NOT(ISNUMBER(posicao_contratual!B11)),NOT(ISNUMBER(posicao_contratual!O11))),"",ROUND(posicao_contratual!B11*posicao_contratual!O11,2)) | F13: =IF(OR(posicao_contratual!A11="",NOT(ISNUMBER(posicao_contratual!B11)),NOT(ISNUMBER(posicao_contratual!S11))),"",ROUND(posicao_contratual!B11*posicao_contratual!S11,2)) | G13: =IF(OR(posicao_contratual!A11="",NOT(ISNUMBER(posicao_contratual!B11)),NOT(ISNUMBER(posicao_contratual!W11))),"",ROUND(posicao_contratual!B11*posicao_contratual!W11,2))
A14: =IF(posicao_contratual!A12="","",posicao_contratual!A12) | B14: =IF(posicao_contratual!A12="","",posicao_contratual!B12) | C14: =IF(OR(posicao_contratual!A12="",NOT(ISNUMBER(posicao_contratual!B12)),NOT(ISNUMBER(posicao_contratual!G12))),"",ROUND(posicao_contratual!B12*posicao_contratual!G12,2)) | D14: =IF(OR(posicao_contratual!A12="",NOT(ISNUMBER(posicao_contratual!B12)),NOT(ISNUMBER(posicao_contratual!K12))),"",ROUND(posicao_contratual!B12*posicao_contratual!K12,2)) | E14: =IF(OR(posicao_contratual!A12="",NOT(ISNUMBER(posicao_contratual!B12)),NOT(ISNUMBER(posicao_contratual!O12))),"",ROUND(posicao_contratual!B12*posicao_contratual!O12,2)) | F14: =IF(OR(posicao_contratual!A12="",NOT(ISNUMBER(posicao_contratual!B12)),NOT(ISNUMBER(posicao_contratual!S12))),"",ROUND(posicao_contratual!B12*posicao_contratual!S12,2)) | G14: =IF(OR(posicao_contratual!A12="",NOT(ISNUMBER(posicao_contratual!B12)),NOT(ISNUMBER(posicao_contratual!W12))),"",ROUND(posicao_contratual!B12*posicao_contratual!W12,2))
A15: =IF(posicao_contratual!A13="","",posicao_contratual!A13) | B15: =IF(posicao_contratual!A13="","",posicao_contratual!B13) | C15: =IF(OR(posicao_contratual!A13="",NOT(ISNUMBER(posicao_contratual!B13)),NOT(ISNUMBER(posicao_contratual!G13))),"",ROUND(posicao_contratual!B13*posicao_contratual!G13,2)) | D15: =IF(OR(posicao_contratual!A13="",NOT(ISNUMBER(posicao_contratual!B13)),NOT(ISNUMBER(posicao_contratual!K13))),"",ROUND(posicao_contratual!B13*posicao_contratual!K13,2)) | E15: =IF(OR(posicao_contratual!A13="",NOT(ISNUMBER(posicao_contratual!B13)),NOT(ISNUMBER(posicao_contratual!O13))),"",ROUND(posicao_contratual!B13*posicao_contratual!O13,2)) | F15: =IF(OR(posicao_contratual!A13="",NOT(ISNUMBER(posicao_contratual!B13)),NOT(ISNUMBER(posicao_contratual!S13))),"",ROUND(posicao_contratual!B13*posicao_contratual!S13,2)) | G15: =IF(OR(posicao_contratual!A13="",NOT(ISNUMBER(posicao_contratual!B13)),NOT(ISNUMBER(posicao_contratual!W13))),"",ROUND(posicao_contratual!B13*posicao_contratual!W13,2))
... A203: =IF(posicao_contratual!A201="","",posicao_contratual!A201) | B203: =IF(posicao_contratual!A201="","",posicao_contratual!B201) | C203: =IF(OR(posicao_contratual!A201="",NOT(ISNUMBER(posicao_contratual!B201)),NOT(ISNUMBER(posicao_contratual!G201))),"",ROUND(posicao_contratual!B201*posicao_contratual!G201,2)) | D203: =IF(OR(posicao_contratual!A201="",NOT(ISNUMBER(posicao_contratual!B201)),NOT(ISNUMBER(posicao_contratual!K201))),"",ROUND(posicao_contratual!B201*posicao_contratual!K201,2)) | E203: =IF(OR(posicao_contratual!A201="",NOT(ISNUMBER(posicao_contratual!B201)),NOT(ISNUMBER(posicao_contratual!O201))),"",ROUND(posicao_contratual!B201*posicao_contratual!O201,2)) | F203: =IF(OR(posicao_contratual!A201="",NOT(ISNUMBER(posicao_contratual!B201)),NOT(ISNUMBER(posicao_contratual!S201))),"",ROUND(posicao_contratual!B201*posicao_contratual!S201,2)) | G203: =IF(OR(posicao_contratual!A201="",NOT(ISNUMBER(posicao_contratual!B201)),NOT(ISNUMBER(posicao_contratual!W201))),"",ROUND(posicao_contratual!B201*posicao_contratual!W201,2))
A204: TOTAL | C204: =ROUND(SUM(C4:C203),2) -> 278000 | D204: =ROUND(SUM(D4:D203),2) -> 280500 | E204: =ROUND(SUM(E4:E203),2) -> 278000 | F204: =ROUND(SUM(F4:F203),2) -> 278000 | G204: =ROUND(SUM(G4:G203),2) -> 278000
A206: BLOCO 2 - COMPARACAO DE REFERENCIA - NAO UTILIZAR COMO VTA OU VALOR DE PAGAMENTO
A207: VTA pelo metodo aplicado | B207: =MEMORIA_RESULTADOS!$B$26 -> 1340973.6
A208: Contrato original integralmente reajustado ate o ciclo atual - REFERENCIA APENAS | B208: =IFERROR(ROUND(SUMPRODUCT(posicao_contratual!$B$2:$B$201,posicao_contratual!$C$2:$C$201)*RESULTADOS!$H$5,2),"") -> 292233.6
A210: O valor integralmente reajustado e apenas um cenario comparativo. Ele pressupoe que todo o contrato original permanecesse sujeito ao fator acumulado final, desconsiderando a execucao ocorrida em ciclos distintos e a reducao do saldo remanescente. Nao utilizar este valor como VTA, retroativo ou base de pagamento.

Sheet CONTROLE
A1: MODO DE LEITURA | B1: Financeiro (Mensalidade)
A2: Ciclo vigente (em execução) | B2: C1
A3: DATA DE CORTE DA APURAÇÃO | B3: 45657 | C3: Última data considerada nos cálculos, PCs, competências e resultados da apuração.
A4: C0 e ciclos fora da analise | B4: Preencher FINANCEIRO: coluna B com o nome do ciclo (ex: c0, c1), coluna C com o valor efetivamente pago. Se vazio, o sistema usa calculo por itens/estoque.
A6: RESUMO DO REAJUSTE | B6: VALOR
A7: Índice utilizado | B7: IST (Anatel)
A8: Data-base original | B8: 44927
A9: Quantidade de ciclos desta análise | B9: =COUNTIF(parametros!A2:A6,"Sim") -> 1
A10: Variação histórica integral até o ciclo vigente | B10: =IF(ISNUMBER(B11),B11-1,"") -> 0.0512
A11: Fator histórico integral (até o ciclo vigente) | B11: =IFERROR(IF(UPPER($B$2)="C0",1,IF(UPPER($B$2)="C1",IF(COUNT(parametros!$E$3:$E$3)=1,parametros!$F$3,""),IF(UPPER($B$2)="C2",IF(COUNT(parametros!$E$3:$E$4)=2,parametros!$F$4,""),IF(UPPER($B$2)="C3",IF(COUNT(parametros!$E$3:$E$5)=3,parametros!$F$5,""),IF(UPPER($B$2)="C4",IF(COUNT(parametros!$E$3:$E$6)=4,parametros!$F$6,""),""))))),"") -> 1.0512
A12: Último ciclo considerado nesta apuração | B12: =IFERROR(IF(parametros!A6="Sim",parametros!B6,IF(parametros!A5="Sim",parametros!B5,IF(parametros!A4="Sim",parametros!B4,IF(parametros!A3="Sim",parametros!B3,IF(parametros!A2="Sim",parametros!B2,"Nenhum"))))),"Nenhum") -> C1
A13: Início do último ciclo considerado | B13: =IFERROR(IF(parametros!A6="Sim",parametros!C6,IF(parametros!A5="Sim",parametros!C5,IF(parametros!A4="Sim",parametros!C4,IF(parametros!A3="Sim",parametros!C3,IF(parametros!A2="Sim",parametros!C2,""))))),"") -> 45292
A14: Data de geracao do arquivo | B14: =NOW() -> 46295.82

Sheet parametros
A1: COMPUTAR_NESTA_APURACAO | B1: CICLO | C1: DATA_INICIO | D1: DATA_FIM | E1: PERCENTUAL_DO_CICLO | F1: FATOR_ACUMULADO | G1: SITUACAO | H1: INICIO_EFEITO_FINANCEIRO | J1: CICLO | K1: TIPO_REGISTRO | L1: ORDEM | M1: COMPETENCIA | N1: VALOR_INDICE | O1: FATOR_MENSAL | P1: FATOR_ACUMULADO | Q1: VARIACAO_FINAL | R1: METODO_FONTE
A2: Nao | B2: C0 | C2: 44927 | D2: 45291 | F2: =1 -> 1 | T2: Sim
A3: Sim | B3: C1 | C3: 45292 | D3: 45657 | E3: 0.0512 | F3: =IF(E3="","",IF(NOT(ISNUMBER(E3)),"",IF(NOT(ISNUMBER(F2)),"",F2*(1+E3)))) -> 1.0512 | G3: TEMPESTIVO | H3: 45292 | T3: Nao | U3: 45270
A4: Nao | B4: C2 | C4: 45658 | D4: 46022 | E4: 0.0374 | F4: =IF(E4="","",IF(NOT(ISNUMBER(E4)),"",IF(NOT(ISNUMBER(F3)),"",F3*(1+E4)))) -> 1.0905149 | G4: TEMPESTIVO | H4: 45658 | T4: N/A | U4: 45638
A5: Nao | B5: C3 | C5: 46023 | D5: 46387 | E5: 0.0289 | F5: =IF(E5="","",IF(NOT(ISNUMBER(E5)),"",IF(NOT(ISNUMBER(F4)),"",F4*(1+E5)))) -> 1.1220308 | G5: TEMPESTIVO | H5: 46023 | U5: 46006
A6: Nao | B6: C4 | C6: 46388 | D6: 46752 | F6: =IF(E6="","",IF(NOT(ISNUMBER(E6)),"",IF(NOT(ISNUMBER(F5)),"",F5*(1+E6))))
A9: MEMORIA DO FATOR APLICAVEL A APURACAO
A10: CICLO | B10: COMPUTA? | C10: PERCENTUAL | D10: FATOR | E10: FATOR_ACUMULADO_APURACAO | F10: STATUS | G10: EXISTE REAJUSTE ANTERIOR FORMALIZADO? (Sim/Não; vazio=não comprovado)
A11: C0 | B11: =A2 -> Nao | C11: =IF(B11="Sim",E2,"") | D11: =1 -> 1 | E11: =1 -> 1 | F11: Base
A12: C1 | B12: =A3 -> Sim | C12: =IF(B12="Sim",E3,"") -> 0.0512 | D12: =IF(C12="","",1+C12) -> 1.0512 | E12: =IF(B12="Sim",E11*D12,E11) -> 1.0512 | F12: =IF(B12="Sim","Aplicado","Fora da apuracao") -> Aplicado
A13: C2 | B13: =A4 -> Nao | C13: =IF(B13="Sim",E4,"") | D13: =IF(C13="","",1+C13) | E13: =IF(B13="Sim",E12*D13,E12) -> 1.0512 | F13: =IF(B13="Sim","Aplicado","Fora da apuracao") -> Fora da apuracao
A14: C3 | B14: =A5 -> Nao | C14: =IF(B14="Sim",E5,"") | D14: =IF(C14="","",1+C14) | E14: =IF(B14="Sim",E13*D14,E13) -> 1.0512 | F14: =IF(B14="Sim","Aplicado","Fora da apuracao") -> Fora da apuracao
A15: C4 | B15: =A6 -> Nao | C15: =IF(B15="Sim",E6,"") | D15: =IF(C15="","",1+C15) | E15: =IF(B15="Sim",E14*D15,E14) -> 1.0512 | F15: =IF(B15="Sim","Aplicado","Fora da apuracao") -> Fora da apuracao
A16: TOTAL APURACAO | D16: =E15 -> 1.0512 | E16: =E15 -> 1.0512 | F16: =E16-1 -> 0.0512

Sheet financeiro
A1: COMPETENCIA | B1: CICLO | C1: VALOR_PAGO | D1: FATOR_APLICAVEL | E1: VALOR_ATUALIZADO | F1: DELTA | G1: EFEITO_FINANCEIRO
A2: 44927 | B2: =IF(A2="","",IF(AND(ISNUMBER(parametros!$C$2),ISNUMBER(parametros!$D$2),A2>=parametros!$C$2,A2<=parametros!$D$2),"c0",IF(AND(ISNUMBER(parametros!$C$3),ISNUMBER(parametros!$D$3),A2>=parametros!$C$3,A2<=parametros!$D$3),"c1",IF(AND(ISNUMBER(parametros!$C$4),ISNUMBER(parametros!$D$4),A2>=parametros!$C$4,A2<=parametros!$D$4),"c2",IF(AND(ISNUMBER(parametros!$C$5),ISNUMBER(parametros!$D$5),A2>=parametros!$C$5,A2<=parametros!$D$5),"c3",IF(AND(ISNUMBER(parametros!$C$6),ISNUMBER(parametros!$D$6),A2>=parametros!$C$6,A2<=parametros!$D$6),"c4","Fora dos ciclos")))))) -> c0 | C2: 42500 | D2: =IF(B2="","",IF(B2="c0",1,IF(B2="c1",IF(parametros!$A$3<>"Sim","",IF(NOT(ISNUMBER(parametros!$E$3)),"",1+parametros!$E$3)),IF(B2="c2",IF(parametros!$A$4<>"Sim","",IF(NOT(ISNUMBER(parametros!$E$4)),"",IF(parametros!$A$3="Sim",1+parametros!$E$3,1)*(1+parametros!$E$4))),IF(B2="c3",IF(parametros!$A$5<>"Sim","",IF(NOT(ISNUMBER(parametros!$E$5)),"",IF(parametros!$A$3="Sim",1+parametros!$E$3,1)*IF(parametros!$A$4="Sim",1+parametros!$E$4,1)*(1+parametros!$E$5))),IF(B2="c4",IF(parametros!$A$6<>"Sim","",IF(NOT(ISNUMBER(parametros!$E$6)),"",IF(parametros!$A$3="Sim",1+parametros!$E$3,1)*IF(parametros!$A$4="Sim",1+parametros!$E$4,1)*IF(parametros!$A$5="Sim",1+parametros!$E$5,1)*(1+parametros!$E$6))),"")))))) -> 1 | E2: =IF(C2="","",IF(G2="","",IF(G2="Sim",IF(NOT(ISNUMBER(D2)),"",ROUND(C2*D2,2)),C2))) -> 42500 | F2: =IF(C2="","",IF(G2="","",IF(G2="Sim",IF(E2="","",ROUND(E2-C2,2)),0))) -> 0 | G2: Sim
A3: 44958 | B3: =IF(A3="","",IF(AND(ISNUMBER(parametros!$C$2),ISNUMBER(parametros!$D$2),A3>=parametros!$C$2,A3<=parametros!$D$2),"c0",IF(AND(ISNUMBER(parametros!$C$3),ISNUMBER(parametros!$D$3),A3>=parametros!$C$3,A3<=parametros!$D$3),"c1",IF(AND(ISNUMBER(parametros!$C$4),ISNUMBER(parametros!$D$4),A3>=parametros!$C$4,A3<=parametros!$D$4),"c2",IF(AND(ISNUMBER(parametros!$C$5),ISNUMBER(parametros!$D$5),A3>=parametros!$C$5,A3<=parametros!$D$5),"c3",IF(AND(ISNUMBER(parametros!$C$6),ISNUMBER(parametros!$D$6),A3>=parametros!$C$6,A3<=parametros!$D$6),"c4","Fora dos ciclos")))))) -> c0 | C3: 42500 | D3: =IF(B3="","",IF(B3="c0",1,IF(B3="c1",IF(parametros!$A$3<>"Sim","",IF(NOT(ISNUMBER(parametros!$E$3)),"",1+parametros!$E$3)),IF(B3="c2",IF(parametros!$A$4<>"Sim","",IF(NOT(ISNUMBER(parametros!$E$4)),"",IF(parametros!$A$3="Sim",1+parametros!$E$3,1)*(1+parametros!$E$4))),IF(B3="c3",IF(parametros!$A$5<>"Sim","",IF(NOT(ISNUMBER(parametros!$E$5)),"",IF(parametros!$A$3="Sim",1+parametros!$E$3,1)*IF(parametros!$A$4="Sim",1+parametros!$E$4,1)*(1+parametros!$E$5))),IF(B3="c4",IF(parametros!$A$6<>"Sim","",IF(NOT(ISNUMBER(parametros!$E$6)),"",IF(parametros!$A$3="Sim",1+parametros!$E$3,1)*IF(parametros!$A$4="Sim",1+parametros!$E$4,1)*IF(parametros!$A$5="Sim",1+parametros!$E$5,1)*(1+parametros!$E$6))),"")))))) -> 1 | E3: =IF(C3="","",IF(G3="","",IF(G3="Sim",IF(NOT(ISNUMBER(D3)),"",ROUND(C3*D3,2)),C3))) -> 42500 | F3: =IF(C3="","",IF(G3="","",IF(G3="Sim",IF(E3="","",ROUND(E3-C3,2)),0))) -> 0 | G3: Sim
A4: 44986 | B4: =IF(A4="","",IF(AND(ISNUMBER(parametros!$C$2),ISNUMBER(parametros!$D$2),A4>=parametros!$C$2,A4<=parametros!$D$2),"c0",IF(AND(ISNUMBER(parametros!$C$3),ISNUMBER(parametros!$D$3),A4>=parametros!$C$3,A4<=parametros!$D$3),"c1",IF(AND(ISNUMBER(parametros!$C$4),ISNUMBER(parametros!$D$4),A4>=parametros!$C$4,A4<=parametros!$D$4),"c2",IF(AND(ISNUMBER(parametros!$C$5),ISNUMBER(parametros!$D$5),A4>=parametros!$C$5,A4<=parametros!$D$5),"c3",IF(AND(ISNUMBER(parametros!$C$6),ISNUMBER(parametros!$D$6),A4>=parametros!$C$6,A4<=parametros!$D$6),"c4","Fora dos ciclos")))))) -> c0 | C4: 42500 | D4: =IF(B4="","",IF(B4="c0",1,IF(B4="c1",IF(parametros!$A$3<>"Sim","",IF(NOT(ISNUMBER(parametros!$E$3)),"",1+parametros!$E$3)),IF(B4="c2",IF(parametros!$A$4<>"Sim","",IF(NOT(ISNUMBER(parametros!$E$4)),"",IF(parametros!$A$3="Sim",1+parametros!$E$3,1)*(1+parametros!$E$4))),IF(B4="c3",IF(parametros!$A$5<>"Sim","",IF(NOT(ISNUMBER(parametros!$E$5)),"",IF(parametros!$A$3="Sim",1+parametros!$E$3,1)*IF(parametros!$A$4="Sim",1+parametros!$E$4,1)*(1+parametros!$E$5))),IF(B4="c4",IF(parametros!$A$6<>"Sim","",IF(NOT(ISNUMBER(parametros!$E$6)),"",IF(parametros!$A$3="Sim",1+parametros!$E$3,1)*IF(parametros!$A$4="Sim",1+parametros!$E$4,1)*IF(parametros!$A$5="Sim",1+parametros!$E$5,1)*(1+parametros!$E$6))),"")))))) -> 1 | E4: =IF(C4="","",IF(G4="","",IF(G4="Sim",IF(NOT(ISNUMBER(D4)),"",ROUND(C4*D4,2)),C4))) -> 42500 | F4: =IF(C4="","",IF(G4="","",IF(G4="Sim",IF(E4="","",ROUND(E4-C4,2)),0))) -> 0 | G4: Sim
A5: 45017 | B5: =IF(A5="","",IF(AND(ISNUMBER(parametros!$C$2),ISNUMBER(parametros!$D$2),A5>=parametros!$C$2,A5<=parametros!$D$2),"c0",IF(AND(ISNUMBER(parametros!$C$3),ISNUMBER(parametros!$D$3),A5>=parametros!$C$3,A5<=parametros!$D$3),"c1",IF(AND(ISNUMBER(parametros!$C$4),ISNUMBER(parametros!$D$4),A5>=parametros!$C$4,A5<=parametros!$D$4),"c2",IF(AND(ISNUMBER(parametros!$C$5),ISNUMBER(parametros!$D$5),A5>=parametros!$C$5,A5<=parametros!$D$5),"c3",IF(AND(ISNUMBER(parametros!$C$6),ISNUMBER(parametros!$D$6),A5>=parametros!$C$6,A5<=parametros!$D$6),"c4","Fora dos ciclos")))))) -> c0 | C5: 42500 | D5: =IF(B5="","",IF(B5="c0",1,IF(B5="c1",IF(parametros!$A$3<>"Sim","",IF(NOT(ISNUMBER(parametros!$E$3)),"",1+parametros!$E$3)),IF(B5="c2",IF(parametros!$A$4<>"Sim","",IF(NOT(ISNUMBER(parametros!$E$4)),"",IF(parametros!$A$3="Sim",1+parametros!$E$3,1)*(1+parametros!$E$4))),IF(B5="c3",IF(parametros!$A$5<>"Sim","",IF(NOT(ISNUMBER(parametros!$E$5)),"",IF(parametros!$A$3="Sim",1+parametros!$E$3,1)*IF(parametros!$A$4="Sim",1+parametros!$E$4,1)*(1+parametros!$E$5))),IF(B5="c4",IF(parametros!$A$6<>"Sim","",IF(NOT(ISNUMBER(parametros!$E$6)),"",IF(parametros!$A$3="Sim",1+parametros!$E$3,1)*IF(parametros!$A$4="Sim",1+parametros!$E$4,1)*IF(parametros!$A$5="Sim",1+parametros!$E$5,1)*(1+parametros!$E$6))),"")))))) -> 1 | E5: =IF(C5="","",IF(G5="","",IF(G5="Sim",IF(NOT(ISNUMBER(D5)),"",ROUND(C5*D5,2)),C5))) -> 42500 | F5: =IF(C5="","",IF(G5="","",IF(G5="Sim",IF(E5="","",ROUND(E5-C5,2)),0))) -> 0 | G5: Sim
A6: 45047 | B6: =IF(A6="","",IF(AND(ISNUMBER(parametros!$C$2),ISNUMBER(parametros!$D$2),A6>=parametros!$C$2,A6<=parametros!$D$2),"c0",IF(AND(ISNUMBER(parametros!$C$3),ISNUMBER(parametros!$D$3),A6>=parametros!$C$3,A6<=parametros!$D$3),"c1",IF(AND(ISNUMBER(parametros!$C$4),ISNUMBER(parametros!$D$4),A6>=parametros!$C$4,A6<=parametros!$D$4),"c2",IF(AND(ISNUMBER(parametros!$C$5),ISNUMBER(parametros!$D$5),A6>=parametros!$C$5,A6<=parametros!$D$5),"c3",IF(AND(ISNUMBER(parametros!$C$6),ISNUMBER(parametros!$D$6),A6>=parametros!$C$6,A6<=parametros!$D$6),"c4","Fora dos ciclos")))))) -> c0 | C6: 42500 | D6: =IF(B6="","",IF(B6="c0",1,IF(B6="c1",IF(parametros!$A$3<>"Sim","",IF(NOT(ISNUMBER(parametros!$E$3)),"",1+parametros!$E$3)),IF(B6="c2",IF(parametros!$A$4<>"Sim","",IF(NOT(ISNUMBER(parametros!$E$4)),"",IF(parametros!$A$3="Sim",1+parametros!$E$3,1)*(1+parametros!$E$4))),IF(B6="c3",IF(parametros!$A$5<>"Sim","",IF(NOT(ISNUMBER(parametros!$E$5)),"",IF(parametros!$A$3="Sim",1+parametros!$E$3,1)*IF(parametros!$A$4="Sim",1+parametros!$E$4,1)*(1+parametros!$E$5))),IF(B6="c4",IF(parametros!$A$6<>"Sim","",IF(NOT(ISNUMBER(parametros!$E$6)),"",IF(parametros!$A$3="Sim",1+parametros!$E$3,1)*IF(parametros!$A$4="Sim",1+parametros!$E$4,1)*IF(parametros!$A$5="Sim",1+parametros!$E$5,1)*(1+parametros!$E$6))),"")))))) -> 1 | E6: =IF(C6="","",IF(G6="","",IF(G6="Sim",IF(NOT(ISNUMBER(D6)),"",ROUND(C6*D6,2)),C6))) -> 42500 | F6: =IF(C6="","",IF(G6="","",IF(G6="Sim",IF(E6="","",ROUND(E6-C6,2)),0))) -> 0 | G6: Sim
A7: 45078 | B7: =IF(A7="","",IF(AND(ISNUMBER(parametros!$C$2),ISNUMBER(parametros!$D$2),A7>=parametros!$C$2,A7<=parametros!$D$2),"c0",IF(AND(ISNUMBER(parametros!$C$3),ISNUMBER(parametros!$D$3),A7>=parametros!$C$3,A7<=parametros!$D$3),"c1",IF(AND(ISNUMBER(parametros!$C$4),ISNUMBER(parametros!$D$4),A7>=parametros!$C$4,A7<=parametros!$D$4),"c2",IF(AND(ISNUMBER(parametros!$C$5),ISNUMBER(parametros!$D$5),A7>=parametros!$C$5,A7<=parametros!$D$5),"c3",IF(AND(ISNUMBER(parametros!$C$6),ISNUMBER(parametros!$D$6),A7>=parametros!$C$6,A7<=parametros!$D$6),"c4","Fora dos ciclos")))))) -> c0 | C7: 42500 | D7: =IF(B7="","",IF(B7="c0",1,IF(B7="c1",IF(parametros!$A$3<>"Sim","",IF(NOT(ISNUMBER(parametros!$E$3)),"",1+parametros!$E$3)),IF(B7="c2",IF(parametros!$A$4<>"Sim","",IF(NOT(ISNUMBER(parametros!$E$4)),"",IF(parametros!$A$3="Sim",1+parametros!$E$3,1)*(1+parametros!$E$4))),IF(B7="c3",IF(parametros!$A$5<>"Sim","",IF(NOT(ISNUMBER(parametros!$E$5)),"",IF(parametros!$A$3="Sim",1+parametros!$E$3,1)*IF(parametros!$A$4="Sim",1+parametros!$E$4,1)*(1+parametros!$E$5))),IF(B7="c4",IF(parametros!$A$6<>"Sim","",IF(NOT(ISNUMBER(parametros!$E$6)),"",IF(parametros!$A$3="Sim",1+parametros!$E$3,1)*IF(parametros!$A$4="Sim",1+parametros!$E$4,1)*IF(parametros!$A$5="Sim",1+parametros!$E$5,1)*(1+parametros!$E$6))),"")))))) -> 1 | E7: =IF(C7="","",IF(G7="","",IF(G7="Sim",IF(NOT(ISNUMBER(D7)),"",ROUND(C7*D7,2)),C7))) -> 42500 | F7: =IF(C7="","",IF(G7="","",IF(G7="Sim",IF(E7="","",ROUND(E7-C7,2)),0))) -> 0 | G7: Sim
A8: 45108 | B8: =IF(A8="","",IF(AND(ISNUMBER(parametros!$C$2),ISNUMBER(parametros!$D$2),A8>=parametros!$C$2,A8<=parametros!$D$2),"c0",IF(AND(ISNUMBER(parametros!$C$3),ISNUMBER(parametros!$D$3),A8>=parametros!$C$3,A8<=parametros!$D$3),"c1",IF(AND(ISNUMBER(parametros!$C$4),ISNUMBER(parametros!$D$4),A8>=parametros!$C$4,A8<=parametros!$D$4),"c2",IF(AND(ISNUMBER(parametros!$C$5),ISNUMBER(parametros!$D$5),A8>=parametros!$C$5,A8<=parametros!$D$5),"c3",IF(AND(ISNUMBER(parametros!$C$6),ISNUMBER(parametros!$D$6),A8>=parametros!$C$6,A8<=parametros!$D$6),"c4","Fora dos ciclos")))))) -> c0 | C8: 42500 | D8: =IF(B8="","",IF(B8="c0",1,IF(B8="c1",IF(parametros!$A$3<>"Sim","",IF(NOT(ISNUMBER(parametros!$E$3)),"",1+parametros!$E$3)),IF(B8="c2",IF(parametros!$A$4<>"Sim","",IF(NOT(ISNUMBER(parametros!$E$4)),"",IF(parametros!$A$3="Sim",1+parametros!$E$3,1)*(1+parametros!$E$4))),IF(B8="c3",IF(parametros!$A$5<>"Sim","",IF(NOT(ISNUMBER(parametros!$E$5)),"",IF(parametros!$A$3="Sim",1+parametros!$E$3,1)*IF(parametros!$A$4="Sim",1+parametros!$E$4,1)*(1+parametros!$E$5))),IF(B8="c4",IF(parametros!$A$6<>"Sim","",IF(NOT(ISNUMBER(parametros!$E$6)),"",IF(parametros!$A$3="Sim",1+parametros!$E$3,1)*IF(parametros!$A$4="Sim",1+parametros!$E$4,1)*IF(parametros!$A$5="Sim",1+parametros!$E$5,1)*(1+parametros!$E$6))),"")))))) -> 1 | E8: =IF(C8="","",IF(G8="","",IF(G8="Sim",IF(NOT(ISNUMBER(D8)),"",ROUND(C8*D8,2)),C8))) -> 42500 | F8: =IF(C8="","",IF(G8="","",IF(G8="Sim",IF(E8="","",ROUND(E8-C8,2)),0))) -> 0 | G8: Sim
A9: 45139 | B9: =IF(A9="","",IF(AND(ISNUMBER(parametros!$C$2),ISNUMBER(parametros!$D$2),A9>=parametros!$C$2,A9<=parametros!$D$2),"c0",IF(AND(ISNUMBER(parametros!$C$3),ISNUMBER(parametros!$D$3),A9>=parametros!$C$3,A9<=parametros!$D$3),"c1",IF(AND(ISNUMBER(parametros!$C$4),ISNUMBER(parametros!$D$4),A9>=parametros!$C$4,A9<=parametros!$D$4),"c2",IF(AND(ISNUMBER(parametros!$C$5),ISNUMBER(parametros!$D$5),A9>=parametros!$C$5,A9<=parametros!$D$5),"c3",IF(AND(ISNUMBER(parametros!$C$6),ISNUMBER(parametros!$D$6),A9>=parametros!$C$6,A9<=parametros!$D$6),"c4","Fora dos ciclos")))))) -> c0 | C9: 42500 | D9: =IF(B9="","",IF(B9="c0",1,IF(B9="c1",IF(parametros!$A$3<>"Sim","",IF(NOT(ISNUMBER(parametros!$E$3)),"",1+parametros!$E$3)),IF(B9="c2",IF(parametros!$A$4<>"Sim","",IF(NOT(ISNUMBER(parametros!$E$4)),"",IF(parametros!$A$3="Sim",1+parametros!$E$3,1)*(1+parametros!$E$4))),IF(B9="c3",IF(parametros!$A$5<>"Sim","",IF(NOT(ISNUMBER(parametros!$E$5)),"",IF(parametros!$A$3="Sim",1+parametros!$E$3,1)*IF(parametros!$A$4="Sim",1+parametros!$E$4,1)*(1+parametros!$E$5))),IF(B9="c4",IF(parametros!$A$6<>"Sim","",IF(NOT(ISNUMBER(parametros!$E$6)),"",IF(parametros!$A$3="Sim",1+parametros!$E$3,1)*IF(parametros!$A$4="Sim",1+parametros!$E$4,1)*IF(parametros!$A$5="Sim",1+parametros!$E$5,1)*(1+parametros!$E$6))),"")))))) -> 1 | E9: =IF(C9="","",IF(G9="","",IF(G9="Sim",IF(NOT(ISNUMBER(D9)),"",ROUND(C9*D9,2)),C9))) -> 42500 | F9: =IF(C9="","",IF(G9="","",IF(G9="Sim",IF(E9="","",ROUND(E9-C9,2)),0))) -> 0 | G9: Sim
A10: 45170 | B10: =IF(A10="","",IF(AND(ISNUMBER(parametros!$C$2),ISNUMBER(parametros!$D$2),A10>=parametros!$C$2,A10<=parametros!$D$2),"c0",IF(AND(ISNUMBER(parametros!$C$3),ISNUMBER(parametros!$D$3),A10>=parametros!$C$3,A10<=parametros!$D$3),"c1",IF(AND(ISNUMBER(parametros!$C$4),ISNUMBER(parametros!$D$4),A10>=parametros!$C$4,A10<=parametros!$D$4),"c2",IF(AND(ISNUMBER(parametros!$C$5),ISNUMBER(parametros!$D$5),A10>=parametros!$C$5,A10<=parametros!$D$5),"c3",IF(AND(ISNUMBER(parametros!$C$6),ISNUMBER(parametros!$D$6),A10>=parametros!$C$6,A10<=parametros!$D$6),"c4","Fora dos ciclos")))))) -> c0 | C10: 42500 | D10: =IF(B10="","",IF(B10="c0",1,IF(B10="c1",IF(parametros!$A$3<>"Sim","",IF(NOT(ISNUMBER(parametros!$E$3)),"",1+parametros!$E$3)),IF(B10="c2",IF(parametros!$A$4<>"Sim","",IF(NOT(ISNUMBER(parametros!$E$4)),"",IF(parametros!$A$3="Sim",1+parametros!$E$3,1)*(1+parametros!$E$4))),IF(B10="c3",IF(parametros!$A$5<>"Sim","",IF(NOT(ISNUMBER(parametros!$E$5)),"",IF(parametros!$A$3="Sim",1+parametros!$E$3,1)*IF(parametros!$A$4="Sim",1+parametros!$E$4,1)*(1+parametros!$E$5))),IF(B10="c4",IF(parametros!$A$6<>"Sim","",IF(NOT(ISNUMBER(parametros!$E$6)),"",IF(parametros!$A$3="Sim",1+parametros!$E$3,1)*IF(parametros!$A$4="Sim",1+parametros!$E$4,1)*IF(parametros!$A$5="Sim",1+parametros!$E$5,1)*(1+parametros!$E$6))),"")))))) -> 1 | E10: =IF(C10="","",IF(G10="","",IF(G10="Sim",IF(NOT(ISNUMBER(D10)),"",ROUND(C10*D10,2)),C10))) -> 42500 | F10: =IF(C10="","",IF(G10="","",IF(G10="Sim",IF(E10="","",ROUND(E10-C10,2)),0))) -> 0 | G10: Sim
A11: 45200 | B11: =IF(A11="","",IF(AND(ISNUMBER(parametros!$C$2),ISNUMBER(parametros!$D$2),A11>=parametros!$C$2,A11<=parametros!$D$2),"c0",IF(AND(ISNUMBER(parametros!$C$3),ISNUMBER(parametros!$D$3),A11>=parametros!$C$3,A11<=parametros!$D$3),"c1",IF(AND(ISNUMBER(parametros!$C$4),ISNUMBER(parametros!$D$4),A11>=parametros!$C$4,A11<=parametros!$D$4),"c2",IF(AND(ISNUMBER(parametros!$C$5),ISNUMBER(parametros!$D$5),A11>=parametros!$C$5,A11<=parametros!$D$5),"c3",IF(AND(ISNUMBER(parametros!$C$6),ISNUMBER(parametros!$D$6),A11>=parametros!$C$6,A11<=parametros!$D$6),"c4","Fora dos ciclos")))))) -> c0 | C11: 42500 | D11: =IF(B11="","",IF(B11="c0",1,IF(B11="c1",IF(parametros!$A$3<>"Sim","",IF(NOT(ISNUMBER(parametros!$E$3)),"",1+parametros!$E$3)),IF(B11="c2",IF(parametros!$A$4<>"Sim","",IF(NOT(ISNUMBER(parametros!$E$4)),"",IF(parametros!$A$3="Sim",1+parametros!$E$3,1)*(1+parametros!$E$4))),IF(B11="c3",IF(parametros!$A$5<>"Sim","",IF(NOT(ISNUMBER(parametros!$E$5)),"",IF(parametros!$A$3="Sim",1+parametros!$E$3,1)*IF(parametros!$A$4="Sim",1+parametros!$E$4,1)*(1+parametros!$E$5))),IF(B11="c4",IF(parametros!$A$6<>"Sim","",IF(NOT(ISNUMBER(parametros!$E$6)),"",IF(parametros!$A$3="Sim",1+parametros!$E$3,1)*IF(parametros!$A$4="Sim",1+parametros!$E$4,1)*IF(parametros!$A$5="Sim",1+parametros!$E$5,1)*(1+parametros!$E$6))),"")))))) -> 1 | E11: =IF(C11="","",IF(G11="","",IF(G11="Sim",IF(NOT(ISNUMBER(D11)),"",ROUND(C11*D11,2)),C11))) -> 42500 | F11: =IF(C11="","",IF(G11="","",IF(G11="Sim",IF(E11="","",ROUND(E11-C11,2)),0))) -> 0 | G11: Sim
A12: 45231 | B12: =IF(A12="","",IF(AND(ISNUMBER(parametros!$C$2),ISNUMBER(parametros!$D$2),A12>=parametros!$C$2,A12<=parametros!$D$2),"c0",IF(AND(ISNUMBER(parametros!$C$3),ISNUMBER(parametros!$D$3),A12>=parametros!$C$3,A12<=parametros!$D$3),"c1",IF(AND(ISNUMBER(parametros!$C$4),ISNUMBER(parametros!$D$4),A12>=parametros!$C$4,A12<=parametros!$D$4),"c2",IF(AND(ISNUMBER(parametros!$C$5),ISNUMBER(parametros!$D$5),A12>=parametros!$C$5,A12<=parametros!$D$5),"c3",IF(AND(ISNUMBER(parametros!$C$6),ISNUMBER(parametros!$D$6),A12>=parametros!$C$6,A12<=parametros!$D$6),"c4","Fora dos ciclos")))))) -> c0 | C12: 42500 | D12: =IF(B12="","",IF(B12="c0",1,IF(B12="c1",IF(parametros!$A$3<>"Sim","",IF(NOT(ISNUMBER(parametros!$E$3)),"",1+parametros!$E$3)),IF(B12="c2",IF(parametros!$A$4<>"Sim","",IF(NOT(ISNUMBER(parametros!$E$4)),"",IF(parametros!$A$3="Sim",1+parametros!$E$3,1)*(1+parametros!$E$4))),IF(B12="c3",IF(parametros!$A$5<>"Sim","",IF(NOT(ISNUMBER(parametros!$E$5)),"",IF(parametros!$A$3="Sim",1+parametros!$E$3,1)*IF(parametros!$A$4="Sim",1+parametros!$E$4,1)*(1+parametros!$E$5))),IF(B12="c4",IF(parametros!$A$6<>"Sim","",IF(NOT(ISNUMBER(parametros!$E$6)),"",IF(parametros!$A$3="Sim",1+parametros!$E$3,1)*IF(parametros!$A$4="Sim",1+parametros!$E$4,1)*IF(parametros!$A$5="Sim",1+parametros!$E$5,1)*(1+parametros!$E$6))),"")))))) -> 1 | E12: =IF(C12="","",IF(G12="","",IF(G12="Sim",IF(NOT(ISNUMBER(D12)),"",ROUND(C12*D12,2)),C12))) -> 42500 | F12: =IF(C12="","",IF(G12="","",IF(G12="Sim",IF(E12="","",ROUND(E12-C12,2)),0))) -> 0 | G12: Sim
A13: 45261 | B13: =IF(A13="","",IF(AND(ISNUMBER(parametros!$C$2),ISNUMBER(parametros!$D$2),A13>=parametros!$C$2,A13<=parametros!$D$2),"c0",IF(AND(ISNUMBER(parametros!$C$3),ISNUMBER(parametros!$D$3),A13>=parametros!$C$3,A13<=parametros!$D$3),"c1",IF(AND(ISNUMBER(parametros!$C$4),ISNUMBER(parametros!$D$4),A13>=parametros!$C$4,A13<=parametros!$D$4),"c2",IF(AND(ISNUMBER(parametros!$C$5),ISNUMBER(parametros!$D$5),A13>=parametros!$C$5,A13<=parametros!$D$5),"c3",IF(AND(ISNUMBER(parametros!$C$6),ISNUMBER(parametros!$D$6),A13>=parametros!$C$6,A13<=parametros!$D$6),"c4","Fora dos ciclos")))))) -> c0 | C13: 42500 | D13: =IF(B13="","",IF(B13="c0",1,IF(B13="c1",IF(parametros!$A$3<>"Sim","",IF(NOT(ISNUMBER(parametros!$E$3)),"",1+parametros!$E$3)),IF(B13="c2",IF(parametros!$A$4<>"Sim","",IF(NOT(ISNUMBER(parametros!$E$4)),"",IF(parametros!$A$3="Sim",1+parametros!$E$3,1)*(1+parametros!$E$4))),IF(B13="c3",IF(parametros!$A$5<>"Sim","",IF(NOT(ISNUMBER(parametros!$E$5)),"",IF(parametros!$A$3="Sim",1+parametros!$E$3,1)*IF(parametros!$A$4="Sim",1+parametros!$E$4,1)*(1+parametros!$E$5))),IF(B13="c4",IF(parametros!$A$6<>"Sim","",IF(NOT(ISNUMBER(parametros!$E$6)),"",IF(parametros!$A$3="Sim",1+parametros!$E$3,1)*IF(parametros!$A$4="Sim",1+parametros!$E$4,1)*IF(parametros!$A$5="Sim",1+parametros!$E$5,1)*(1+parametros!$E$6))),"")))))) -> 1 | E13: =IF(C13="","",IF(G13="","",IF(G13="Sim",IF(NOT(ISNUMBER(D13)),"",ROUND(C13*D13,2)),C13))) -> 42500 | F13: =IF(C13="","",IF(G13="","",IF(G13="Sim",IF(E13="","",ROUND(E13-C13,2)),0))) -> 0 | G13: Sim
... A25: 45627 | B25: =IF(A25="","",IF(AND(ISNUMBER(parametros!$C$2),ISNUMBER(parametros!$D$2),A25>=parametros!$C$2,A25<=parametros!$D$2),"c0",IF(AND(ISNUMBER(parametros!$C$3),ISNUMBER(parametros!$D$3),A25>=parametros!$C$3,A25<=parametros!$D$3),"c1",IF(AND(ISNUMBER(parametros!$C$4),ISNUMBER(parametros!$D$4),A25>=parametros!$C$4,A25<=parametros!$D$4),"c2",IF(AND(ISNUMBER(parametros!$C$5),ISNUMBER(parametros!$D$5),A25>=parametros!$C$5,A25<=parametros!$D$5),"c3",IF(AND(ISNUMBER(parametros!$C$6),ISNUMBER(parametros!$D$6),A25>=parametros!$C$6,A25<=parametros!$D$6),"c4","Fora dos ciclos")))))) -> c1 | C25: 42500 | D25: =IF(B25="","",IF(B25="c0",1,IF(B25="c1",IF(parametros!$A$3<>"Sim","",IF(NOT(ISNUMBER(parametros!$E$3)),"",1+parametros!$E$3)),IF(B25="c2",IF(parametros!$A$4<>"Sim","",IF(NOT(ISNUMBER(parametros!$E$4)),"",IF(parametros!$A$3="Sim",1+parametros!$E$3,1)*(1+parametros!$E$4))),IF(B25="c3",IF(parametros!$A$5<>"Sim","",IF(NOT(ISNUMBER(parametros!$E$5)),"",IF(parametros!$A$3="Sim",1+parametros!$E$3,1)*IF(parametros!$A$4="Sim",1+parametros!$E$4,1)*(1+parametros!$E$5))),IF(B25="c4",IF(parametros!$A$6<>"Sim","",IF(NOT(ISNUMBER(parametros!$E$6)),"",IF(parametros!$A$3="Sim",1+parametros!$E$3,1)*IF(parametros!$A$4="Sim",1+parametros!$E$4,1)*IF(parametros!$A$5="Sim",1+parametros!$E$5,1)*(1+parametros!$E$6))),"")))))) -> 1.0512 | E25: =IF(C25="","",IF(G25="","",IF(G25="Sim",IF(NOT(ISNUMBER(D25)),"",ROUND(C25*D25,2)),C25))) -> 44676 | F25: =IF(C25="","",IF(G25="","",IF(G25="Sim",IF(E25="","",ROUND(E25-C25,2)),0))) -> 2176 | G25: Sim
B26: =IF(A26="","",IF(AND(ISNUMBER(parametros!$C$2),ISNUMBER(parametros!$D$2),A26>=parametros!$C$2,A26<=parametros!$D$2),"c0",IF(AND(ISNUMBER(parametros!$C$3),ISNUMBER(parametros!$D$3),A26>=parametros!$C$3,A26<=parametros!$D$3),"c1",IF(AND(ISNUMBER(parametros!$C$4),ISNUMBER(parametros!$D$4),A26>=parametros!$C$4,A26<=parametros!$D$4),"c2",IF(AND(ISNUMBER(parametros!$C$5),ISNUMBER(parametros!$D$5),A26>=parametros!$C$5,A26<=parametros!$D$5),"c3",IF(AND(ISNUMBER(parametros!$C$6),ISNUMBER(parametros!$D$6),A26>=parametros!$C$6,A26<=parametros!$D$6),"c4","Fora dos ciclos")))))) | D26: =IF(B26="","",IF(B26="c0",1,IF(B26="c1",IF(parametros!$A$3<>"Sim","",IF(NOT(ISNUMBER(parametros!$E$3)),"",1+parametros!$E$3)),IF(B26="c2",IF(parametros!$A$4<>"Sim","",IF(NOT(ISNUMBER(parametros!$E$4)),"",IF(parametros!$A$3="Sim",1+parametros!$E$3,1)*(1+parametros!$E$4))),IF(B26="c3",IF(parametros!$A$5<>"Sim","",IF(NOT(ISNUMBER(parametros!$E$5)),"",IF(parametros!$A$3="Sim",1+parametros!$E$3,1)*IF(parametros!$A$4="Sim",1+parametros!$E$4,1)*(1+parametros!$E$5))),IF(B26="c4",IF(parametros!$A$6<>"Sim","",IF(NOT(ISNUMBER(parametros!$E$6)),"",IF(parametros!$A$3="Sim",1+parametros!$E$3,1)*IF(parametros!$A$4="Sim",1+parametros!$E$4,1)*IF(parametros!$A$5="Sim",1+parametros!$E$5,1)*(1+parametros!$E$6))),"")))))) | E26: =IF(C26="","",IF(G26="","",IF(G26="Sim",IF(NOT(ISNUMBER(D26)),"",ROUND(C26*D26,2)),C26))) | F26: =IF(C26="","",IF(G26="","",IF(G26="Sim",IF(E26="","",ROUND(E26-C26,2)),0)))
B27: =IF(A27="","",IF(AND(ISNUMBER(parametros!$C$2),ISNUMBER(parametros!$D$2),A27>=parametros!$C$2,A27<=parametros!$D$2),"c0",IF(AND(ISNUMBER(parametros!$C$3),ISNUMBER(parametros!$D$3),A27>=parametros!$C$3,A27<=parametros!$D$3),"c1",IF(AND(ISNUMBER(parametros!$C$4),ISNUMBER(parametros!$D$4),A27>=parametros!$C$4,A27<=parametros!$D$4),"c2",IF(AND(ISNUMBER(parametros!$C$5),ISNUMBER(parametros!$D$5),A27>=parametros!$C$5,A27<=parametros!$D$5),"c3",IF(AND(ISNUMBER(parametros!$C$6),ISNUMBER(parametros!$D$6),A27>=parametros!$C$6,A27<=parametros!$D$6),"c4","Fora dos ciclos")))))) | D27: =IF(B27="","",IF(B27="c0",1,IF(B27="c1",IF(parametros!$A$3<>"Sim","",IF(NOT(ISNUMBER(parametros!$E$3)),"",1+parametros!$E$3)),IF(B27="c2",IF(parametros!$A$4<>"Sim","",IF(NOT(ISNUMBER(parametros!$E$4)),"",IF(parametros!$A$3="Sim",1+parametros!$E$3,1)*(1+parametros!$E$4))),IF(B27="c3",IF(parametros!$A$5<>"Sim","",IF(NOT(ISNUMBER(parametros!$E$5)),"",IF(parametros!$A$3="Sim",1+parametros!$E$3,1)*IF(parametros!$A$4="Sim",1+parametros!$E$4,1)*(1+parametros!$E$5))),IF(B27="c4",IF(parametros!$A$6<>"Sim","",IF(NOT(ISNUMBER(parametros!$E$6)),"",IF(parametros!$A$3="Sim",1+parametros!$E$3,1)*IF(parametros!$A$4="Sim",1+parametros!$E$4,1)*IF(parametros!$A$5="Sim",1+parametros!$E$5,1)*(1+parametros!$E$6))),"")))))) | E27: =IF(C27="","",IF(G27="","",IF(G27="Sim",IF(NOT(ISNUMBER(D27)),"",ROUND(C27*D27,2)),C27))) | F27: =IF(C27="","",IF(G27="","",IF(G27="Sim",IF(E27="","",ROUND(E27-C27,2)),0)))
B28: =IF(A28="","",IF(AND(ISNUMBER(parametros!$C$2),ISNUMBER(parametros!$D$2),A28>=parametros!$C$2,A28<=parametros!$D$2),"c0",IF(AND(ISNUMBER(parametros!$C$3),ISNUMBER(parametros!$D$3),A28>=parametros!$C$3,A28<=parametros!$D$3),"c1",IF(AND(ISNUMBER(parametros!$C$4),ISNUMBER(parametros!$D$4),A28>=parametros!$C$4,A28<=parametros!$D$4),"c2",IF(AND(ISNUMBER(parametros!$C$5),ISNUMBER(parametros!$D$5),A28>=parametros!$C$5,A28<=parametros!$D$5),"c3",IF(AND(ISNUMBER(parametros!$C$6),ISNUMBER(parametros!$D$6),A28>=parametros!$C$6,A28<=parametros!$D$6),"c4","Fora dos ciclos")))))) | D28: =IF(B28="","",IF(B28="c0",1,IF(B28="c1",IF(parametros!$A$3<>"Sim","",IF(NOT(ISNUMBER(parametros!$E$3)),"",1+parametros!$E$3)),IF(B28="c2",IF(parametros!$A$4<>"Sim","",IF(NOT(ISNUMBER(parametros!$E$4)),"",IF(parametros!$A$3="Sim",1+parametros!$E$3,1)*(1+parametros!$E$4))),IF(B28="c3",IF(parametros!$A$5<>"Sim","",IF(NOT(ISNUMBER(parametros!$E$5)),"",IF(parametros!$A$3="Sim",1+parametros!$E$3,1)*IF(parametros!$A$4="Sim",1+parametros!$E$4,1)*(1+parametros!$E$5))),IF(B28="c4",IF(parametros!$A$6<>"Sim","",IF(NOT(ISNUMBER(parametros!$E$6)),"",IF(parametros!$A$3="Sim",1+parametros!$E$3,1)*IF(parametros!$A$4="Sim",1+parametros!$E$4,1)*IF(parametros!$A$5="Sim",1+parametros!$E$5,1)*(1+parametros!$E$6))),"")))))) | E28: =IF(C28="","",IF(G28="","",IF(G28="Sim",IF(NOT(ISNUMBER(D28)),"",ROUND(C28*D28,2)),C28))) | F28: =IF(C28="","",IF(G28="","",IF(G28="Sim",IF(E28="","",ROUND(E28-C28,2)),0)))
B29: =IF(A29="","",IF(AND(ISNUMBER(parametros!$C$2),ISNUMBER(parametros!$D$2),A29>=parametros!$C$2,A29<=parametros!$D$2),"c0",IF(AND(ISNUMBER(parametros!$C$3),ISNUMBER(parametros!$D$3),A29>=parametros!$C$3,A29<=parametros!$D$3),"c1",IF(AND(ISNUMBER(parametros!$C$4),ISNUMBER(parametros!$D$4),A29>=parametros!$C$4,A29<=parametros!$D$4),"c2",IF(AND(ISNUMBER(parametros!$C$5),ISNUMBER(parametros!$D$5),A29>=parametros!$C$5,A29<=parametros!$D$5),"c3",IF(AND(ISNUMBER(parametros!$C$6),ISNUMBER(parametros!$D$6),A29>=parametros!$C$6,A29<=parametros!$D$6),"c4","Fora dos ciclos")))))) | D29: =IF(B29="","",IF(B29="c0",1,IF(B29="c1",IF(parametros!$A$3<>"Sim","",IF(NOT(ISNUMBER(parametros!$E$3)),"",1+parametros!$E$3)),IF(B29="c2",IF(parametros!$A$4<>"Sim","",IF(NOT(ISNUMBER(parametros!$E$4)),"",IF(parametros!$A$3="Sim",1+parametros!$E$3,1)*(1+parametros!$E$4))),IF(B29="c3",IF(parametros!$A$5<>"Sim","",IF(NOT(ISNUMBER(parametros!$E$5)),"",IF(parametros!$A$3="Sim",1+parametros!$E$3,1)*IF(parametros!$A$4="Sim",1+parametros!$E$4,1)*(1+parametros!$E$5))),IF(B29="c4",IF(parametros!$A$6<>"Sim","",IF(NOT(ISNUMBER(parametros!$E$6)),"",IF(parametros!$A$3="Sim",1+parametros!$E$3,1)*IF(parametros!$A$4="Sim",1+parametros!$E$4,1)*IF(parametros!$A$5="Sim",1+parametros!$E$5,1)*(1+parametros!$E$6))),"")))))) | E29: =IF(C29="","",IF(G29="","",IF(G29="Sim",IF(NOT(ISNUMBER(D29)),"",ROUND(C29*D29,2)),C29))) | F29: =IF(C29="","",IF(G29="","",IF(G29="Sim",IF(E29="","",ROUND(E29-C29,2)),0)))
B30: =IF(A30="","",IF(AND(ISNUMBER(parametros!$C$2),ISNUMBER(parametros!$D$2),A30>=parametros!$C$2,A30<=parametros!$D$2),"c0",IF(AND(ISNUMBER(parametros!$C$3),ISNUMBER(parametros!$D$3),A30>=parametros!$C$3,A30<=parametros!$D$3),"c1",IF(AND(ISNUMBER(parametros!$C$4),ISNUMBER(parametros!$D$4),A30>=parametros!$C$4,A30<=parametros!$D$4),"c2",IF(AND(ISNUMBER(parametros!$C$5),ISNUMBER(parametros!$D$5),A30>=parametros!$C$5,A30<=parametros!$D$5),"c3",IF(AND(ISNUMBER(parametros!$C$6),ISNUMBER(parametros!$D$6),A30>=parametros!$C$6,A30<=parametros!$D$6),"c4","Fora dos ciclos")))))) | D30: =IF(B30="","",IF(B30="c0",1,IF(B30="c1",IF(parametros!$A$3<>"Sim","",IF(NOT(ISNUMBER(parametros!$E$3)),"",1+parametros!$E$3)),IF(B30="c2",IF(parametros!$A$4<>"Sim","",IF(NOT(ISNUMBER(parametros!$E$4)),"",IF(parametros!$A$3="Sim",1+parametros!$E$3,1)*(1+parametros!$E$4))),IF(B30="c3",IF(parametros!$A$5<>"Sim","",IF(NOT(ISNUMBER(parametros!$E$5)),"",IF(parametros!$A$3="Sim",1+parametros!$E$3,1)*IF(parametros!$A$4="Sim",1+parametros!$E$4,1)*(1+parametros!$E$5))),IF(B30="c4",IF(parametros!$A$6<>"Sim","",IF(NOT(ISNUMBER(parametros!$E$6)),"",IF(parametros!$A$3="Sim",1+parametros!$E$3,1)*IF(parametros!$A$4="Sim",1+parametros!$E$4,1)*IF(parametros!$A$5="Sim",1+parametros!$E$5,1)*(1+parametros!$E$6))),"")))))) | E30: =IF(C30="","",IF(G30="","",IF(G30="Sim",IF(NOT(ISNUMBER(D30)),"",ROUND(C30*D30,2)),C30))) | F30: =IF(C30="","",IF(G30="","",IF(G30="Sim",IF(E30="","",ROUND(E30-C30,2)),0)))
B31: =IF(A31="","",IF(AND(ISNUMBER(parametros!$C$2),ISNUMBER(parametros!$D$2),A31>=parametros!$C$2,A31<=parametros!$D$2),"c0",IF(AND(ISNUMBER(parametros!$C$3),ISNUMBER(parametros!$D$3),A31>=parametros!$C$3,A31<=parametros!$D$3),"c1",IF(AND(ISNUMBER(parametros!$C$4),ISNUMBER(parametros!$D$4),A31>=parametros!$C$4,A31<=parametros!$D$4),"c2",IF(AND(ISNUMBER(parametros!$C$5),ISNUMBER(parametros!$D$5),A31>=parametros!$C$5,A31<=parametros!$D$5),"c3",IF(AND(ISNUMBER(parametros!$C$6),ISNUMBER(parametros!$D$6),A31>=parametros!$C$6,A31<=parametros!$D$6),"c4","Fora dos ciclos")))))) | D31: =IF(B31="","",IF(B31="c0",1,IF(B31="c1",IF(parametros!$A$3<>"Sim","",IF(NOT(ISNUMBER(parametros!$E$3)),"",1+parametros!$E$3)),IF(B31="c2",IF(parametros!$A$4<>"Sim","",IF(NOT(ISNUMBER(parametros!$E$4)),"",IF(parametros!$A$3="Sim",1+parametros!$E$3,1)*(1+parametros!$E$4))),IF(B31="c3",IF(parametros!$A$5<>"Sim","",IF(NOT(ISNUMBER(parametros!$E$5)),"",IF(parametros!$A$3="Sim",1+parametros!$E$3,1)*IF(parametros!$A$4="Sim",1+parametros!$E$4,1)*(1+parametros!$E$5))),IF(B31="c4",IF(parametros!$A$6<>"Sim","",IF(NOT(ISNUMBER(parametros!$E$6)),"",IF(parametros!$A$3="Sim",1+parametros!$E$3,1)*IF(parametros!$A$4="Sim",1+parametros!$E$4,1)*IF(parametros!$A$5="Sim",1+parametros!$E$5,1)*(1+parametros!$E$6))),"")))))) | E31: =IF(C31="","",IF(G31="","",IF(G31="Sim",IF(NOT(ISNUMBER(D31)),"",ROUND(C31*D31,2)),C31))) | F31: =IF(C31="","",IF(G31="","",IF(G31="Sim",IF(E31="","",ROUND(E31-C31,2)),0)))
B32: =IF(A32="","",IF(AND(ISNUMBER(parametros!$C$2),ISNUMBER(parametros!$D$2),A32>=parametros!$C$2,A32<=parametros!$D$2),"c0",IF(AND(ISNUMBER(parametros!$C$3),ISNUMBER(parametros!$D$3),A32>=parametros!$C$3,A32<=parametros!$D$3),"c1",IF(AND(ISNUMBER(parametros!$C$4),ISNUMBER(parametros!$D$4),A32>=parametros!$C$4,A32<=parametros!$D$4),"c2",IF(AND(ISNUMBER(parametros!$C$5),ISNUMBER(parametros!$D$5),A32>=parametros!$C$5,A32<=parametros!$D$5),"c3",IF(AND(ISNUMBER(parametros!$C$6),ISNUMBER(parametros!$D$6),A32>=parametros!$C$6,A32<=parametros!$D$6),"c4","Fora dos ciclos")))))) | D32: =IF(B32="","",IF(B32="c0",1,IF(B32="c1",IF(parametros!$A$3<>"Sim","",IF(NOT(ISNUMBER(parametros!$E$3)),"",1+parametros!$E$3)),IF(B32="c2",IF(parametros!$A$4<>"Sim","",IF(NOT(ISNUMBER(parametros!$E$4)),"",IF(parametros!$A$3="Sim",1+parametros!$E$3,1)*(1+parametros!$E$4))),IF(B32="c3",IF(parametros!$A$5<>"Sim","",IF(NOT(ISNUMBER(parametros!$E$5)),"",IF(parametros!$A$3="Sim",1+parametros!$E$3,1)*IF(parametros!$A$4="Sim",1+parametros!$E$4,1)*(1+parametros!$E$5))),IF(B32="c4",IF(parametros!$A$6<>"Sim","",IF(NOT(ISNUMBER(parametros!$E$6)),"",IF(parametros!$A$3="Sim",1+parametros!$E$3,1)*IF(parametros!$A$4="Sim",1+parametros!$E$4,1)*IF(parametros!$A$5="Sim",1+parametros!$E$5,1)*(1+parametros!$E$6))),"")))))) | E32: =IF(C32="","",IF(G32="","",IF(G32="Sim",IF(NOT(ISNUMBER(D32)),"",ROUND(C32*D32,2)),C32))) | F32: =IF(C32="","",IF(G32="","",IF(G32="Sim",IF(E32="","",ROUND(E32-C32,2)),0)))
B33: =IF(A33="","",IF(AND(ISNUMBER(parametros!$C$2),ISNUMBER(parametros!$D$2),A33>=parametros!$C$2,A33<=parametros!$D$2),"c0",IF(AND(ISNUMBER(parametros!$C$3),ISNUMBER(parametros!$D$3),A33>=parametros!$C$3,A33<=parametros!$D$3),"c1",IF(AND(ISNUMBER(parametros!$C$4),ISNUMBER(parametros!$D$4),A33>=parametros!$C$4,A33<=parametros!$D$4),"c2",IF(AND(ISNUMBER(parametros!$C$5),ISNUMBER(parametros!$D$5),A33>=parametros!$C$5,A33<=parametros!$D$5),"c3",IF(AND(ISNUMBER(parametros!$C$6),ISNUMBER(parametros!$D$6),A33>=parametros!$C$6,A33<=parametros!$D$6),"c4","Fora dos ciclos")))))) | D33: =IF(B33="","",IF(B33="c0",1,IF(B33="c1",IF(parametros!$A$3<>"Sim","",IF(NOT(ISNUMBER(parametros!$E$3)),"",1+parametros!$E$3)),IF(B33="c2",IF(parametros!$A$4<>"Sim","",IF(NOT(ISNUMBER(parametros!$E$4)),"",IF(parametros!$A$3="Sim",1+parametros!$E$3,1)*(1+parametros!$E$4))),IF(B33="c3",IF(parametros!$A$5<>"Sim","",IF(NOT(ISNUMBER(parametros!$E$5)),"",IF(parametros!$A$3="Sim",1+parametros!$E$3,1)*IF(parametros!$A$4="Sim",1+parametros!$E$4,1)*(1+parametros!$E$5))),IF(B33="c4",IF(parametros!$A$6<>"Sim","",IF(NOT(ISNUMBER(parametros!$E$6)),"",IF(parametros!$A$3="Sim",1+parametros!$E$3,1)*IF(parametros!$A$4="Sim",1+parametros!$E$4,1)*IF(parametros!$A$5="Sim",1+parametros!$E$5,1)*(1+parametros!$E$6))),"")))))) | E33: =IF(C33="","",IF(G33="","",IF(G33="Sim",IF(NOT(ISNUMBER(D33)),"",ROUND(C33*D33,2)),C33))) | F33: =IF(C33="","",IF(G33="","",IF(G33="Sim",IF(E33="","",ROUND(E33-C33,2)),0)))
B34: =IF(A34="","",IF(AND(ISNUMBER(parametros!$C$2),ISNUMBER(parametros!$D$2),A34>=parametros!$C$2,A34<=parametros!$D$2),"c0",IF(AND(ISNUMBER(parametros!$C$3),ISNUMBER(parametros!$D$3),A34>=parametros!$C$3,A34<=parametros!$D$3),"c1",IF(AND(ISNUMBER(parametros!$C$4),ISNUMBER(parametros!$D$4),A34>=parametros!$C$4,A34<=parametros!$D$4),"c2",IF(AND(ISNUMBER(parametros!$C$5),ISNUMBER(parametros!$D$5),A34>=parametros!$C$5,A34<=parametros!$D$5),"c3",IF(AND(ISNUMBER(parametros!$C$6),ISNUMBER(parametros!$D$6),A34>=parametros!$C$6,A34<=parametros!$D$6),"c4","Fora dos ciclos")))))) | D34: =IF(B34="","",IF(B34="c0",1,IF(B34="c1",IF(parametros!$A$3<>"Sim","",IF(NOT(ISNUMBER(parametros!$E$3)),"",1+parametros!$E$3)),IF(B34="c2",IF(parametros!$A$4<>"Sim","",IF(NOT(ISNUMBER(parametros!$E$4)),"",IF(parametros!$A$3="Sim",1+parametros!$E$3,1)*(1+parametros!$E$4))),IF(B34="c3",IF(parametros!$A$5<>"Sim","",IF(NOT(ISNUMBER(parametros!$E$5)),"",IF(parametros!$A$3="Sim",1+parametros!$E$3,1)*IF(parametros!$A$4="Sim",1+parametros!$E$4,1)*(1+parametros!$E$5))),IF(B34="c4",IF(parametros!$A$6<>"Sim","",IF(NOT(ISNUMBER(parametros!$E$6)),"",IF(parametros!$A$3="Sim",1+parametros!$E$3,1)*IF(parametros!$A$4="Sim",1+parametros!$E$4,1)*IF(parametros!$A$5="Sim",1+parametros!$E$5,1)*(1+parametros!$E$6))),"")))))) | E34: =IF(C34="","",IF(G34="","",IF(G34="Sim",IF(NOT(ISNUMBER(D34)),"",ROUND(C34*D34,2)),C34))) | F34: =IF(C34="","",IF(G34="","",IF(G34="Sim",IF(E34="","",ROUND(E34-C34,2)),0)))
B35: =IF(A35="","",IF(AND(ISNUMBER(parametros!$C$2),ISNUMBER(parametros!$D$2),A35>=parametros!$C$2,A35<=parametros!$D$2),"c0",IF(AND(ISNUMBER(parametros!$C$3),ISNUMBER(parametros!$D$3),A35>=parametros!$C$3,A35<=parametros!$D$3),"c1",IF(AND(ISNUMBER(parametros!$C$4),ISNUMBER(parametros!$D$4),A35>=parametros!$C$4,A35<=parametros!$D$4),"c2",IF(AND(ISNUMBER(parametros!$C$5),ISNUMBER(parametros!$D$5),A35>=parametros!$C$5,A35<=parametros!$D$5),"c3",IF(AND(ISNUMBER(parametros!$C$6),ISNUMBER(parametros!$D$6),A35>=parametros!$C$6,A35<=parametros!$D$6),"c4","Fora dos ciclos")))))) | D35: =IF(B35="","",IF(B35="c0",1,IF(B35="c1",IF(parametros!$A$3<>"Sim","",IF(NOT(ISNUMBER(parametros!$E$3)),"",1+parametros!$E$3)),IF(B35="c2",IF(parametros!$A$4<>"Sim","",IF(NOT(ISNUMBER(parametros!$E$4)),"",IF(parametros!$A$3="Sim",1+parametros!$E$3,1)*(1+parametros!$E$4))),IF(B35="c3",IF(parametros!$A$5<>"Sim","",IF(NOT(ISNUMBER(parametros!$E$5)),"",IF(parametros!$A$3="Sim",1+parametros!$E$3,1)*IF(parametros!$A$4="Sim",1+parametros!$E$4,1)*(1+parametros!$E$5))),IF(B35="c4",IF(parametros!$A$6<>"Sim","",IF(NOT(ISNUMBER(parametros!$E$6)),"",IF(parametros!$A$3="Sim",1+parametros!$E$3,1)*IF(parametros!$A$4="Sim",1+parametros!$E$4,1)*IF(parametros!$A$5="Sim",1+parametros!$E$5,1)*(1+parametros!$E$6))),"")))))) | E35: =IF(C35="","",IF(G35="","",IF(G35="Sim",IF(NOT(ISNUMBER(D35)),"",ROUND(C35*D35,2)),C35))) | F35: =IF(C35="","",IF(G35="","",IF(G35="Sim",IF(E35="","",ROUND(E35-C35,2)),0)))
B36: =IF(A36="","",IF(AND(ISNUMBER(parametros!$C$2),ISNUMBER(parametros!$D$2),A36>=parametros!$C$2,A36<=parametros!$D$2),"c0",IF(AND(ISNUMBER(parametros!$C$3),ISNUMBER(parametros!$D$3),A36>=parametros!$C$3,A36<=parametros!$D$3),"c1",IF(AND(ISNUMBER(parametros!$C$4),ISNUMBER(parametros!$D$4),A36>=parametros!$C$4,A36<=parametros!$D$4),"c2",IF(AND(ISNUMBER(parametros!$C$5),ISNUMBER(parametros!$D$5),A36>=parametros!$C$5,A36<=parametros!$D$5),"c3",IF(AND(ISNUMBER(parametros!$C$6),ISNUMBER(parametros!$D$6),A36>=parametros!$C$6,A36<=parametros!$D$6),"c4","Fora dos ciclos")))))) | D36: =IF(B36="","",IF(B36="c0",1,IF(B36="c1",IF(parametros!$A$3<>"Sim","",IF(NOT(ISNUMBER(parametros!$E$3)),"",1+parametros!$E$3)),IF(B36="c2",IF(parametros!$A$4<>"Sim","",IF(NOT(ISNUMBER(parametros!$E$4)),"",IF(parametros!$A$3="Sim",1+parametros!$E$3,1)*(1+parametros!$E$4))),IF(B36="c3",IF(parametros!$A$5<>"Sim","",IF(NOT(ISNUMBER(parametros!$E$5)),"",IF(parametros!$A$3="Sim",1+parametros!$E$3,1)*IF(parametros!$A$4="Sim",1+parametros!$E$4,1)*(1+parametros!$E$5))),IF(B36="c4",IF(parametros!$A$6<>"Sim","",IF(NOT(ISNUMBER(parametros!$E$6)),"",IF(parametros!$A$3="Sim",1+parametros!$E$3,1)*IF(parametros!$A$4="Sim",1+parametros!$E$4,1)*IF(parametros!$A$5="Sim",1+parametros!$E$5,1)*(1+parametros!$E$6))),"")))))) | E36: =IF(C36="","",IF(G36="","",IF(G36="Sim",IF(NOT(ISNUMBER(D36)),"",ROUND(C36*D36,2)),C36))) | F36: =IF(C36="","",IF(G36="","",IF(G36="Sim",IF(E36="","",ROUND(E36-C36,2)),0)))
B37: =IF(A37="","",IF(AND(ISNUMBER(parametros!$C$2),ISNUMBER(parametros!$D$2),A37>=parametros!$C$2,A37<=parametros!$D$2),"c0",IF(AND(ISNUMBER(parametros!$C$3),ISNUMBER(parametros!$D$3),A37>=parametros!$C$3,A37<=parametros!$D$3),"c1",IF(AND(ISNUMBER(parametros!$C$4),ISNUMBER(parametros!$D$4),A37>=parametros!$C$4,A37<=parametros!$D$4),"c2",IF(AND(ISNUMBER(parametros!$C$5),ISNUMBER(parametros!$D$5),A37>=parametros!$C$5,A37<=parametros!$D$5),"c3",IF(AND(ISNUMBER(parametros!$C$6),ISNUMBER(parametros!$D$6),A37>=parametros!$C$6,A37<=parametros!$D$6),"c4","Fora dos ciclos")))))) | D37: =IF(B37="","",IF(B37="c0",1,IF(B37="c1",IF(parametros!$A$3<>"Sim","",IF(NOT(ISNUMBER(parametros!$E$3)),"",1+parametros!$E$3)),IF(B37="c2",IF(parametros!$A$4<>"Sim","",IF(NOT(ISNUMBER(parametros!$E$4)),"",IF(parametros!$A$3="Sim",1+parametros!$E$3,1)*(1+parametros!$E$4))),IF(B37="c3",IF(parametros!$A$5<>"Sim","",IF(NOT(ISNUMBER(parametros!$E$5)),"",IF(parametros!$A$3="Sim",1+parametros!$E$3,1)*IF(parametros!$A$4="Sim",1+parametros!$E$4,1)*(1+parametros!$E$5))),IF(B37="c4",IF(parametros!$A$6<>"Sim","",IF(NOT(ISNUMBER(parametros!$E$6)),"",IF(parametros!$A$3="Sim",1+parametros!$E$3,1)*IF(parametros!$A$4="Sim",1+parametros!$E$4,1)*IF(parametros!$A$5="Sim",1+parametros!$E$5,1)*(1+parametros!$E$6))),"")))))) | E37: =IF(C37="","",IF(G37="","",IF(G37="Sim",IF(NOT(ISNUMBER(D37)),"",ROUND(C37*D37,2)),C37))) | F37: =IF(C37="","",IF(G37="","",IF(G37="Sim",IF(E37="","",ROUND(E37-C37,2)),0)))
... B73: =IF(A73="","",IF(AND(ISNUMBER(parametros!$C$2),ISNUMBER(parametros!$D$2),A73>=parametros!$C$2,A73<=parametros!$D$2),"c0",IF(AND(ISNUMBER(parametros!$C$3),ISNUMBER(parametros!$D$3),A73>=parametros!$C$3,A73<=parametros!$D$3),"c1",IF(AND(ISNUMBER(parametros!$C$4),ISNUMBER(parametros!$D$4),A73>=parametros!$C$4,A73<=parametros!$D$4),"c2",IF(AND(ISNUMBER(parametros!$C$5),ISNUMBER(parametros!$D$5),A73>=parametros!$C$5,A73<=parametros!$D$5),"c3",IF(AND(ISNUMBER(parametros!$C$6),ISNUMBER(parametros!$D$6),A73>=parametros!$C$6,A73<=parametros!$D$6),"c4","Fora dos ciclos")))))) | D73: =IF(B73="","",IF(B73="c0",1,IF(B73="c1",IF(parametros!$A$3<>"Sim","",IF(NOT(ISNUMBER(parametros!$E$3)),"",1+parametros!$E$3)),IF(B73="c2",IF(parametros!$A$4<>"Sim","",IF(NOT(ISNUMBER(parametros!$E$4)),"",IF(parametros!$A$3="Sim",1+parametros!$E$3,1)*(1+parametros!$E$4))),IF(B73="c3",IF(parametros!$A$5<>"Sim","",IF(NOT(ISNUMBER(parametros!$E$5)),"",IF(parametros!$A$3="Sim",1+parametros!$E$3,1)*IF(parametros!$A$4="Sim",1+parametros!$E$4,1)*(1+parametros!$E$5))),IF(B73="c4",IF(parametros!$A$6<>"Sim","",IF(NOT(ISNUMBER(parametros!$E$6)),"",IF(parametros!$A$3="Sim",1+parametros!$E$3,1)*IF(parametros!$A$4="Sim",1+parametros!$E$4,1)*IF(parametros!$A$5="Sim",1+parametros!$E$5,1)*(1+parametros!$E$6))),"")))))) | E73: =IF(C73="","",IF(G73="","",IF(G73="Sim",IF(NOT(ISNUMBER(D73)),"",ROUND(C73*D73,2)),C73))) | F73: =IF(C73="","",IF(G73="","",IF(G73="Sim",IF(E73="","",ROUND(E73-C73,2)),0)))
B74: TOTAL | C74: =SUM(C2:C73) -> 1020000 | E74: =SUM(E2:E73) -> 1046112 | F74: =SUM(F2:F73) -> 26112

Sheet itens_Remanesc
