Workbook
Name AJUSTE_MANUAL_VTA: RESULTADOS!B24
Name JUSTIFICATIVA_RETRO: RESULTADOS!D5
Name METODO_RETROATIVO: RESULTADOS!B4
Name QTD_REM_OFICIAL: RESULTADOS!B35
Name REM_ATUALIZADO_OFICIAL: RESULTADOS!D35
Name REM_BASE_OFICIAL: RESULTADOS!C35
Name RETRO_FIN: RESULTADOS!B15
Name RETRO_ITENS: RESULTADOS!D15
Name RETRO_OFICIAL: RESULTADOS!B16
Name RETRO_PC: RESULTADOS!C15
Name TOLERANCIA_DIVERGENCIA: RESULTADOS!D4
Name VALOR_MANUAL_RETRO: RESULTADOS!B5
Name VTA_CALCULADO: RESULTADOS!B23
Name VTA_FINAL: RESULTADOS!B26
Name VTA_MANUAL_OFICIAL: RESULTADOS!B25

Sheet CONTROLE
A1: MODO DE LEITURA | B1: Principal | C1: Principal = pago + remanescente | D = consumo por ciclo
A2: Ciclo vigente (em execução) | B2: C1
A3: Data de corte (única p/ contrato) | B3: 45657
A4: C0 e ciclos fora da analise | B4: Preencher FINANCEIRO: coluna B com o nome do ciclo (ex: c0, c1), coluna C com o valor efetivamente pago. Se vazio, o sistema usa calculo por itens/estoque.
A6: RESUMO DO REAJUSTE | B6: VALOR
A7: Índice utilizado | B7: IST (Anatel)
A8: Data-base original | B8: 44927
A9: Quantidade de ciclos desta análise | B9: =COUNTIF(parametros!A2:A6,"Sim") -> 1
A10: Variação acumulada final | B10: =IFERROR(IF(ISNUMBER(parametros!F6),parametros!F6-1,IF(ISNUMBER(parametros!F5),parametros!F5-1,IF(ISNUMBER(parametros!F4),parametros!F4-1,IF(ISNUMBER(parametros!F3),parametros!F3-1,IF(ISNUMBER(parametros!F2),parametros!F2-1,""))))),"") -> 0.12203076
A11: Fator acumulado total | B11: =IFERROR(IF(ISNUMBER(parametros!F6),parametros!F6,IF(ISNUMBER(parametros!F5),parametros!F5,IF(ISNUMBER(parametros!F4),parametros!F4,IF(ISNUMBER(parametros!F3),parametros!F3,IF(ISNUMBER(parametros!F2),parametros!F2,""))))),"") -> 1.1220308
A12: Último ciclo considerado nesta apuração | B12: =IFERROR(IF(parametros!A6="Sim",parametros!B6,IF(parametros!A5="Sim",parametros!B5,IF(parametros!A4="Sim",parametros!B4,IF(parametros!A3="Sim",parametros!B3,IF(parametros!A2="Sim",parametros!B2,"Nenhum"))))),"Nenhum") -> C1
A13: Início do último ciclo considerado | B13: =IFERROR(IF(parametros!A6="Sim",parametros!C6,IF(parametros!A5="Sim",parametros!C5,IF(parametros!A4="Sim",parametros!C4,IF(parametros!A3="Sim",parametros!C3,IF(parametros!A2="Sim",parametros!C2,""))))),"") -> 45292
A14: Data de geracao do arquivo | B14: =NOW() -> 46295.82

Sheet parametros
A1: COMPUTAR_NESTA_APURACAO | B1: CICLO | C1: DATA_INICIO | D1: DATA_FIM | E1: PERCENTUAL_DO_CICLO | F1: FATOR_ACUMULADO | G1: SITUACAO
A2: Nao | B2: C0 | C2: 44927 | D2: 45291 | E2: 0 | F2: =1 -> 1 | G2: Base
A3: Sim | B3: C1 | C3: 45292 | D3: 45657 | E3: 0.0512 | F3: =IF(E3="","",IF(NOT(ISNUMBER(E3)),"",IF(NOT(ISNUMBER(F2)),"",F2*(1+E3)))) -> 1.0512 | G3: TEMPESTIVO
A4: Nao | B4: C2 | C4: 45658 | D4: 46022 | E4: 0.0374 | F4: =IF(E4="","",IF(NOT(ISNUMBER(E4)),"",IF(NOT(ISNUMBER(F3)),"",F3*(1+E4)))) -> 1.0905149 | G4: TEMPESTIVO
A5: Nao | B5: C3 | C5: 46023 | D5: 46387 | E5: 0.0289 | F5: =IF(E5="","",IF(NOT(ISNUMBER(E5)),"",IF(NOT(ISNUMBER(F4)),"",F4*(1+E5)))) -> 1.1220308 | G5: TEMPESTIVO
A6: Nao | B6: C4 | C6: 46388 | D6: 46752 | F6: =IF(E6="","",IF(NOT(ISNUMBER(E6)),"",IF(NOT(ISNUMBER(F5)),"",F5*(1+E6))))
A9: MEMORIA DO FATOR APLICAVEL A APURACAO
A10: CICLO | B10: COMPUTA? | C10: PERCENTUAL | D10: FATOR | E10: FATOR_ACUMULADO_APURACAO | F10: STATUS
A11: C0 | B11: =A2 -> Nao | C11: =IF(B11="Sim",E2,"") | D11: =1 -> 1 | E11: =1 -> 1 | F11: Base
A12: C1 | B12: =A3 -> Sim | C12: =IF(B12="Sim",E3,"") -> 0.0512 | D12: =IF(C12="","",1+C12) -> 1.0512 | E12: =IF(B12="Sim",E11*D12,E11) -> 1.0512 | F12: =IF(B12="Sim","Aplicado","Fora da apuracao") -> Aplicado
A13: C2 | B13: =A4 -> Nao | C13: =IF(B13="Sim",E4,"") | D13: =IF(C13="","",1+C13) | E13: =IF(B13="Sim",E12*D13,E12) -> 1.0512 | F13: =IF(B13="Sim","Aplicado","Fora da apuracao") -> Fora da apuracao
A14: C3 | B14: =A5 -> Nao | C14: =IF(B14="Sim",E5,"") | D14: =IF(C14="","",1+C14) | E14: =IF(B14="Sim",E13*D14,E13) -> 1.0512 | F14: =IF(B14="Sim","Aplicado","Fora da apuracao") -> Fora da apuracao
A15: C4 | B15: =A6 -> Nao | C15: =IF(B15="Sim",E6,"") | D15: =IF(C15="","",1+C15) | E15: =IF(B15="Sim",E14*D15,E14) -> 1.0512 | F15: =IF(B15="Sim","Aplicado","Fora da apuracao") -> Fora da apuracao
A16: TOTAL APURACAO | D16: =E15 -> 1.0512 | E16: =E15 -> 1.0512 | F16: =E16-1 -> 0.0512

Sheet financeiro
A1: COMPETENCIA | B1: CICLO | C1: VALOR_PAGO | D1: FATOR_APLICAVEL | E1: VALOR_ATUALIZADO | F1: DELTA | G1: EFEITO_FINANCEIRO
A2: 44927 | B2: =IF(A2="","",IF(OR(A2<MIN(parametros!$C$2:$C$6),A2>MAX(parametros!$D$2:$D$6)),"Fora dos ciclos",LOWER(LOOKUP(A2,parametros!$C$2:$C$6,parametros!$B$2:$B$6)))) -> c0 | C2: 42500 | D2: =IF(B2="","",IF(B2="c0",1,IF(B2="c1",IF(parametros!$A$3<>"Sim","",IF(NOT(ISNUMBER(parametros!$E$3)),"",1+parametros!$E$3)),IF(B2="c2",IF(parametros!$A$4<>"Sim","",IF(NOT(ISNUMBER(parametros!$E$4)),"",IF(parametros!$A$3="Sim",1+parametros!$E$3,1)*(1+parametros!$E$4))),IF(B2="c3",IF(parametros!$A$5<>"Sim","",IF(NOT(ISNUMBER(parametros!$E$5)),"",IF(parametros!$A$3="Sim",1+parametros!$E$3,1)*IF(parametros!$A$4="Sim",1+parametros!$E$4,1)*(1+parametros!$E$5))),IF(B2="c4",IF(parametros!$A$6<>"Sim","",IF(NOT(ISNUMBER(parametros!$E$6)),"",IF(parametros!$A$3="Sim",1+parametros!$E$3,1)*IF(parametros!$A$4="Sim",1+parametros!$E$4,1)*IF(parametros!$A$5="Sim",1+parametros!$E$5,1)*(1+parametros!$E$6))),"")))))) -> 1 | E2: =IF(OR(C2="",NOT(ISNUMBER(D2))),"",ROUND(C2*D2,2)) -> 42500 | F2: =IF(OR(C2="",E2=""),"",IF(G2<>"Sim",0,ROUND(E2-C2,2))) -> 0 | G2: Sim
A3: 44958 | B3: =IF(A3="","",IF(OR(A3<MIN(parametros!$C$2:$C$6),A3>MAX(parametros!$D$2:$D$6)),"Fora dos ciclos",LOWER(LOOKUP(A3,parametros!$C$2:$C$6,parametros!$B$2:$B$6)))) -> c0 | C3: 42500 | D3: =IF(B3="","",IF(B3="c0",1,IF(B3="c1",IF(parametros!$A$3<>"Sim","",IF(NOT(ISNUMBER(parametros!$E$3)),"",1+parametros!$E$3)),IF(B3="c2",IF(parametros!$A$4<>"Sim","",IF(NOT(ISNUMBER(parametros!$E$4)),"",IF(parametros!$A$3="Sim",1+parametros!$E$3,1)*(1+parametros!$E$4))),IF(B3="c3",IF(parametros!$A$5<>"Sim","",IF(NOT(ISNUMBER(parametros!$E$5)),"",IF(parametros!$A$3="Sim",1+parametros!$E$3,1)*IF(parametros!$A$4="Sim",1+parametros!$E$4,1)*(1+parametros!$E$5))),IF(B3="c4",IF(parametros!$A$6<>"Sim","",IF(NOT(ISNUMBER(parametros!$E$6)),"",IF(parametros!$A$3="Sim",1+parametros!$E$3,1)*IF(parametros!$A$4="Sim",1+parametros!$E$4,1)*IF(parametros!$A$5="Sim",1+parametros!$E$5,1)*(1+parametros!$E$6))),"")))))) -> 1 | E3: =IF(OR(C3="",NOT(ISNUMBER(D3))),"",ROUND(C3*D3,2)) -> 42500 | F3: =IF(OR(C3="",E3=""),"",IF(G3<>"Sim",0,ROUND(E3-C3,2))) -> 0 | G3: Sim
A4: 44986 | B4: =IF(A4="","",IF(OR(A4<MIN(parametros!$C$2:$C$6),A4>MAX(parametros!$D$2:$D$6)),"Fora dos ciclos",LOWER(LOOKUP(A4,parametros!$C$2:$C$6,parametros!$B$2:$B$6)))) -> c0 | C4: 42500 | D4: =IF(B4="","",IF(B4="c0",1,IF(B4="c1",IF(parametros!$A$3<>"Sim","",IF(NOT(ISNUMBER(parametros!$E$3)),"",1+parametros!$E$3)),IF(B4="c2",IF(parametros!$A$4<>"Sim","",IF(NOT(ISNUMBER(parametros!$E$4)),"",IF(parametros!$A$3="Sim",1+parametros!$E$3,1)*(1+parametros!$E$4))),IF(B4="c3",IF(parametros!$A$5<>"Sim","",IF(NOT(ISNUMBER(parametros!$E$5)),"",IF(parametros!$A$3="Sim",1+parametros!$E$3,1)*IF(parametros!$A$4="Sim",1+parametros!$E$4,1)*(1+parametros!$E$5))),IF(B4="c4",IF(parametros!$A$6<>"Sim","",IF(NOT(ISNUMBER(parametros!$E$6)),"",IF(parametros!$A$3="Sim",1+parametros!$E$3,1)*IF(parametros!$A$4="Sim",1+parametros!$E$4,1)*IF(parametros!$A$5="Sim",1+parametros!$E$5,1)*(1+parametros!$E$6))),"")))))) -> 1 | E4: =IF(OR(C4="",NOT(ISNUMBER(D4))),"",ROUND(C4*D4,2)) -> 42500 | F4: =IF(OR(C4="",E4=""),"",IF(G4<>"Sim",0,ROUND(E4-C4,2))) -> 0 | G4: Sim
A5: 45017 | B5: =IF(A5="","",IF(OR(A5<MIN(parametros!$C$2:$C$6),A5>MAX(parametros!$D$2:$D$6)),"Fora dos ciclos",LOWER(LOOKUP(A5,parametros!$C$2:$C$6,parametros!$B$2:$B$6)))) -> c0 | C5: 42500 | D5: =IF(B5="","",IF(B5="c0",1,IF(B5="c1",IF(parametros!$A$3<>"Sim","",IF(NOT(ISNUMBER(parametros!$E$3)),"",1+parametros!$E$3)),IF(B5="c2",IF(parametros!$A$4<>"Sim","",IF(NOT(ISNUMBER(parametros!$E$4)),"",IF(parametros!$A$3="Sim",1+parametros!$E$3,1)*(1+parametros!$E$4))),IF(B5="c3",IF(parametros!$A$5<>"Sim","",IF(NOT(ISNUMBER(parametros!$E$5)),"",IF(parametros!$A$3="Sim",1+parametros!$E$3,1)*IF(parametros!$A$4="Sim",1+parametros!$E$4,1)*(1+parametros!$E$5))),IF(B5="c4",IF(parametros!$A$6<>"Sim","",IF(NOT(ISNUMBER(parametros!$E$6)),"",IF(parametros!$A$3="Sim",1+parametros!$E$3,1)*IF(parametros!$A$4="Sim",1+parametros!$E$4,1)*IF(parametros!$A$5="Sim",1+parametros!$E$5,1)*(1+parametros!$E$6))),"")))))) -> 1 | E5: =IF(OR(C5="",NOT(ISNUMBER(D5))),"",ROUND(C5*D5,2)) -> 42500 | F5: =IF(OR(C5="",E5=""),"",IF(G5<>"Sim",0,ROUND(E5-C5,2))) -> 0 | G5: Sim
A6: 45047 | B6: =IF(A6="","",IF(OR(A6<MIN(parametros!$C$2:$C$6),A6>MAX(parametros!$D$2:$D$6)),"Fora dos ciclos",LOWER(LOOKUP(A6,parametros!$C$2:$C$6,parametros!$B$2:$B$6)))) -> c0 | C6: 42500 | D6: =IF(B6="","",IF(B6="c0",1,IF(B6="c1",IF(parametros!$A$3<>"Sim","",IF(NOT(ISNUMBER(parametros!$E$3)),"",1+parametros!$E$3)),IF(B6="c2",IF(parametros!$A$4<>"Sim","",IF(NOT(ISNUMBER(parametros!$E$4)),"",IF(parametros!$A$3="Sim",1+parametros!$E$3,1)*(1+parametros!$E$4))),IF(B6="c3",IF(parametros!$A$5<>"Sim","",IF(NOT(ISNUMBER(parametros!$E$5)),"",IF(parametros!$A$3="Sim",1+parametros!$E$3,1)*IF(parametros!$A$4="Sim",1+parametros!$E$4,1)*(1+parametros!$E$5))),IF(B6="c4",IF(parametros!$A$6<>"Sim","",IF(NOT(ISNUMBER(parametros!$E$6)),"",IF(parametros!$A$3="Sim",1+parametros!$E$3,1)*IF(parametros!$A$4="Sim",1+parametros!$E$4,1)*IF(parametros!$A$5="Sim",1+parametros!$E$5,1)*(1+parametros!$E$6))),"")))))) -> 1 | E6: =IF(OR(C6="",NOT(ISNUMBER(D6))),"",ROUND(C6*D6,2)) -> 42500 | F6: =IF(OR(C6="",E6=""),"",IF(G6<>"Sim",0,ROUND(E6-C6,2))) -> 0 | G6: Sim
A7: 45078 | B7: =IF(A7="","",IF(OR(A7<MIN(parametros!$C$2:$C$6),A7>MAX(parametros!$D$2:$D$6)),"Fora dos ciclos",LOWER(LOOKUP(A7,parametros!$C$2:$C$6,parametros!$B$2:$B$6)))) -> c0 | C7: 42500 | D7: =IF(B7="","",IF(B7="c0",1,IF(B7="c1",IF(parametros!$A$3<>"Sim","",IF(NOT(ISNUMBER(parametros!$E$3)),"",1+parametros!$E$3)),IF(B7="c2",IF(parametros!$A$4<>"Sim","",IF(NOT(ISNUMBER(parametros!$E$4)),"",IF(parametros!$A$3="Sim",1+parametros!$E$3,1)*(1+parametros!$E$4))),IF(B7="c3",IF(parametros!$A$5<>"Sim","",IF(NOT(ISNUMBER(parametros!$E$5)),"",IF(parametros!$A$3="Sim",1+parametros!$E$3,1)*IF(parametros!$A$4="Sim",1+parametros!$E$4,1)*(1+parametros!$E$5))),IF(B7="c4",IF(parametros!$A$6<>"Sim","",IF(NOT(ISNUMBER(parametros!$E$6)),"",IF(parametros!$A$3="Sim",1+parametros!$E$3,1)*IF(parametros!$A$4="Sim",1+parametros!$E$4,1)*IF(parametros!$A$5="Sim",1+parametros!$E$5,1)*(1+parametros!$E$6))),"")))))) -> 1 | E7: =IF(OR(C7="",NOT(ISNUMBER(D7))),"",ROUND(C7*D7,2)) -> 42500 | F7: =IF(OR(C7="",E7=""),"",IF(G7<>"Sim",0,ROUND(E7-C7,2))) -> 0 | G7: Sim
A8: 45108 | B8: =IF(A8="","",IF(OR(A8<MIN(parametros!$C$2:$C$6),A8>MAX(parametros!$D$2:$D$6)),"Fora dos ciclos",LOWER(LOOKUP(A8,parametros!$C$2:$C$6,parametros!$B$2:$B$6)))) -> c0 | C8: 42500 | D8: =IF(B8="","",IF(B8="c0",1,IF(B8="c1",IF(parametros!$A$3<>"Sim","",IF(NOT(ISNUMBER(parametros!$E$3)),"",1+parametros!$E$3)),IF(B8="c2",IF(parametros!$A$4<>"Sim","",IF(NOT(ISNUMBER(parametros!$E$4)),"",IF(parametros!$A$3="Sim",1+parametros!$E$3,1)*(1+parametros!$E$4))),IF(B8="c3",IF(parametros!$A$5<>"Sim","",IF(NOT(ISNUMBER(parametros!$E$5)),"",IF(parametros!$A$3="Sim",1+parametros!$E$3,1)*IF(parametros!$A$4="Sim",1+parametros!$E$4,1)*(1+parametros!$E$5))),IF(B8="c4",IF(parametros!$A$6<>"Sim","",IF(NOT(ISNUMBER(parametros!$E$6)),"",IF(parametros!$A$3="Sim",1+parametros!$E$3,1)*IF(parametros!$A$4="Sim",1+parametros!$E$4,1)*IF(parametros!$A$5="Sim",1+parametros!$E$5,1)*(1+parametros!$E$6))),"")))))) -> 1 | E8: =IF(OR(C8="",NOT(ISNUMBER(D8))),"",ROUND(C8*D8,2)) -> 42500 | F8: =IF(OR(C8="",E8=""),"",IF(G8<>"Sim",0,ROUND(E8-C8,2))) -> 0 | G8: Sim
A9: 45139 | B9: =IF(A9="","",IF(OR(A9<MIN(parametros!$C$2:$C$6),A9>MAX(parametros!$D$2:$D$6)),"Fora dos ciclos",LOWER(LOOKUP(A9,parametros!$C$2:$C$6,parametros!$B$2:$B$6)))) -> c0 | C9: 42500 | D9: =IF(B9="","",IF(B9="c0",1,IF(B9="c1",IF(parametros!$A$3<>"Sim","",IF(NOT(ISNUMBER(parametros!$E$3)),"",1+parametros!$E$3)),IF(B9="c2",IF(parametros!$A$4<>"Sim","",IF(NOT(ISNUMBER(parametros!$E$4)),"",IF(parametros!$A$3="Sim",1+parametros!$E$3,1)*(1+parametros!$E$4))),IF(B9="c3",IF(parametros!$A$5<>"Sim","",IF(NOT(ISNUMBER(parametros!$E$5)),"",IF(parametros!$A$3="Sim",1+parametros!$E$3,1)*IF(parametros!$A$4="Sim",1+parametros!$E$4,1)*(1+parametros!$E$5))),IF(B9="c4",IF(parametros!$A$6<>"Sim","",IF(NOT(ISNUMBER(parametros!$E$6)),"",IF(parametros!$A$3="Sim",1+parametros!$E$3,1)*IF(parametros!$A$4="Sim",1+parametros!$E$4,1)*IF(parametros!$A$5="Sim",1+parametros!$E$5,1)*(1+parametros!$E$6))),"")))))) -> 1 | E9: =IF(OR(C9="",NOT(ISNUMBER(D9))),"",ROUND(C9*D9,2)) -> 42500 | F9: =IF(OR(C9="",E9=""),"",IF(G9<>"Sim",0,ROUND(E9-C9,2))) -> 0 | G9: Sim
A10: 45170 | B10: =IF(A10="","",IF(OR(A10<MIN(parametros!$C$2:$C$6),A10>MAX(parametros!$D$2:$D$6)),"Fora dos ciclos",LOWER(LOOKUP(A10,parametros!$C$2:$C$6,parametros!$B$2:$B$6)))) -> c0 | C10: 42500 | D10: =IF(B10="","",IF(B10="c0",1,IF(B10="c1",IF(parametros!$A$3<>"Sim","",IF(NOT(ISNUMBER(parametros!$E$3)),"",1+parametros!$E$3)),IF(B10="c2",IF(parametros!$A$4<>"Sim","",IF(NOT(ISNUMBER(parametros!$E$4)),"",IF(parametros!$A$3="Sim",1+parametros!$E$3,1)*(1+parametros!$E$4))),IF(B10="c3",IF(parametros!$A$5<>"Sim","",IF(NOT(ISNUMBER(parametros!$E$5)),"",IF(parametros!$A$3="Sim",1+parametros!$E$3,1)*IF(parametros!$A$4="Sim",1+parametros!$E$4,1)*(1+parametros!$E$5))),IF(B10="c4",IF(parametros!$A$6<>"Sim","",IF(NOT(ISNUMBER(parametros!$E$6)),"",IF(parametros!$A$3="Sim",1+parametros!$E$3,1)*IF(parametros!$A$4="Sim",1+parametros!$E$4,1)*IF(parametros!$A$5="Sim",1+parametros!$E$5,1)*(1+parametros!$E$6))),"")))))) -> 1 | E10: =IF(OR(C10="",NOT(ISNUMBER(D10))),"",ROUND(C10*D10,2)) -> 42500 | F10: =IF(OR(C10="",E10=""),"",IF(G10<>"Sim",0,ROUND(E10-C10,2))) -> 0 | G10: Sim
A11: 45200 | B11: =IF(A11="","",IF(OR(A11<MIN(parametros!$C$2:$C$6),A11>MAX(parametros!$D$2:$D$6)),"Fora dos ciclos",LOWER(LOOKUP(A11,parametros!$C$2:$C$6,parametros!$B$2:$B$6)))) -> c0 | C11: 42500 | D11: =IF(B11="","",IF(B11="c0",1,IF(B11="c1",IF(parametros!$A$3<>"Sim","",IF(NOT(ISNUMBER(parametros!$E$3)),"",1+parametros!$E$3)),IF(B11="c2",IF(parametros!$A$4<>"Sim","",IF(NOT(ISNUMBER(parametros!$E$4)),"",IF(parametros!$A$3="Sim",1+parametros!$E$3,1)*(1+parametros!$E$4))),IF(B11="c3",IF(parametros!$A$5<>"Sim","",IF(NOT(ISNUMBER(parametros!$E$5)),"",IF(parametros!$A$3="Sim",1+parametros!$E$3,1)*IF(parametros!$A$4="Sim",1+parametros!$E$4,1)*(1+parametros!$E$5))),IF(B11="c4",IF(parametros!$A$6<>"Sim","",IF(NOT(ISNUMBER(parametros!$E$6)),"",IF(parametros!$A$3="Sim",1+parametros!$E$3,1)*IF(parametros!$A$4="Sim",1+parametros!$E$4,1)*IF(parametros!$A$5="Sim",1+parametros!$E$5,1)*(1+parametros!$E$6))),"")))))) -> 1 | E11: =IF(OR(C11="",NOT(ISNUMBER(D11))),"",ROUND(C11*D11,2)) -> 42500 | F11: =IF(OR(C11="",E11=""),"",IF(G11<>"Sim",0,ROUND(E11-C11,2))) -> 0 | G11: Sim
A12: 45231 | B12: =IF(A12="","",IF(OR(A12<MIN(parametros!$C$2:$C$6),A12>MAX(parametros!$D$2:$D$6)),"Fora dos ciclos",LOWER(LOOKUP(A12,parametros!$C$2:$C$6,parametros!$B$2:$B$6)))) -> c0 | C12: 42500 | D12: =IF(B12="","",IF(B12="c0",1,IF(B12="c1",IF(parametros!$A$3<>"Sim","",IF(NOT(ISNUMBER(parametros!$E$3)),"",1+parametros!$E$3)),IF(B12="c2",IF(parametros!$A$4<>"Sim","",IF(NOT(ISNUMBER(parametros!$E$4)),"",IF(parametros!$A$3="Sim",1+parametros!$E$3,1)*(1+parametros!$E$4))),IF(B12="c3",IF(parametros!$A$5<>"Sim","",IF(NOT(ISNUMBER(parametros!$E$5)),"",IF(parametros!$A$3="Sim",1+parametros!$E$3,1)*IF(parametros!$A$4="Sim",1+parametros!$E$4,1)*(1+parametros!$E$5))),IF(B12="c4",IF(parametros!$A$6<>"Sim","",IF(NOT(ISNUMBER(parametros!$E$6)),"",IF(parametros!$A$3="Sim",1+parametros!$E$3,1)*IF(parametros!$A$4="Sim",1+parametros!$E$4,1)*IF(parametros!$A$5="Sim",1+parametros!$E$5,1)*(1+parametros!$E$6))),"")))))) -> 1 | E12: =IF(OR(C12="",NOT(ISNUMBER(D12))),"",ROUND(C12*D12,2)) -> 42500 | F12: =IF(OR(C12="",E12=""),"",IF(G12<>"Sim",0,ROUND(E12-C12,2))) -> 0 | G12: Sim
A13: 45261 | B13: =IF(A13="","",IF(OR(A13<MIN(parametros!$C$2:$C$6),A13>MAX(parametros!$D$2:$D$6)),"Fora dos ciclos",LOWER(LOOKUP(A13,parametros!$C$2:$C$6,parametros!$B$2:$B$6)))) -> c0 | C13: 42500 | D13: =IF(B13="","",IF(B13="c0",1,IF(B13="c1",IF(parametros!$A$3<>"Sim","",IF(NOT(ISNUMBER(parametros!$E$3)),"",1+parametros!$E$3)),IF(B13="c2",IF(parametros!$A$4<>"Sim","",IF(NOT(ISNUMBER(parametros!$E$4)),"",IF(parametros!$A$3="Sim",1+parametros!$E$3,1)*(1+parametros!$E$4))),IF(B13="c3",IF(parametros!$A$5<>"Sim","",IF(NOT(ISNUMBER(parametros!$E$5)),"",IF(parametros!$A$3="Sim",1+parametros!$E$3,1)*IF(parametros!$A$4="Sim",1+parametros!$E$4,1)*(1+parametros!$E$5))),IF(B13="c4",IF(parametros!$A$6<>"Sim","",IF(NOT(ISNUMBER(parametros!$E$6)),"",IF(parametros!$A$3="Sim",1+parametros!$E$3,1)*IF(parametros!$A$4="Sim",1+parametros!$E$4,1)*IF(parametros!$A$5="Sim",1+parametros!$E$5,1)*(1+parametros!$E$6))),"")))))) -> 1 | E13: =IF(OR(C13="",NOT(ISNUMBER(D13))),"",ROUND(C13*D13,2)) -> 42500 | F13: =IF(OR(C13="",E13=""),"",IF(G13<>"Sim",0,ROUND(E13-C13,2))) -> 0 | G13: Sim
... A25: 45627 | B25: =IF(A25="","",IF(OR(A25<MIN(parametros!$C$2:$C$6),A25>MAX(parametros!$D$2:$D$6)),"Fora dos ciclos",LOWER(LOOKUP(A25,parametros!$C$2:$C$6,parametros!$B$2:$B$6)))) -> c1 | C25: 42500 | D25: =IF(B25="","",IF(B25="c0",1,IF(B25="c1",IF(parametros!$A$3<>"Sim","",IF(NOT(ISNUMBER(parametros!$E$3)),"",1+parametros!$E$3)),IF(B25="c2",IF(parametros!$A$4<>"Sim","",IF(NOT(ISNUMBER(parametros!$E$4)),"",IF(parametros!$A$3="Sim",1+parametros!$E$3,1)*(1+parametros!$E$4))),IF(B25="c3",IF(parametros!$A$5<>"Sim","",IF(NOT(ISNUMBER(parametros!$E$5)),"",IF(parametros!$A$3="Sim",1+parametros!$E$3,1)*IF(parametros!$A$4="Sim",1+parametros!$E$4,1)*(1+parametros!$E$5))),IF(B25="c4",IF(parametros!$A$6<>"Sim","",IF(NOT(ISNUMBER(parametros!$E$6)),"",IF(parametros!$A$3="Sim",1+parametros!$E$3,1)*IF(parametros!$A$4="Sim",1+parametros!$E$4,1)*IF(parametros!$A$5="Sim",1+parametros!$E$5,1)*(1+parametros!$E$6))),"")))))) -> 1.0512 | E25: =IF(OR(C25="",NOT(ISNUMBER(D25))),"",ROUND(C25*D25,2)) -> 44676 | F25: =IF(OR(C25="",E25=""),"",IF(G25<>"Sim",0,ROUND(E25-C25,2))) -> 2176 | G25: Sim
B26: =IF(A26="","",IF(OR(A26<MIN(parametros!$C$2:$C$6),A26>MAX(parametros!$D$2:$D$6)),"Fora dos ciclos",LOWER(LOOKUP(A26,parametros!$C$2:$C$6,parametros!$B$2:$B$6)))) | D26: =IF(B26="","",IF(B26="c0",1,IF(B26="c1",IF(parametros!$A$3<>"Sim","",IF(NOT(ISNUMBER(parametros!$E$3)),"",1+parametros!$E$3)),IF(B26="c2",IF(parametros!$A$4<>"Sim","",IF(NOT(ISNUMBER(parametros!$E$4)),"",IF(parametros!$A$3="Sim",1+parametros!$E$3,1)*(1+parametros!$E$4))),IF(B26="c3",IF(parametros!$A$5<>"Sim","",IF(NOT(ISNUMBER(parametros!$E$5)),"",IF(parametros!$A$3="Sim",1+parametros!$E$3,1)*IF(parametros!$A$4="Sim",1+parametros!$E$4,1)*(1+parametros!$E$5))),IF(B26="c4",IF(parametros!$A$6<>"Sim","",IF(NOT(ISNUMBER(parametros!$E$6)),"",IF(parametros!$A$3="Sim",1+parametros!$E$3,1)*IF(parametros!$A$4="Sim",1+parametros!$E$4,1)*IF(parametros!$A$5="Sim",1+parametros!$E$5,1)*(1+parametros!$E$6))),"")))))) | E26: =IF(OR(C26="",NOT(ISNUMBER(D26))),"",ROUND(C26*D26,2)) | F26: =IF(OR(C26="",E26=""),"",IF(G26<>"Sim",0,ROUND(E26-C26,2)))
B27: =IF(A27="","",IF(OR(A27<MIN(parametros!$C$2:$C$6),A27>MAX(parametros!$D$2:$D$6)),"Fora dos ciclos",LOWER(LOOKUP(A27,parametros!$C$2:$C$6,parametros!$B$2:$B$6)))) | D27: =IF(B27="","",IF(B27="c0",1,IF(B27="c1",IF(parametros!$A$3<>"Sim","",IF(NOT(ISNUMBER(parametros!$E$3)),"",1+parametros!$E$3)),IF(B27="c2",IF(parametros!$A$4<>"Sim","",IF(NOT(ISNUMBER(parametros!$E$4)),"",IF(parametros!$A$3="Sim",1+parametros!$E$3,1)*(1+parametros!$E$4))),IF(B27="c3",IF(parametros!$A$5<>"Sim","",IF(NOT(ISNUMBER(parametros!$E$5)),"",IF(parametros!$A$3="Sim",1+parametros!$E$3,1)*IF(parametros!$A$4="Sim",1+parametros!$E$4,1)*(1+parametros!$E$5))),IF(B27="c4",IF(parametros!$A$6<>"Sim","",IF(NOT(ISNUMBER(parametros!$E$6)),"",IF(parametros!$A$3="Sim",1+parametros!$E$3,1)*IF(parametros!$A$4="Sim",1+parametros!$E$4,1)*IF(parametros!$A$5="Sim",1+parametros!$E$5,1)*(1+parametros!$E$6))),"")))))) | E27: =IF(OR(C27="",NOT(ISNUMBER(D27))),"",ROUND(C27*D27,2)) | F27: =IF(OR(C27="",E27=""),"",IF(G27<>"Sim",0,ROUND(E27-C27,2)))
B28: =IF(A28="","",IF(OR(A28<MIN(parametros!$C$2:$C$6),A28>MAX(parametros!$D$2:$D$6)),"Fora dos ciclos",LOWER(LOOKUP(A28,parametros!$C$2:$C$6,parametros!$B$2:$B$6)))) | D28: =IF(B28="","",IF(B28="c0",1,IF(B28="c1",IF(parametros!$A$3<>"Sim","",IF(NOT(ISNUMBER(parametros!$E$3)),"",1+parametros!$E$3)),IF(B28="c2",IF(parametros!$A$4<>"Sim","",IF(NOT(ISNUMBER(parametros!$E$4)),"",IF(parametros!$A$3="Sim",1+parametros!$E$3,1)*(1+parametros!$E$4))),IF(B28="c3",IF(parametros!$A$5<>"Sim","",IF(NOT(ISNUMBER(parametros!$E$5)),"",IF(parametros!$A$3="Sim",1+parametros!$E$3,1)*IF(parametros!$A$4="Sim",1+parametros!$E$4,1)*(1+parametros!$E$5))),IF(B28="c4",IF(parametros!$A$6<>"Sim","",IF(NOT(ISNUMBER(parametros!$E$6)),"",IF(parametros!$A$3="Sim",1+parametros!$E$3,1)*IF(parametros!$A$4="Sim",1+parametros!$E$4,1)*IF(parametros!$A$5="Sim",1+parametros!$E$5,1)*(1+parametros!$E$6))),"")))))) | E28: =IF(OR(C28="",NOT(ISNUMBER(D28))),"",ROUND(C28*D28,2)) | F28: =IF(OR(C28="",E28=""),"",IF(G28<>"Sim",0,ROUND(E28-C28,2)))
B29: =IF(A29="","",IF(OR(A29<MIN(parametros!$C$2:$C$6),A29>MAX(parametros!$D$2:$D$6)),"Fora dos ciclos",LOWER(LOOKUP(A29,parametros!$C$2:$C$6,parametros!$B$2:$B$6)))) | D29: =IF(B29="","",IF(B29="c0",1,IF(B29="c1",IF(parametros!$A$3<>"Sim","",IF(NOT(ISNUMBER(parametros!$E$3)),"",1+parametros!$E$3)),IF(B29="c2",IF(parametros!$A$4<>"Sim","",IF(NOT(ISNUMBER(parametros!$E$4)),"",IF(parametros!$A$3="Sim",1+parametros!$E$3,1)*(1+parametros!$E$4))),IF(B29="c3",IF(parametros!$A$5<>"Sim","",IF(NOT(ISNUMBER(parametros!$E$5)),"",IF(parametros!$A$3="Sim",1+parametros!$E$3,1)*IF(parametros!$A$4="Sim",1+parametros!$E$4,1)*(1+parametros!$E$5))),IF(B29="c4",IF(parametros!$A$6<>"Sim","",IF(NOT(ISNUMBER(parametros!$E$6)),"",IF(parametros!$A$3="Sim",1+parametros!$E$3,1)*IF(parametros!$A$4="Sim",1+parametros!$E$4,1)*IF(parametros!$A$5="Sim",1+parametros!$E$5,1)*(1+parametros!$E$6))),"")))))) | E29: =IF(OR(C29="",NOT(ISNUMBER(D29))),"",ROUND(C29*D29,2)) | F29: =IF(OR(C29="",E29=""),"",IF(G29<>"Sim",0,ROUND(E29-C29,2)))
B30: =IF(A30="","",IF(OR(A30<MIN(parametros!$C$2:$C$6),A30>MAX(parametros!$D$2:$D$6)),"Fora dos ciclos",LOWER(LOOKUP(A30,parametros!$C$2:$C$6,parametros!$B$2:$B$6)))) | D30: =IF(B30="","",IF(B30="c0",1,IF(B30="c1",IF(parametros!$A$3<>"Sim","",IF(NOT(ISNUMBER(parametros!$E$3)),"",1+parametros!$E$3)),IF(B30="c2",IF(parametros!$A$4<>"Sim","",IF(NOT(ISNUMBER(parametros!$E$4)),"",IF(parametros!$A$3="Sim",1+parametros!$E$3,1)*(1+parametros!$E$4))),IF(B30="c3",IF(parametros!$A$5<>"Sim","",IF(NOT(ISNUMBER(parametros!$E$5)),"",IF(parametros!$A$3="Sim",1+parametros!$E$3,1)*IF(parametros!$A$4="Sim",1+parametros!$E$4,1)*(1+parametros!$E$5))),IF(B30="c4",IF(parametros!$A$6<>"Sim","",IF(NOT(ISNUMBER(parametros!$E$6)),"",IF(parametros!$A$3="Sim",1+parametros!$E$3,1)*IF(parametros!$A$4="Sim",1+parametros!$E$4,1)*IF(parametros!$A$5="Sim",1+parametros!$E$5,1)*(1+parametros!$E$6))),"")))))) | E30: =IF(OR(C30="",NOT(ISNUMBER(D30))),"",ROUND(C30*D30,2)) | F30: =IF(OR(C30="",E30=""),"",IF(G30<>"Sim",0,ROUND(E30-C30,2)))
B31: =IF(A31="","",IF(OR(A31<MIN(parametros!$C$2:$C$6),A31>MAX(parametros!$D$2:$D$6)),"Fora dos ciclos",LOWER(LOOKUP(A31,parametros!$C$2:$C$6,parametros!$B$2:$B$6)))) | D31: =IF(B31="","",IF(B31="c0",1,IF(B31="c1",IF(parametros!$A$3<>"Sim","",IF(NOT(ISNUMBER(parametros!$E$3)),"",1+parametros!$E$3)),IF(B31="c2",IF(parametros!$A$4<>"Sim","",IF(NOT(ISNUMBER(parametros!$E$4)),"",IF(parametros!$A$3="Sim",1+parametros!$E$3,1)*(1+parametros!$E$4))),IF(B31="c3",IF(parametros!$A$5<>"Sim","",IF(NOT(ISNUMBER(parametros!$E$5)),"",IF(parametros!$A$3="Sim",1+parametros!$E$3,1)*IF(parametros!$A$4="Sim",1+parametros!$E$4,1)*(1+parametros!$E$5))),IF(B31="c4",IF(parametros!$A$6<>"Sim","",IF(NOT(ISNUMBER(parametros!$E$6)),"",IF(parametros!$A$3="Sim",1+parametros!$E$3,1)*IF(parametros!$A$4="Sim",1+parametros!$E$4,1)*IF(parametros!$A$5="Sim",1+parametros!$E$5,1)*(1+parametros!$E$6))),"")))))) | E31: =IF(OR(C31="",NOT(ISNUMBER(D31))),"",ROUND(C31*D31,2)) | F31: =IF(OR(C31="",E31=""),"",IF(G31<>"Sim",0,ROUND(E31-C31,2)))
B32: =IF(A32="","",IF(OR(A32<MIN(parametros!$C$2:$C$6),A32>MAX(parametros!$D$2:$D$6)),"Fora dos ciclos",LOWER(LOOKUP(A32,parametros!$C$2:$C$6,parametros!$B$2:$B$6)))) | D32: =IF(B32="","",IF(B32="c0",1,IF(B32="c1",IF(parametros!$A$3<>"Sim","",IF(NOT(ISNUMBER(parametros!$E$3)),"",1+parametros!$E$3)),IF(B32="c2",IF(parametros!$A$4<>"Sim","",IF(NOT(ISNUMBER(parametros!$E$4)),"",IF(parametros!$A$3="Sim",1+parametros!$E$3,1)*(1+parametros!$E$4))),IF(B32="c3",IF(parametros!$A$5<>"Sim","",IF(NOT(ISNUMBER(parametros!$E$5)),"",IF(parametros!$A$3="Sim",1+parametros!$E$3,1)*IF(parametros!$A$4="Sim",1+parametros!$E$4,1)*(1+parametros!$E$5))),IF(B32="c4",IF(parametros!$A$6<>"Sim","",IF(NOT(ISNUMBER(parametros!$E$6)),"",IF(parametros!$A$3="Sim",1+parametros!$E$3,1)*IF(parametros!$A$4="Sim",1+parametros!$E$4,1)*IF(parametros!$A$5="Sim",1+parametros!$E$5,1)*(1+parametros!$E$6))),"")))))) | E32: =IF(OR(C32="",NOT(ISNUMBER(D32))),"",ROUND(C32*D32,2)) | F32: =IF(OR(C32="",E32=""),"",IF(G32<>"Sim",0,ROUND(E32-C32,2)))
B33: =IF(A33="","",IF(OR(A33<MIN(parametros!$C$2:$C$6),A33>MAX(parametros!$D$2:$D$6)),"Fora dos ciclos",LOWER(LOOKUP(A33,parametros!$C$2:$C$6,parametros!$B$2:$B$6)))) | D33: =IF(B33="","",IF(B33="c0",1,IF(B33="c1",IF(parametros!$A$3<>"Sim","",IF(NOT(ISNUMBER(parametros!$E$3)),"",1+parametros!$E$3)),IF(B33="c2",IF(parametros!$A$4<>"Sim","",IF(NOT(ISNUMBER(parametros!$E$4)),"",IF(parametros!$A$3="Sim",1+parametros!$E$3,1)*(1+parametros!$E$4))),IF(B33="c3",IF(parametros!$A$5<>"Sim","",IF(NOT(ISNUMBER(parametros!$E$5)),"",IF(parametros!$A$3="Sim",1+parametros!$E$3,1)*IF(parametros!$A$4="Sim",1+parametros!$E$4,1)*(1+parametros!$E$5))),IF(B33="c4",IF(parametros!$A$6<>"Sim","",IF(NOT(ISNUMBER(parametros!$E$6)),"",IF(parametros!$A$3="Sim",1+parametros!$E$3,1)*IF(parametros!$A$4="Sim",1+parametros!$E$4,1)*IF(parametros!$A$5="Sim",1+parametros!$E$5,1)*(1+parametros!$E$6))),"")))))) | E33: =IF(OR(C33="",NOT(ISNUMBER(D33))),"",ROUND(C33*D33,2)) | F33: =IF(OR(C33="",E33=""),"",IF(G33<>"Sim",0,ROUND(E33-C33,2)))
B34: =IF(A34="","",IF(OR(A34<MIN(parametros!$C$2:$C$6),A34>MAX(parametros!$D$2:$D$6)),"Fora dos ciclos",LOWER(LOOKUP(A34,parametros!$C$2:$C$6,parametros!$B$2:$B$6)))) | D34: =IF(B34="","",IF(B34="c0",1,IF(B34="c1",IF(parametros!$A$3<>"Sim","",IF(NOT(ISNUMBER(parametros!$E$3)),"",1+parametros!$E$3)),IF(B34="c2",IF(parametros!$A$4<>"Sim","",IF(NOT(ISNUMBER(parametros!$E$4)),"",IF(parametros!$A$3="Sim",1+parametros!$E$3,1)*(1+parametros!$E$4))),IF(B34="c3",IF(parametros!$A$5<>"Sim","",IF(NOT(ISNUMBER(parametros!$E$5)),"",IF(parametros!$A$3="Sim",1+parametros!$E$3,1)*IF(parametros!$A$4="Sim",1+parametros!$E$4,1)*(1+parametros!$E$5))),IF(B34="c4",IF(parametros!$A$6<>"Sim","",IF(NOT(ISNUMBER(parametros!$E$6)),"",IF(parametros!$A$3="Sim",1+parametros!$E$3,1)*IF(parametros!$A$4="Sim",1+parametros!$E$4,1)*IF(parametros!$A$5="Sim",1+parametros!$E$5,1)*(1+parametros!$E$6))),"")))))) | E34: =IF(OR(C34="",NOT(ISNUMBER(D34))),"",ROUND(C34*D34,2)) | F34: =IF(OR(C34="",E34=""),"",IF(G34<>"Sim",0,ROUND(E34-C34,2)))
B35: =IF(A35="","",IF(OR(A35<MIN(parametros!$C$2:$C$6),A35>MAX(parametros!$D$2:$D$6)),"Fora dos ciclos",LOWER(LOOKUP(A35,parametros!$C$2:$C$6,parametros!$B$2:$B$6)))) | D35: =IF(B35="","",IF(B35="c0",1,IF(B35="c1",IF(parametros!$A$3<>"Sim","",IF(NOT(ISNUMBER(parametros!$E$3)),"",1+parametros!$E$3)),IF(B35="c2",IF(parametros!$A$4<>"Sim","",IF(NOT(ISNUMBER(parametros!$E$4)),"",IF(parametros!$A$3="Sim",1+parametros!$E$3,1)*(1+parametros!$E$4))),IF(B35="c3",IF(parametros!$A$5<>"Sim","",IF(NOT(ISNUMBER(parametros!$E$5)),"",IF(parametros!$A$3="Sim",1+parametros!$E$3,1)*IF(parametros!$A$4="Sim",1+parametros!$E$4,1)*(1+parametros!$E$5))),IF(B35="c4",IF(parametros!$A$6<>"Sim","",IF(NOT(ISNUMBER(parametros!$E$6)),"",IF(parametros!$A$3="Sim",1+parametros!$E$3,1)*IF(parametros!$A$4="Sim",1+parametros!$E$4,1)*IF(parametros!$A$5="Sim",1+parametros!$E$5,1)*(1+parametros!$E$6))),"")))))) | E35: =IF(OR(C35="",NOT(ISNUMBER(D35))),"",ROUND(C35*D35,2)) | F35: =IF(OR(C35="",E35=""),"",IF(G35<>"Sim",0,ROUND(E35-C35,2)))
B36: =IF(A36="","",IF(OR(A36<MIN(parametros!$C$2:$C$6),A36>MAX(parametros!$D$2:$D$6)),"Fora dos ciclos",LOWER(LOOKUP(A36,parametros!$C$2:$C$6,parametros!$B$2:$B$6)))) | D36: =IF(B36="","",IF(B36="c0",1,IF(B36="c1",IF(parametros!$A$3<>"Sim","",IF(NOT(ISNUMBER(parametros!$E$3)),"",1+parametros!$E$3)),IF(B36="c2",IF(parametros!$A$4<>"Sim","",IF(NOT(ISNUMBER(parametros!$E$4)),"",IF(parametros!$A$3="Sim",1+parametros!$E$3,1)*(1+parametros!$E$4))),IF(B36="c3",IF(parametros!$A$5<>"Sim","",IF(NOT(ISNUMBER(parametros!$E$5)),"",IF(parametros!$A$3="Sim",1+parametros!$E$3,1)*IF(parametros!$A$4="Sim",1+parametros!$E$4,1)*(1+parametros!$E$5))),IF(B36="c4",IF(parametros!$A$6<>"Sim","",IF(NOT(ISNUMBER(parametros!$E$6)),"",IF(parametros!$A$3="Sim",1+parametros!$E$3,1)*IF(parametros!$A$4="Sim",1+parametros!$E$4,1)*IF(parametros!$A$5="Sim",1+parametros!$E$5,1)*(1+parametros!$E$6))),"")))))) | E36: =IF(OR(C36="",NOT(ISNUMBER(D36))),"",ROUND(C36*D36,2)) | F36: =IF(OR(C36="",E36=""),"",IF(G36<>"Sim",0,ROUND(E36-C36,2)))
B37: =IF(A37="","",IF(OR(A37<MIN(parametros!$C$2:$C$6),A37>MAX(parametros!$D$2:$D$6)),"Fora dos ciclos",LOWER(LOOKUP(A37,parametros!$C$2:$C$6,parametros!$B$2:$B$6)))) | D37: =IF(B37="","",IF(B37="c0",1,IF(B37="c1",IF(parametros!$A$3<>"Sim","",IF(NOT(ISNUMBER(parametros!$E$3)),"",1+parametros!$E$3)),IF(B37="c2",IF(parametros!$A$4<>"Sim","",IF(NOT(ISNUMBER(parametros!$E$4)),"",IF(parametros!$A$3="Sim",1+parametros!$E$3,1)*(1+parametros!$E$4))),IF(B37="c3",IF(parametros!$A$5<>"Sim","",IF(NOT(ISNUMBER(parametros!$E$5)),"",IF(parametros!$A$3="Sim",1+parametros!$E$3,1)*IF(parametros!$A$4="Sim",1+parametros!$E$4,1)*(1+parametros!$E$5))),IF(B37="c4",IF(parametros!$A$6<>"Sim","",IF(NOT(ISNUMBER(parametros!$E$6)),"",IF(parametros!$A$3="Sim",1+parametros!$E$3,1)*IF(parametros!$A$4="Sim",1+parametros!$E$4,1)*IF(parametros!$A$5="Sim",1+parametros!$E$5,1)*(1+parametros!$E$6))),"")))))) | E37: =IF(OR(C37="",NOT(ISNUMBER(D37))),"",ROUND(C37*D37,2)) | F37: =IF(OR(C37="",E37=""),"",IF(G37<>"Sim",0,ROUND(E37-C37,2)))
... B73: =IF(A73="","",IF(OR(A73<MIN(parametros!$C$2:$C$6),A73>MAX(parametros!$D$2:$D$6)),"Fora dos ciclos",LOWER(LOOKUP(A73,parametros!$C$2:$C$6,parametros!$B$2:$B$6)))) | D73: =IF(B73="","",IF(B73="c0",1,IF(B73="c1",IF(parametros!$A$3<>"Sim","",IF(NOT(ISNUMBER(parametros!$E$3)),"",1+parametros!$E$3)),IF(B73="c2",IF(parametros!$A$4<>"Sim","",IF(NOT(ISNUMBER(parametros!$E$4)),"",IF(parametros!$A$3="Sim",1+parametros!$E$3,1)*(1+parametros!$E$4))),IF(B73="c3",IF(parametros!$A$5<>"Sim","",IF(NOT(ISNUMBER(parametros!$E$5)),"",IF(parametros!$A$3="Sim",1+parametros!$E$3,1)*IF(parametros!$A$4="Sim",1+parametros!$E$4,1)*(1+parametros!$E$5))),IF(B73="c4",IF(parametros!$A$6<>"Sim","",IF(NOT(ISNUMBER(parametros!$E$6)),"",IF(parametros!$A$3="Sim",1+parametros!$E$3,1)*IF(parametros!$A$4="Sim",1+parametros!$E$4,1)*IF(parametros!$A$5="Sim",1+parametros!$E$5,1)*(1+parametros!$E$6))),"")))))) | E73: =IF(OR(C73="",NOT(ISNUMBER(D73))),"",ROUND(C73*D73,2)) | F73: =IF(OR(C73="",E73=""),"",IF(G73<>"Sim",0,ROUND(E73-C73,2)))

Sheet itens_Remanesc
A1: ITEM | B1: QTD_BASE_ORIGINAL (0 PARA NOVO ITEM FORMALIZADO) | C1: VU_ORIGINAL | D1: VALOR_TOTAL | E1: =IF(parametros!$C$3="","QTD_REM_BASE_C1","QTD_REM_BASE_C1"&CHAR(10)&"Inicio: "&RIGHT("0"&DAY(parametros!$C$3),2)&"/"&RIGHT("0"&MONTH(parametros!$C$3),2)&"/"&YEAR(parametros!$C$3)) -> QTD_REM_BASE_C1 Inicio: 01/01/2024 | F1: =IF(parametros!$C$3="","VALOR_REM_INICIO_C1","VALOR_REM_INICIO_C1"&CHAR(10)&"Inicio: "&RIGHT("0"&DAY(parametros!$C$3),2)&"/"&RIGHT("0"&MONTH(parametros!$C$3),2)&"/"&YEAR(parametros!$C$3)) -> VALOR_REM_INICIO_C1 Inicio: 01/01/2024 | G1: =IF(parametros!$C$4="","QTD_REM_BASE_C2","QTD_REM_BASE_C2"&CHAR(10)&"Inicio: "&RIGHT("0"&DAY(parametros!$C$4),2)&"/"&RIGHT("0"&MONTH(parametros!$C$4),2)&"/"&YEAR(parametros!$C$4)) -> QTD_REM_BASE_C2 Inicio: 01/01/2025 | H1: =IF(parametros!$C$4="","VALOR_REM_INICIO_C2","VALOR_REM_INICIO_C2"&CHAR(10)&"Inicio: "&RIGHT("0"&DAY(parametros!$C$4),2)&"/"&RIGHT("0"&MONTH(parametros!$C$4),2)&"/"&YEAR(parametros!$C$4)) -> VALOR_REM_INICIO_C2 Inicio: 01/01/2025 | I1: =IF(parametros!$C$5="","QTD_REM_BASE_C3","QTD_REM_BASE_C3"&CHAR(10)&"Inicio: "&RIGHT("0"&DAY(parametros!$C$5),2)&"/"&RIGHT("0"&MONTH(parametros!$C$5),2)&"/"&YEAR(parametros!$C$5)) -> QTD_REM_BASE_C3 Inicio: 01/01/2026 | J1: =IF(parametros!$C$5="","VALOR_REM_INICIO_C3","VALOR_REM_INICIO_C3"&CHAR(10)&"Inicio: "&RIGHT("0"&DAY(parametros!$C$5),2)&"/"&RIGHT("0"&MONTH(parametros!$C$5),2)&"/"&YEAR(parametros!$C$5)) -> VALOR_REM_INICIO_C3 Inicio: 01/01/2026 | K1: =IF(parametros!$C$6="","QTD_REM_BASE_C4","QTD_REM_BASE_C4"&CHAR(10)&"Inicio: "&RIGHT("0"&DAY(parametros!$C$6),2)&"/"&RIGHT("0"&MONTH(parametros!$C$6),2)&"/"&YEAR(parametros!$C$6)) -> QTD_REM_BASE_C4 Inicio: 01/01/2027 | L1: =IF(parametros!$C$6="","VALOR_REM_INICIO_C4","VALOR_REM_INICIO_C4"&CHAR(10)&"Inicio: "&RIGHT("0"&DAY(parametros!$C$6),2)&"/"&RIGHT("0"&MONTH(parametros!$C$6),2)&"/"&YEAR(parametros!$C$6)) -> VALOR_REM_INICIO_C4 Inicio: 01/01/2027 | M1: =IF(parametros!$C$3="","QTD_EXECUTADA_C1","QTD_EXECUTADA_C1"&CHAR(10)&"Inicio: "&RIGHT("0"&DAY(parametros!$C$3),2)&"/"&RIGHT("0"&MONTH(parametros!$C$3),2)&"/"&YEAR(parametros!$C$3)) -> QTD_EXECUTADA_C1 Inicio: 01/01/2024 | N1: =IF(parametros!$C$3="","VALOR_EXECUTADO_C1","VALOR_EXECUTADO_C1"&CHAR(10)&"Inicio: "&RIGHT("0"&DAY(parametros!$C$3),2)&"/"&RIGHT("0"&MONTH(parametros!$C$3),2)&"/"&YEAR(parametros!$C$3)) -> VALOR_EXECUTADO_C1 Inicio: 01/01/2024 | O1: =IF(parametros!$C$4="","QTD_EXECUTADA_C2","QTD_EXECUTADA_C2"&CHAR(10)&"Inicio: "&RIGHT("0"&DAY(parametros!$C$4),2)&"/"&RIGHT("0"&MONTH(parametros!$C$4),2)&"/"&YEAR(parametros!$C$4)) -> QTD_EXECUTADA_C2 Inicio: 01/01/2025 | P1: =IF(parametros!$C$4="","VALOR_EXECUTADO_C2","VALOR_EXECUTADO_C2"&CHAR(10)&"Inicio: "&RIGHT("0"&DAY(parametros!$C$4),2)&"/"&RIGHT("0"&MONTH(parametros!$C$4),2)&"/"&YEAR(parametros!$C$4)) -> VALOR_EXECUTADO_C2 Inicio: 01/01/2025 | Q1: =IF(parametros!$C$5="","QTD_EXECUTADA_C3","QTD_EXECUTADA_C3"&CHAR(10)&"Inicio: "&RIGHT("0"&DAY(parametros!$C$5),2)&"/"&RIGHT("0"&MONTH(parametros!$C$5),2)&"/"&YEAR(parametros!$C$5)) -> QTD_EXECUTADA_C3 Inicio: 01/01/2026 | R1: =IF(parametros!$C$5="","VALOR_EXECUTADO_C3","VALOR_EXECUTADO_C3"&CHAR(10)&"Inicio: "&RIGHT("0"&DAY(parametros!$C$5),2)&"/"&RIGHT("0"&MONTH(parametros!$C$5),2)&"/"&YEAR(parametros!$C$5)) -> VALOR_EXECUTADO_C3 Inicio: 01/01/2026 | S1: =IF(parametros!$C$6="","QTD_EXECUTADA_C4","QTD_EXECUTADA_C4"&CHAR(10)&"Inicio: "&RIGHT("0"&DAY(parametros!$C$6),2)&"/"&RIGHT("0"&MONTH(parametros!$C$6),2)&"/"&YEAR(parametros!$C$6)) -> QTD_EXECUTADA_C4 Inicio: 01/01/2027 | T1: =IF(parametros!$C$6="","VALOR_EXECUTADO_C4","VALOR_EXECUTADO_C4"&CHAR(10)&"Inicio: "&RIGHT("0"&DAY(parametros!$C$6),2)&"/"&RIGHT("0"&MONTH(parametros!$C$6),2)&"/"&YEAR(parametros!$C$6)) -> VALOR_EXECUTADO_C4 Inicio: 01/01/2027 | U1: CHECK | V1: CHECK_QTD | W1: CICLO | X1: COMPUTAR_NESTA_APURACAO | Y1: FATOR_PROPRIO | Z1: FATOR_ACUMULADO | AA1: EXECUÇÃO IMPLÍCITA C0 — INFORMATIVO | AB1: QTD_EXECUTADA_C0 | AC1: VALOR_EXECUTADO_C0 | AD1: QTD_CONTRATADA_VIGENTE_C0 | AE1: QTD_CONTRATADA_VIGENTE_C1 | AF1: QTD_CONTRATADA_VIGENTE_C2 | AG1: QTD_CONTRATADA_VIGENTE_C3 | AH1: QTD_CONTRATADA_VIGENTE_C4 | AI1: QTD_REM_AJUSTADA_C0 | AJ1: QTD_REM_AJUSTADA_C1 | AK1: QTD_REM_AJUSTADA_C2 | AL1: QTD_REM_AJUSTADA_C3 | AM1: QTD_REM_AJUSTADA_C4 | AN1: CHECK_POSICAO_CONTRATUAL
A2: ITEM-001 | B2: 120 | C2: 250 | D2: =IF(FALSE,ROUND(SUMIF($A1:A$2,"<>",$D1:D$2),2),IF(OR(A2="",B2="",C2=""),"",ROUND(B2*C2,2))) -> 30000 | E2: 120 | F2: =IF(FALSE,ROUND(SUMIF($A1:A$2,"<>",$F1:F$2),2),IF(OR(A2="",posicao_contratual!K2="",C2="",NOT(ISNUMBER($Z$3))),"",ROUND(posicao_contratual!K2*C2*$Z$3,2))) -> 31536 | G2: 120 | H2: =IF(FALSE,ROUND(SUMIF($A1:A$2,"<>",$H1:H$2),2),IF(OR(A2="",posicao_contratual!O2="",C2="",NOT(ISNUMBER($Z$4))),"",ROUND(posicao_contratual!O2*C2*$Z$4,2))) -> 32715.45 | I2: 120 | J2: =IF(FALSE,ROUND(SUMIF($A1:A$2,"<>",$J1:J$2),2),IF(OR(A2="",posicao_contratual!S2="",C2="",NOT(ISNUMBER($Z$5))),"",ROUND(posicao_contratual!S2*C2*$Z$5,2))) -> 33660.92 | K2: 120 | L2: =IF(FALSE,ROUND(SUMIF($A1:A$2,"<>",$L1:L$2),2),IF(OR(A2="",posicao_contratual!W2="",C2="",NOT(ISNUMBER($Z$6))),"",ROUND(posicao_contratual!W2*C2*$Z$6,2))) | M2: 120 | N2: =IF(FALSE,ROUND(SUMIF($A1:A$2,"<>",$N1:N$2),2),IF(OR(M2="",C2="",NOT(ISNUMBER($Z$3))),"",ROUND(M2*C2*$Z$3,2))) -> 31536 | O2: =IF(OR(posicao_contratual!N2="",posicao_contratual!R2=""),"",ROUND(MAX(posicao_contratual!N2+posicao_contratual!L2-posicao_contratual!R2,0),2)) -> 0 | P2: =IF(FALSE,ROUND(SUMIF($A1:A$2,"<>",$P1:P$2),2),IF(OR(O2="",C2="",NOT(ISNUMBER($Z$4))),"",ROUND(O2*C2*$Z$4,2))) -> 0 | Q2: =IF(OR(posicao_contratual!R2="",posicao_contratual!V2=""),"",ROUND(MAX(posicao_contratual!R2+posicao_contratual!P2-posicao_contratual!V2,0),2)) -> 0 | R2: =IF(FALSE,ROUND(SUMIF($A1:A$2,"<>",$R1:R$2),2),IF(OR(Q2="",C2="",NOT(ISNUMBER($Z$5))),"",ROUND(Q2*C2*$Z$5,2))) -> 0 | U2: =IF(A2="","",posicao_contratual!X2) -> OK | V2: =IF(A2="","",posicao_contratual!X2) -> OK | W2: C0 | X2: =parametros!$A$2 -> Nao | Y2: =IF(ISNUMBER(parametros!$E$2),parametros!$E$2,"") -> 0 | Z2: =IF(ISNUMBER(parametros!$F$2),parametros!$F$2,"") -> 1 | AB2: =IF(OR(A2="",posicao_contratual!E2="",posicao_contratual!J2=""),"",ROUND(MAX(posicao_contratual!E2-posicao_contratual!J2,0),2)) -> 0 | AC2: =IF(FALSE,ROUND(SUMIF($A1:A$2,"<>",$AC1:AC$2),2),IF(OR(AB2="",C2="",NOT(ISNUMBER($Z$2))),"",ROUND(AB2*C2*$Z$2,2))) -> 0 | AD2: =IF(A2="","",posicao_contratual!E2) -> 120 | AE2: =IF(A2="","",posicao_contratual!I2) -> 130 | AF2: =IF(A2="","",posicao_contratual!M2) -> 130 | AG2: =IF(A2="","",posicao_contratual!Q2) -> 130 | AH2: =IF(A2="","",posicao_contratual!U2) -> 130 | AI2: =IF(A2="","",posicao_contratual!G2) -> 120 | AJ2: =IF(A2="","",posicao_contratual!K2) -> 120 | AK2: =IF(A2="","",posicao_contratual!O2) -> 120 | AL2: =IF(A2="","",posicao_contratual!S2) -> 120 | AM2: =IF(A2="","",posicao_contratual!W2) -> 120 | AN2: =IF(A2="","",posicao_contratual!X2) -> OK
A3: ITEM-002 | B3: 80 | C3: 1500 | D3: =IF(AND(A3="",A2<>"",COUNTIF(A4:$A$200,"<>")=0),ROUND(SUMIF($A$2:A2,"<>",$D$2:D2),2),IF(OR(A3="",B3="",C3=""),"",ROUND(B3*C3,2))) -> 120000 | E3: 80 | F3: =IF(AND(A3="",A2<>"",COUNTIF(A4:$A$200,"<>")=0),ROUND(SUMIF($A$2:A2,"<>",$F$2:F2),2),IF(OR(A3="",posicao_contratual!K3="",C3="",NOT(ISNUMBER($Z$3))),"",ROUND(posicao_contratual!K3*C3*$Z$3,2))) -> 126144 | G3: 80 | H3: =IF(AND(A3="",A2<>"",COUNTIF(A4:$A$200,"<>")=0),ROUND(SUMIF($A$2:A2,"<>",$H$2:H2),2),IF(OR(A3="",posicao_contratual!O3="",C3="",NOT(ISNUMBER($Z$4))),"",ROUND(posicao_contratual!O3*C3*$Z$4,2))) -> 130861.79 | I3: 80 | J3: =IF(AND(A3="",A2<>"",COUNTIF(A4:$A$200,"<>")=0),ROUND(SUMIF($A$2:A2,"<>",$J$2:J2),2),IF(OR(A3="",posicao_contratual!S3="",C3="",NOT(ISNUMBER($Z$5))),"",ROUND(posicao_contratual!S3*C3*$Z$5,2))) -> 134643.69 | K3: 80 | L3: =IF(AND(A3="",A2<>"",COUNTIF(A4:$A$200,"<>")=0),ROUND(SUMIF($A$2:A2,"<>",$L$2:L2),2),IF(OR(A3="",posicao_contratual!W3="",C3="",NOT(ISNUMBER($Z$6))),"",ROUND(posicao_contratual!W3*C3*$Z$6,2))) | M3: 80 | N3: =IF(AND(A3="",A2<>"",COUNTIF(A4:$A$200,"<>")=0),ROUND(SUMIF($A$2:A2,"<>",$N$2:N2),2),IF(OR(M3="",C3="",NOT(ISNUMBER($Z$3))),"",ROUND(M3*C3*$Z$3,2))) -> 126144 | O3: =IF(OR(posicao_contratual!N3="",posicao_contratual!R3=""),"",ROUND(MAX(posicao_contratual!N3+posicao_contratual!L3-posicao_contratual!R3,0),2)) -> 0 | P3: =IF(AND(A3="",A2<>"",COUNTIF(A4:$A$200,"<>")=0),ROUND(SUMIF($A$2:A2,"<>",$P$2:P2),2),IF(OR(O3="",C3="",NOT(ISNUMBER($Z$4))),"",ROUND(O3*C3*$Z$4,2))) -> 0 | Q3: =IF(OR(posicao_contratual!R3="",posicao_contratual!V3=""),"",ROUND(MAX(posicao_contratual!R3+posicao_contratual!P3-posicao_contratual!V3,0),2)) -> 0 | R3: =IF(AND(A3="",A2<>"",COUNTIF(A4:$A$200,"<>")=0),ROUND(SUMIF($A$2:A2,"<>",$R$2:R2),2),IF(OR(Q3="",C3="",NOT(ISNUMBER($Z$5))),"",ROUND(Q3*C3*$Z$5,2))) -> 0 | U3: =IF(AND(A3="",A2<>"",COUNTIF(A4:$A$200,"<>")=0),"TOTAL",IF(A3="","",posicao_contratual!X3)) -> OK | V3: =IF(A3="","",posicao_contratual!X3) -> OK | W3: C1 | X3: =parametros!$A$3 -> Sim | Y3: =IF(ISNUMBER(parametros!$E$3),parametros!$E$3,"") -> 0.0512 | Z3: =IF(ISNUMBER(parametros!$F$3),parametros!$F$3,"") -> 1.0512 | AB3: =IF(OR(A3="",posicao_contratual!E3="",posicao_contratual!J3=""),"",ROUND(MAX(posicao_contratual!E3-posicao_contratual!J3,0),2)) -> 0 | AC3: =IF(AND(A3="",A2<>"",COUNTIF(A4:$A$200,"<>")=0),ROUND(SUMIF($A$2:A2,"<>",$AC$2:AC2),2),IF(OR(AB3="",C3="",NOT(ISNUMBER($Z$2))),"",ROUND(AB3*C3*$Z$2,2))) -> 0 | AD3: =IF(A3="","",posicao_contratual!E3) -> 80 | AE3: =IF(A3="","",posicao_contratual!I3) -> 80 | AF3: =IF(A3="","",posicao_contratual!M3) -> 80 | AG3: =IF(A3="","",posicao_contratual!Q3) -> 80 | AH3: =IF(A3="","",posicao_contratual!U3) -> 80 | AI3: =IF(A3="","",posicao_contratual!G3) -> 80 | AJ3: =IF(A3="","",posicao_contratual!K3) -> 80 | AK3: =IF(A3="","",posicao_contratual!O3) -> 80 | AL3: =IF(A3="","",posicao_contratual!S3) -> 80 | AM3: =IF(A3="","",posicao_contratual!W3) -> 80 | AN3: =IF(A3="","",posicao_contratual!X3) -> OK
A4: ITEM-003 | B4: 40 | C4: 3200 | D4: =IF(AND(A4="",A3<>"",COUNTIF(A5:$A$200,"<>")=0),ROUND(SUMIF($A$2:A3,"<>",$D$2:D3),2),IF(OR(A4="",B4="",C4=""),"",ROUND(B4*C4,2))) -> 128000 | E4: 40 | F4: =IF(AND(A4="",A3<>"",COUNTIF(A5:$A$200,"<>")=0),ROUND(SUMIF($A$2:A3,"<>",$F$2:F3),2),IF(OR(A4="",posicao_contratual!K4="",C4="",NOT(ISNUMBER($Z$3))),"",ROUND(posicao_contratual!K4*C4*$Z$3,2))) -> 134553.6 | G4: 40 | H4: =IF(AND(A4="",A3<>"",COUNTIF(A5:$A$200,"<>")=0),ROUND(SUMIF($A$2:A3,"<>",$H$2:H3),2),IF(OR(A4="",posicao_contratual!O4="",C4="",NOT(ISNUMBER($Z$4))),"",ROUND(posicao_contratual!O4*C4*$Z$4,2))) -> 139585.9 | I4: 40 | J4: =IF(AND(A4="",A3<>"",COUNTIF(A5:$A$200,"<>")=0),ROUND(SUMIF($A$2:A3,"<>",$J$2:J3),2),IF(OR(A4="",posicao_contratual!S4="",C4="",NOT(ISNUMBER($Z$5))),"",ROUND(posicao_contratual!S4*C4*$Z$5,2))) -> 143619.94 | K4: 40 | L4: =IF(AND(A4="",A3<>"",COUNTIF(A5:$A$200,"<>")=0),ROUND(SUMIF($A$2:A3,"<>",$L$2:L3),2),IF(OR(A4="",posicao_contratual!W4="",C4="",NOT(ISNUMBER($Z$6))),"",ROUND(posicao_contratual!W4*C4*$Z$6,2))) | M4: 40 | N4: =IF(AND(A4="",A3<>"",COUNTIF(A5:$A$200,"<>")=0),ROUND(SUMIF($A$2:A3,"<>",$N$2:N3),2),IF(OR(M4="",C4="",NOT(ISNUMBER($Z$3))),"",ROUND(M4*C4*$Z$3,2))) -> 134553.6 | O4: =IF(OR(posicao_contratual!N4="",posicao_contratual!R4=""),"",ROUND(MAX(posicao_contratual!N4+posicao_contratual!L4-posicao_contratual!R4,0),2)) -> 0 | P4: =IF(AND(A4="",A3<>"",COUNTIF(A5:$A$200,"<>")=0),ROUND(SUMIF($A$2:A3,"<>",$P$2:P3),2),IF(OR(O4="",C4="",NOT(ISNUMBER($Z$4))),"",ROUND(O4*C4*$Z$4,2))) -> 0 | Q4: =IF(OR(posicao_contratual!R4="",posicao_contratual!V4=""),"",ROUND(MAX(posicao_contratual!R4+posicao_contratual!P4-posicao_contratual!V4,0),2)) -> 0 | R4: =IF(AND(A4="",A3<>"",COUNTIF(A5:$A$200,"<>")=0),ROUND(SUMIF($A$2:A3,"<>",$R$2:R3),2),IF(OR(Q4="",C4="",NOT(ISNUMBER($Z$5))),"",ROUND(Q4*C4*$Z$5,2))) -> 0 | U4: =IF(AND(A4="",A3<>"",COUNTIF(A5:$A$200,"<>")=0),"TOTAL",IF(A4="","",posicao_contratual!X4)) -> OK | V4: =IF(A4="","",posicao_contratual!X4) -> OK | W4: C2 | X4: =parametros!$A$4 -> Nao | Y4: =IF(ISNUMBER(parametros!$E$4),parametros!$E$4,"") -> 0.0374 | Z4: =IF(ISNUMBER(parametros!$F$4),parametros!$F$4,"") -> 1.0905149 | AB4: =IF(OR(A4="",posicao_contratual!E4="",posicao_contratual!J4=""),"",ROUND(MAX(posicao_contratual!E4-posicao_contratual!J4,0),2)) -> 0 | AC4: =IF(AND(A4="",A3<>"",COUNTIF(A5:$A$200,"<>")=0),ROUND(SUMIF($A$2:A3,"<>",$AC$2:AC3),2),IF(OR(AB4="",C4="",NOT(ISNUMBER($Z$2))),"",ROUND(AB4*C4*$Z$2,2))) -> 0 | AD4: =IF(A4="","",posicao_contratual!E4) -> 40 | AE4: =IF(A4="","",posicao_contratual!I4) -> 40 | AF4: =IF(A4="","",posicao_contratual!M4) -> 40 | AG4: =IF(A4="","",posicao_contratual!Q4) -> 40 | AH4: =IF(A4="","",posicao_contratual!U4) -> 40 | AI4: =IF(A4="","",posicao_contratual!G4) -> 40 | AJ4: =IF(A4="","",posicao_contratual!K4) -> 40 | AK4: =IF(A4="","",posicao_contratual!O4) -> 40 | AL4: =IF(A4="","",posicao_contratual!S4) -> 40 | AM4: =IF(A4="","",posicao_contratual!W4) -> 40 | AN4: =IF(A4="","",posicao_contratual!X4) -> OK
D5: =IF(AND(A5="",A4<>"",COUNTIF(A6:$A$200,"<>")=0),ROUND(SUMIF($A$2:A4,"<>",$D$2:D4),2),IF(OR(A5="",B5="",C5=""),"",ROUND(B5*C5,2))) -> 278000 | F5: =IF(AND(A5="",A4<>"",COUNTIF(A6:$A$200,"<>")=0),ROUND(SUMIF($A$2:A4,"<>",$F$2:F4),2),IF(OR(A5="",posicao_contratual!K5="",C5="",NOT(ISNUMBER($Z$3))),"",ROUND(posicao_contratual!K5*C5*$Z$3,2))) -> 292233.6 | H5: =IF(AND(A5="",A4<>"",COUNTIF(A6:$A$200,"<>")=0),ROUND(SUMIF($A$2:A4,"<>",$H$2:H4),2),IF(OR(A5="",posicao_contratual!O5="",C5="",NOT(ISNUMBER($Z$4))),"",ROUND(posicao_contratual!O5*C5*$Z$4,2))) -> 303163.14 | J5: =IF(AND(A5="",A4<>"",COUNTIF(A6:$A$200,"<>")=0),ROUND(SUMIF($A$2:A4,"<>",$J$2:J4),2),IF(OR(A5="",posicao_contratual!S5="",C5="",NOT(ISNUMBER($Z$5))),"",ROUND(posicao_contratual!S5*C5*$Z$5,2))) -> 311924.55 | L5: =IF(AND(A5="",A4<>"",COUNTIF(A6:$A$200,"<>")=0),ROUND(SUMIF($A$2:A4,"<>",$L$2:L4),2),IF(OR(A5="",posicao_contratual!W5="",C5="",NOT(ISNUMBER($Z$6))),"",ROUND(posicao_contratual!W5*C5*$Z$6,2))) -> 0 | M5: =IF(OR(posicao_contratual!J5="",posicao_contratual!N5=""),"",ROUND(MAX(posicao_contratual!J5+posicao_contratual!H5-posicao_contratual!N5,0),2)) | N5: =IF(AND(A5="",A4<>"",COUNTIF(A6:$A$200,"<>")=0),ROUND(SUMIF($A$2:A4,"<>",$N$2:N4),2),IF(OR(M5="",C5="",NOT(ISNUMBER($Z$3))),"",ROUND(M5*C5*$Z$3,2))) -> 292233.6 | O5: =IF(OR(posicao_contratual!N5="",posicao_contratual!R5=""),"",ROUND(MAX(posicao_contratual!N5+posicao_contratual!L5-posicao_contratual!R5,0),2)) | P5: =IF(AND(A5="",A4<>"",COUNTIF(A6:$A$200,"<>")=0),ROUND(SUMIF($A$2:A4,"<>",$P$2:P4),2),IF(OR(O5="",C5="",NOT(ISNUMBER($Z$4))),"",ROUND(O5*C5*$Z$4,2))) -> 0 | Q5: =IF(OR(posicao_contratual!R5="",posicao_contratual!V5=""),"",ROUND(MAX(posicao_contratual!R5+posicao_contratual!P5-posicao_contratual!V5,0),2)) | R5: =IF(AND(A5="",A4<>"",COUNTIF(A6:$A$200,"<>")=0),ROUND(SUMIF($A$2:A4,"<>",$R$2:R4),2),IF(OR(Q5="",C5="",NOT(ISNUMBER($Z$5))),"",ROUND(Q5*C5*$Z$5,2))) -> 0 | U5: =IF(AND(A5="",A4<>"",COUNTIF(A6:$A$200,"<>")=0),"TOTAL",IF(A5="","",posicao_contratual!X5)) -> TOTAL | V5: =IF(A5="","",posicao_contratual!X5) | W5: C3 | X5: =parametros!$A$5 -> Nao | Y5: =IF(ISNUMBER(parametros!$E$5),parametros!$E$5,"") -> 0.0289 | Z5: =IF(ISNUMBER(parametros!$F$5),parametros!$F$5,"") -> 1.1220308 | AB5: =IF(OR(A5="",posicao_contratual!E5="",posicao_contratual!J5=""),"",ROUND(MAX(posicao_contratual!E5-posicao_contratual!J5,0),2)) | AC5: =IF(AND(A5="",A4<>"",COUNTIF(A6:$A$200,"<>")=0),ROUND(SUMIF($A$2:A4,"<>",$AC$2:AC4),2),IF(OR(AB5="",C5="",NOT(ISNUMBER($Z$2))),"",ROUND(AB5*C5*$Z$2,2))) -> 0 | AD5: =IF(A5="","",posicao_contratual!E5) | AE5: =IF(A5="","",posicao_contratual!I5) | AF5: =IF(A5="","",posicao_contratual!M5) | AG5: =IF(A5="","",posicao_contratual!Q5) | AH5: =IF(A5="","",posicao_contratual!U5) | AI5: =IF(A5="","",posicao_contratual!G5) | AJ5: =IF(A5="","",posicao_contratual!K5) | AK5: =IF(A5="","",posicao_contratual!O5) | AL5: =IF(A5="","",posicao_contratual!S5) | AM5: =IF(A5="","",posicao_contratual!W5) | AN5: =IF(A5="","",posicao_contratual!X5)
D6: =IF(AND(A6="",A5<>"",COUNTIF(A7:$A$200,"<>")=0),ROUND(SUMIF($A$2:A5,"<>",$D$2:D5),2),IF(OR(A6="",B6="",C6=""),"",ROUND(B6*C6,2))) | F6: =IF(AND(A6="",A5<>"",COUNTIF(A7:$A$200,"<>")=0),ROUND(SUMIF($A$2:A5,"<>",$F$2:F5),2),IF(OR(A6="",posicao_contratual!K6="",C6="",NOT(ISNUMBER($Z$3))),"",ROUND(posicao_contratual!K6*C6*$Z$3,2))) | H6: =IF(AND(A6="",A5<>"",COUNTIF(A7:$A$200,"<>")=0),ROUND(SUMIF($A$2:A5,"<>",$H$2:H5),2),IF(OR(A6="",posicao_contratual!O6="",C6="",NOT(ISNUMBER($Z$4))),"",ROUND(posicao_contratual!O6*C6*$Z$4,2))) | J6: =IF(AND(A6="",A5<>"",COUNTIF(A7:$A$200,"<>")=0),ROUND(SUMIF($A$2:A5,"<>",$J$2:J5),2),IF(OR(A6="",posicao_contratual!S6="",C6="",NOT(ISNUMBER($Z$5))),"",ROUND(posicao_contratual!S6*C6*$Z$5,2))) | L6: =IF(AND(A6="",A5<>"",COUNTIF(A7:$A$200,"<>")=0),ROUND(SUMIF($A$2:A5,"<>",$L$2:L5),2),IF(OR(A6="",posicao_contratual!W6="",C6="",NOT(ISNUMBER($Z$6))),"",ROUND(posicao_contratual!W6*C6*$Z$6,2))) | M6: =IF(OR(posicao_contratual!J6="",posicao_contratual!N6=""),"",ROUND(MAX(posicao_contratual!J6+posicao_contratual!H6-posicao_contratual!N6,0),2)) | N6: =IF(AND(A6="",A5<>"",COUNTIF(A7:$A$200,"<>")=0),ROUND(SUMIF($A$2:A5,"<>",$N$2:N5),2),IF(OR(M6="",C6="",NOT(ISNUMBER($Z$3))),"",ROUND(M6*C6*$Z$3,2))) | O6: =IF(OR(posicao_contratual!N6="",posicao_contratual!R6=""),"",ROUND(MAX(posicao_contratual!N6+posicao_contratual!L6-posicao_contratual!R6,0),2)) | P6: =IF(AND(A6="",A5<>"",COUNTIF(A7:$A$200,"<>")=0),ROUND(SUMIF($A$2:A5,"<>",$P$2:P5),2),IF(OR(O6="",C6="",NOT(ISNUMBER($Z$4))),"",ROUND(O6*C6*$Z$4,2))) | Q6: =IF(OR(posicao_contratual!R6="",posicao_contratual!V6=""),"",ROUND(MAX(posicao_contratual!R6+posicao_contratual!P6-posicao_contratual!V6,0),2)) | R6: =IF(AND(A6="",A5<>"",COUNTIF(A7:$A$200,"<>")=0),ROUND(SUMIF($A$2:A5,"<>",$R$2:R5),2),IF(OR(Q6="",C6="",NOT(ISNUMBER($Z$5))),"",ROUND(Q6*C6*$Z$5,2))) | U6: =IF(AND(A6="",A5<>"",COUNTIF(A7:$A$200,"<>")=0),"TOTAL",IF(A6="","",posicao_contratual!X6)) | V6: =IF(A6="","",posicao_contratual!X6) | W6: C4 | X6: =parametros!$A$6 -> Nao | Y6: =IF(ISNUMBER(parametros!$E$6),parametros!$E$6,"") | Z6: =IF(ISNUMBER(parametros!$F$6),parametros!$F$6,"") | AB6: =IF(OR(A6="",posicao_contratual!E6="",posicao_contratual!J6=""),"",ROUND(MAX(posicao_contratual!E6-posicao_contratual!J6,0),2)) | AC6: =IF(AND(A6="",A5<>"",COUNTIF(A7:$A$200,"<>")=0),ROUND(SUMIF($A$2:A5,"<>",$AC$2:AC5),2),IF(OR(AB6="",C6="",NOT(ISNUMBER($Z$2))),"",ROUND(AB6*C6*$Z$2,2))) | AD6: =IF(A6="","",posicao_contratual!E6) | AE6: =IF(A6="","",posicao_contratual!I6) | AF6: =IF(A6="","",posicao_contratual!M6) | AG6: =IF(A6="","",posicao_contratual!Q6) | AH6: =IF(A6="","",posicao_contratual!U6) | AI6: =IF(A6="","",posicao_contratual!G6) | AJ6: =IF(A6="","",posicao_contratual!K6) | AK6: =IF(A6="","",posicao_contratual!O6) | AL6: =IF(A6="","",posicao_contratual!S6) | AM6: =IF(A6="","",posicao_contratual!W6) | AN6: =IF(A6="","",posicao_contratual!X6)
D7: =IF(AND(A7="",A6<>"",COUNTIF(A8:$A$200,"<>")=0),ROUND(SUMIF($A$2:A6,"<>",$D$2:D6),2),IF(OR(A7="",B7="",C7=""),"",ROUND(B7*C7,2))) | F7: =IF(AND(A7="",A6<>"",COUNTIF(A8:$A$200,"<>")=0),ROUND(SUMIF($A$2:A6,"<>",$F$2:F6),2),IF(OR(A7="",posicao_contratual!K7="",C7="",NOT(ISNUMBER($Z$3))),"",ROUND(posicao_contratual!K7*C7*$Z$3,2))) | H7: =IF(AND(A7="",A6<>"",COUNTIF(A8:$A$200,"<>")=0),ROUND(SUMIF($A$2:A6,"<>",$H$2:H6),2),IF(OR(A7="",posicao_contratual!O7="",C7="",NOT(ISNUMBER($Z$4))),"",ROUND(posicao_contratual!O7*C7*$Z$4,2))) | J7: =IF(AND(A7="",A6<>"",COUNTIF(A8:$A$200,"<>")=0),ROUND(SUMIF($A$2:A6,"<>",$J$2:J6),2),IF(OR(A7="",posicao_contratual!S7="",C7="",NOT(ISNUMBER($Z$5))),"",ROUND(posicao_contratual!S7*C7*$Z$5,2))) | L7: =IF(AND(A7="",A6<>"",COUNTIF(A8:$A$200,"<>")=0),ROUND(SUMIF($A$2:A6,"<>",$L$2:L6),2),IF(OR(A7="",posicao_contratual!W7="",C7="",NOT(ISNUMBER($Z$6))),"",ROUND(posicao_contratual!W7*C7*$Z$6,2))) | M7: =IF(OR(posicao_contratual!J7="",posicao_contratual!N7=""),"",ROUND(MAX(posicao_contratual!J7+posicao_contratual!H7-posicao_contratual!N7,0),2)) | N7: =IF(AND(A7="",A6<>"",COUNTIF(A8:$A$200,"<>")=0),ROUND(SUMIF($A$2:A6,"<>",$N$2:N6),2),IF(OR(M7="",C7="",NOT(ISNUMBER($Z$3))),"",ROUND(M7*C7*$Z$3,2))) | O7: =IF(OR(posicao_contratual!N7="",posicao_contratual!R7=""),"",ROUND(MAX(posicao_contratual!N7+posicao_contratual!L7-posicao_contratual!R7,0),2)) | P7: =IF(AND(A7="",A6<>"",COUNTIF(A8:$A$200,"<>")=0),ROUND(SUMIF($A$2:A6,"<>",$P$2:P6),2),IF(OR(O7="",C7="",NOT(ISNUMBER($Z$4))),"",ROUND(O7*C7*$Z$4,2))) | Q7: =IF(OR(posicao_contratual!R7="",posicao_contratual!V7=""),"",ROUND(MAX(posicao_contratual!R7+posicao_contratual!P7-posicao_contratual!V7,0),2)) | R7: =IF(AND(A7="",A6<>"",COUNTIF(A8:$A$200,"<>")=0),ROUND(SUMIF($A$2:A6,"<>",$R$2:R6),2),IF(OR(Q7="",C7="",NOT(ISNUMBER($Z$5))),"",ROUND(Q7*C7*$Z$5,2))) | U7: =IF(AND(A7="",A6<>"",COUNTIF(A8:$A$200,"<>")=0),"TOTAL",IF(A7="","",posicao_contratual!X7)) | V7: =IF(A7="","",posicao_contratual!X7) | AB7: =IF(OR(A7="",posicao_contratual!E7="",posicao_contratual!J7=""),"",ROUND(MAX(posicao_contratual!E7-posicao_contratual!J7,0),2)) | AC7: =IF(AND(A7="",A6<>"",COUNTIF(A8:$A$200,"<>")=0),ROUND(SUMIF($A$2:A6,"<>",$AC$2:AC6),2),IF(OR(AB7="",C7="",NOT(ISNUMBER($Z$2))),"",ROUND(AB7*C7*$Z$2,2))) | AD7: =IF(A7="","",posicao_contratual!E7) | AE7: =IF(A7="","",posicao_contratual!I7) | AF7: =IF(A7="","",posicao_contratual!M7) | AG7: =IF(A7="","",posicao_contratual!Q7) | AH7: =IF(A7="","",posicao_contratual!U7) | AI7: =IF(A7="","",posicao_contratual!G7) | AJ7: =IF(A7="","",posicao_contratual!K7) | AK7: =IF(A7="","",posicao_contratual!O7) | AL7: =IF(A7="","",posicao_contratual!S7) | AM7: =IF(A7="","",posicao_contratual!W7) | AN7: =IF(A7="","",posicao_contratual!X7)
D8: =IF(AND(A8="",A7<>"",COUNTIF(A9:$A$200,"<>")=0),ROUND(SUMIF($A$2:A7,"<>",$D$2:D7),2),IF(OR(A8="",B8="",C8=""),"",ROUND(B8*C8,2))) | F8: =IF(AND(A8="",A7<>"",COUNTIF(A9:$A$200,"<>")=0),ROUND(SUMIF($A$2:A7,"<>",$F$2:F7),2),IF(OR(A8="",posicao_contratual!K8="",C8="",NOT(ISNUMBER($Z$3))),"",ROUND(posicao_contratual!K8*C8*$Z$3,2))) | H8: =IF(AND(A8="",A7<>"",COUNTIF(A9:$A$200,"<>")=0),ROUND(SUMIF($A$2:A7,"<>",$H$2:H7),2),IF(OR(A8="",posicao_contratual!O8="",C8="",NOT(ISNUMBER($Z$4))),"",ROUND(posicao_contratual!O8*C8*$Z$4,2))) | J8: =IF(AND(A8="",A7<>"",COUNTIF(A9:$A$200,"<>")=0),ROUND(SUMIF($A$2:A7,"<>",$J$2:J7),2),IF(OR(A8="",posicao_contratual!S8="",C8="",NOT(ISNUMBER($Z$5))),"",ROUND(posicao_contratual!S8*C8*$Z$5,2))) | L8: =IF(AND(A8="",A7<>"",COUNTIF(A9:$A$200,"<>")=0),ROUND(SUMIF($A$2:A7,"<>",$L$2:L7),2),IF(OR(A8="",posicao_contratual!W8="",C8="",NOT(ISNUMBER($Z$6))),"",ROUND(posicao_contratual!W8*C8*$Z$6,2))) | M8: =IF(OR(posicao_contratual!J8="",posicao_contratual!N8=""),"",ROUND(MAX(posicao_contratual!J8+posicao_contratual!H8-posicao_contratual!N8,0),2)) | N8: =IF(AND(A8="",A7<>"",COUNTIF(A9:$A$200,"<>")=0),ROUND(SUMIF($A$2:A7,"<>",$N$2:N7),2),IF(OR(M8="",C8="",NOT(ISNUMBER($Z$3))),"",ROUND(M8*C8*$Z$3,2))) | O8: =IF(OR(posicao_contratual!N8="",posicao_contratual!R8=""),"",ROUND(MAX(posicao_contratual!N8+posicao_contratual!L8-posicao_contratual!R8,0),2)) | P8: =IF(AND(A8="",A7<>"",COUNTIF(A9:$A$200,"<>")=0),ROUND(SUMIF($A$2:A7,"<>",$P$2:P7),2),IF(OR(O8="",C8="",NOT(ISNUMBER($Z$4))),"",ROUND(O8*C8*$Z$4,2))) | Q8: =IF(OR(posicao_contratual!R8="",posicao_contratual!V8=""),"",ROUND(MAX(posicao_contratual!R8+posicao_contratual!P8-posicao_contratual!V8,0),2)) | R8: =IF(AND(A8="",A7<>"",COUNTIF(A9:$A$200,"<>")=0),ROUND(SUMIF($A$2:A7,"<>",$R$2:R7),2),IF(OR(Q8="",C8="",NOT(ISNUMBER($Z$5))),"",ROUND(Q8*C8*$Z$5,2))) | U8: =IF(AND(A8="",A7<>"",COUNTIF(A9:$A$200,"<>")=0),"TOTAL",IF(A8="","",posicao_contratual!X8)) | V8: =IF(A8="","",posicao_contratual!X8) | AB8: =IF(OR(A8="",posicao_contratual!E8="",posicao_contratual!J8=""),"",ROUND(MAX(posicao_contratual!E8-posicao_contratual!J8,0),2)) | AC8: =IF(AND(A8="",A7<>"",COUNTIF(A9:$A$200,"<>")=0),ROUND(SUMIF($A$2:A7,"<>",$AC$2:AC7),2),IF(OR(AB8="",C8="",NOT(ISNUMBER($Z$2))),"",ROUND(AB8*C8*$Z$2,2))) | AD8: =IF(A8="","",posicao_contratual!E8) | AE8: =IF(A8="","",posicao_contratual!I8) | AF8: =IF(A8="","",posicao_contratual!M8) | AG8: =IF(A8="","",posicao_contratual!Q8) | AH8: =IF(A8="","",posicao_contratual!U8) | AI8: =IF(A8="","",posicao_contratual!G8) | AJ8: =IF(A8="","",posicao_contratual!K8) | AK8: =IF(A8="","",posicao_contratual!O8) | AL8: =IF(A8="","",posicao_contratual!S8) | AM8: =IF(A8="","",posicao_contratual!W8) | AN8: =IF(A8="","",posicao_contratual!X8)
D9: =IF(AND(A9="",A8<>"",COUNTIF(A10:$A$200,"<>")=0),ROUND(SUMIF($A$2:A8,"<>",$D$2:D8),2),IF(OR(A9="",B9="",C9=""),"",ROUND(B9*C9,2))) | F9: =IF(AND(A9="",A8<>"",COUNTIF(A10:$A$200,"<>")=0),ROUND(SUMIF($A$2:A8,"<>",$F$2:F8),2),IF(OR(A9="",posicao_contratual!K9="",C9="",NOT(ISNUMBER($Z$3))),"",ROUND(posicao_contratual!K9*C9*$Z$3,2))) | H9: =IF(AND(A9="",A8<>"",COUNTIF(A10:$A$200,"<>")=0),ROUND(SUMIF($A$2:A8,"<>",$H$2:H8),2),IF(OR(A9="",posicao_contratual!O9="",C9="",NOT(ISNUMBER($Z$4))),"",ROUND(posicao_contratual!O9*C9*$Z$4,2))) | J9: =IF(AND(A9="",A8<>"",COUNTIF(A10:$A$200,"<>")=0),ROUND(SUMIF($A$2:A8,"<>",$J$2:J8),2),IF(OR(A9="",posicao_contratual!S9="",C9="",NOT(ISNUMBER($Z$5))),"",ROUND(posicao_contratual!S9*C9*$Z$5,2))) | L9: =IF(AND(A9="",A8<>"",COUNTIF(A10:$A$200,"<>")=0),ROUND(SUMIF($A$2:A8,"<>",$L$2:L8),2),IF(OR(A9="",posicao_contratual!W9="",C9="",NOT(ISNUMBER($Z$6))),"",ROUND(posicao_contratual!W9*C9*$Z$6,2))) | M9: =IF(OR(posicao_contratual!J9="",posicao_contratual!N9=""),"",ROUND(MAX(posicao_contratual!J9+posicao_contratual!H9-posicao_contratual!N9,0),2)) | N9: =IF(AND(A9="",A8<>"",COUNTIF(A10:$A$200,"<>")=0),ROUND(SUMIF($A$2:A8,"<>",$N$2:N8),2),IF(OR(M9="",C9="",NOT(ISNUMBER($Z$3))),"",ROUND(M9*C9*$Z$3,2))) | O9: =IF(OR(posicao_contratual!N9="",posicao_contratual!R9=""),"",ROUND(MAX(posicao_contratual!N9+posicao_contratual!L9-posicao_contratual!R9,0),2)) | P9: =IF(AND(A9="",A8<>"",COUNTIF(A10:$A$200,"<>")=0),ROUND(SUMIF($A$2:A8,"<>",$P$2:P8),2),IF(OR(O9="",C9="",NOT(ISNUMBER($Z$4))),"",ROUND(O9*C9*$Z$4,2))) | Q9: =IF(OR(posicao_contratual!R9="",posicao_contratual!V9=""),"",ROUND(MAX(posicao_contratual!R9+posicao_contratual!P9-posicao_contratual!V9,0),2)) | R9: =IF(AND(A9="",A8<>"",COUNTIF(A10:$A$200,"<>")=0),ROUND(SUMIF($A$2:A8,"<>",$R$2:R8),2),IF(OR(Q9="",C9="",NOT(ISNUMBER($Z$5))),"",ROUND(Q9*C9*$Z$5,2))) | U9: =IF(AND(A9="",A8<>"",COUNTIF(A10:$A$200,"<>")=0),"TOTAL",IF(A9="","",posicao_contratual!X9)) | V9: =IF(A9="","",posicao_contratual!X9) | AB9: =IF(OR(A9="",posicao_contratual!E9="",posicao_contratual!J9=""),"",ROUND(MAX(posicao_contratual!E9-posicao_contratual!J9,0),2)) | AC9: =IF(AND(A9="",A8<>"",COUNTIF(A10:$A$200,"<>")=0),ROUND(SUMIF($A$2:A8,"<>",$AC$2:AC8),2),IF(OR(AB9="",C9="",NOT(ISNUMBER($Z$2))),"",ROUND(AB9*C9*$Z$2,2))) | AD9: =IF(A9="","",posicao_contratual!E9) | AE9: =IF(A9="","",posicao_contratual!I9) | AF9: =IF(A9="","",posicao_contratual!M9) | AG9: =IF(A9="","",posicao_contratual!Q9) | AH9: =IF(A9="","",posicao_contratual!U9) | AI9: =IF(A9="","",posicao_contratual!G9) | AJ9: =IF(A9="","",posicao_contratual!K9) | AK9: =IF(A9="","",posicao_contratual!O9) | AL9: =IF(A9="","",posicao_contratual!S9) | AM9: =IF(A9="","",posicao_contratual!W9) | AN9: =IF(A9="","",posicao_contratual!X9)
