Workbook

Sheet CONTROLE
A1: MODO DE LEITURA | B1: Principal | C1: Principal = pago + remanescente | D = consumo por ciclo
A2: Ciclo vigente (em execução) | B2: C0
A3: Data de corte (única p/ contrato)
A4: C0 e ciclos fora da analise | B4: Preencher FINANCEIRO: coluna B com o nome do ciclo (ex: c0, c1), coluna C com o valor efetivamente pago. Se vazio, o sistema usa calculo por itens/estoque.
A6: RESUMO DO REAJUSTE | B6: VALOR
A7: Índice utilizado
A8: Data-base original
A9: Quantidade de ciclos desta análise | B9: =COUNTIF(parametros!A2:A6,"Sim")
A10: Variação acumulada final | B10: =IFERROR(IF(ISNUMBER(parametros!G6),parametros!G6-1,IF(ISNUMBER(parametros!G5),parametros!G5-1,IF(ISNUMBER(parametros!G4),parametros!G4-1,IF(ISNUMBER(parametros!G3),parametros!G3-1,IF(ISNUMBER(parametros!G2),parametros!G2-1,""))))),"")
A11: Fator acumulado total | B11: =IFERROR(IF(ISNUMBER(parametros!G6),parametros!G6,IF(ISNUMBER(parametros!G5),parametros!G5,IF(ISNUMBER(parametros!G4),parametros!G4,IF(ISNUMBER(parametros!G3),parametros!G3,IF(ISNUMBER(parametros!G2),parametros!G2,""))))),"")
A12: Último ciclo considerado nesta apuração | B12: =IFERROR(IF(parametros!A6="Sim",parametros!B6,IF(parametros!A5="Sim",parametros!B5,IF(parametros!A4="Sim",parametros!B4,IF(parametros!A3="Sim",parametros!B3,IF(parametros!A2="Sim",parametros!B2,"Nenhum"))))),"Nenhum")
A13: Início do último ciclo considerado | B13: =IFERROR(IF(parametros!A6="Sim",parametros!D6,IF(parametros!A5="Sim",parametros!D5,IF(parametros!A4="Sim",parametros!D4,IF(parametros!A3="Sim",parametros!D3,IF(parametros!A2="Sim",parametros!D2,""))))),"")
A14: Data de geracao do arquivo | B14: =NOW()

Sheet parametros
A1: COMPUTAR_NESTA_APURACAO | B1: CICLO | C1: PERIODO_DO_CICLO | D1: DATA_INICIO | E1: DATA_FIM | F1: PERCENTUAL_DO_CICLO | G1: FATOR_ACUMULADO | H1: SITUACAO
A2: Nao | B2: C0 | F2: 0 | G2: =1 | H2: Base
A3: Nao | B3: C1 | G3: =IF(F3="","",IF(NOT(ISNUMBER(F3)),"",IF(NOT(ISNUMBER(G2)),"",G2*(1+F3)))) | H3: Fora desta apuracao
A4: Nao | B4: C2 | G4: =IF(F4="","",IF(NOT(ISNUMBER(F4)),"",IF(NOT(ISNUMBER(G3)),"",G3*(1+F4)))) | H4: Fora desta apuracao
A5: Nao | B5: C3 | G5: =IF(F5="","",IF(NOT(ISNUMBER(F5)),"",IF(NOT(ISNUMBER(G4)),"",G4*(1+F5)))) | H5: Fora desta apuracao
A6: Nao | B6: C4 | G6: =IF(F6="","",IF(NOT(ISNUMBER(F6)),"",IF(NOT(ISNUMBER(G5)),"",G5*(1+F6)))) | H6: Fora desta apuracao
A9: MEMORIA DO FATOR APLICAVEL A APURACAO
A10: CICLO | B10: COMPUTA? | C10: PERCENTUAL | D10: FATOR | E10: FATOR_ACUMULADO_APURACAO | F10: STATUS
A11: C0 | B11: =A2 | C11: =IF(B11="Sim",F2,"") | D11: =1 | E11: =1 | F11: Base
A12: C1 | B12: =A3 | C12: =IF(B12="Sim",F3,"") | D12: =IF(C12="","",1+C12) | E12: =IF(B12="Sim",E11*D12,E11) | F12: =IF(B12="Sim","Aplicado","Fora da apuracao")
A13: C2 | B13: =A4 | C13: =IF(B13="Sim",F4,"") | D13: =IF(C13="","",1+C13) | E13: =IF(B13="Sim",E12*D13,E12) | F13: =IF(B13="Sim","Aplicado","Fora da apuracao")
A14: C3 | B14: =A5 | C14: =IF(B14="Sim",F5,"") | D14: =IF(C14="","",1+C14) | E14: =IF(B14="Sim",E13*D14,E13) | F14: =IF(B14="Sim","Aplicado","Fora da apuracao")
A15: C4 | B15: =A6 | C15: =IF(B15="Sim",F6,"") | D15: =IF(C15="","",1+C15) | E15: =IF(B15="Sim",E14*D15,E14) | F15: =IF(B15="Sim","Aplicado","Fora da apuracao")
A16: TOTAL APURACAO | E16: =E15 | F16: =E16-1

Sheet financeiro
A1: COMPETENCIA | B1: CICLO | C1: VALOR_PAGO | D1: FATOR_APLICAVEL | E1: VALOR_ATUALIZADO | F1: DELTA | G1: EFEITO_FINANCEIRO
D2: =IF(B2="","",IF(B2="c0",1,IF(B2="c1",IF(parametros!$A$3<>"Sim","",IF(NOT(ISNUMBER(parametros!$F$3)),"",1+parametros!$F$3)),IF(B2="c2",IF(parametros!$A$4<>"Sim","",IF(NOT(ISNUMBER(parametros!$F$4)),"",IF(parametros!$A$3="Sim",1+parametros!$F$3,1)*(1+parametros!$F$4))),IF(B2="c3",IF(parametros!$A$5<>"Sim","",IF(NOT(ISNUMBER(parametros!$F$5)),"",IF(parametros!$A$3="Sim",1+parametros!$F$3,1)*IF(parametros!$A$4="Sim",1+parametros!$F$4,1)*(1+parametros!$F$5))),IF(B2="c4",IF(parametros!$A$6<>"Sim","",IF(NOT(ISNUMBER(parametros!$F$6)),"",IF(parametros!$A$3="Sim",1+parametros!$F$3,1)*IF(parametros!$A$4="Sim",1+parametros!$F$4,1)*IF(parametros!$A$5="Sim",1+parametros!$F$5,1)*(1+parametros!$F$6))),"")))))) | E2: =IF(OR(C2="",NOT(ISNUMBER(D2))),"",ROUND(C2*D2,2)) | F2: =IF(OR(C2="",E2=""),"",IF(G2<>"Sim",0,ROUND(E2-C2,2)))
D3: =IF(B3="","",IF(B3="c0",1,IF(B3="c1",IF(parametros!$A$3<>"Sim","",IF(NOT(ISNUMBER(parametros!$F$3)),"",1+parametros!$F$3)),IF(B3="c2",IF(parametros!$A$4<>"Sim","",IF(NOT(ISNUMBER(parametros!$F$4)),"",IF(parametros!$A$3="Sim",1+parametros!$F$3,1)*(1+parametros!$F$4))),IF(B3="c3",IF(parametros!$A$5<>"Sim","",IF(NOT(ISNUMBER(parametros!$F$5)),"",IF(parametros!$A$3="Sim",1+parametros!$F$3,1)*IF(parametros!$A$4="Sim",1+parametros!$F$4,1)*(1+parametros!$F$5))),IF(B3="c4",IF(parametros!$A$6<>"Sim","",IF(NOT(ISNUMBER(parametros!$F$6)),"",IF(parametros!$A$3="Sim",1+parametros!$F$3,1)*IF(parametros!$A$4="Sim",1+parametros!$F$4,1)*IF(parametros!$A$5="Sim",1+parametros!$F$5,1)*(1+parametros!$F$6))),"")))))) | E3: =IF(OR(C3="",NOT(ISNUMBER(D3))),"",ROUND(C3*D3,2)) | F3: =IF(OR(C3="",E3=""),"",IF(G3<>"Sim",0,ROUND(E3-C3,2)))
D4: =IF(B4="","",IF(B4="c0",1,IF(B4="c1",IF(parametros!$A$3<>"Sim","",IF(NOT(ISNUMBER(parametros!$F$3)),"",1+parametros!$F$3)),IF(B4="c2",IF(parametros!$A$4<>"Sim","",IF(NOT(ISNUMBER(parametros!$F$4)),"",IF(parametros!$A$3="Sim",1+parametros!$F$3,1)*(1+parametros!$F$4))),IF(B4="c3",IF(parametros!$A$5<>"Sim","",IF(NOT(ISNUMBER(parametros!$F$5)),"",IF(parametros!$A$3="Sim",1+parametros!$F$3,1)*IF(parametros!$A$4="Sim",1+parametros!$F$4,1)*(1+parametros!$F$5))),IF(B4="c4",IF(parametros!$A$6<>"Sim","",IF(NOT(ISNUMBER(parametros!$F$6)),"",IF(parametros!$A$3="Sim",1+parametros!$F$3,1)*IF(parametros!$A$4="Sim",1+parametros!$F$4,1)*IF(parametros!$A$5="Sim",1+parametros!$F$5,1)*(1+parametros!$F$6))),"")))))) | E4: =IF(OR(C4="",NOT(ISNUMBER(D4))),"",ROUND(C4*D4,2)) | F4: =IF(OR(C4="",E4=""),"",IF(G4<>"Sim",0,ROUND(E4-C4,2)))
D5: =IF(B5="","",IF(B5="c0",1,IF(B5="c1",IF(parametros!$A$3<>"Sim","",IF(NOT(ISNUMBER(parametros!$F$3)),"",1+parametros!$F$3)),IF(B5="c2",IF(parametros!$A$4<>"Sim","",IF(NOT(ISNUMBER(parametros!$F$4)),"",IF(parametros!$A$3="Sim",1+parametros!$F$3,1)*(1+parametros!$F$4))),IF(B5="c3",IF(parametros!$A$5<>"Sim","",IF(NOT(ISNUMBER(parametros!$F$5)),"",IF(parametros!$A$3="Sim",1+parametros!$F$3,1)*IF(parametros!$A$4="Sim",1+parametros!$F$4,1)*(1+parametros!$F$5))),IF(B5="c4",IF(parametros!$A$6<>"Sim","",IF(NOT(ISNUMBER(parametros!$F$6)),"",IF(parametros!$A$3="Sim",1+parametros!$F$3,1)*IF(parametros!$A$4="Sim",1+parametros!$F$4,1)*IF(parametros!$A$5="Sim",1+parametros!$F$5,1)*(1+parametros!$F$6))),"")))))) | E5: =IF(OR(C5="",NOT(ISNUMBER(D5))),"",ROUND(C5*D5,2)) | F5: =IF(OR(C5="",E5=""),"",IF(G5<>"Sim",0,ROUND(E5-C5,2)))
D6: =IF(B6="","",IF(B6="c0",1,IF(B6="c1",IF(parametros!$A$3<>"Sim","",IF(NOT(ISNUMBER(parametros!$F$3)),"",1+parametros!$F$3)),IF(B6="c2",IF(parametros!$A$4<>"Sim","",IF(NOT(ISNUMBER(parametros!$F$4)),"",IF(parametros!$A$3="Sim",1+parametros!$F$3,1)*(1+parametros!$F$4))),IF(B6="c3",IF(parametros!$A$5<>"Sim","",IF(NOT(ISNUMBER(parametros!$F$5)),"",IF(parametros!$A$3="Sim",1+parametros!$F$3,1)*IF(parametros!$A$4="Sim",1+parametros!$F$4,1)*(1+parametros!$F$5))),IF(B6="c4",IF(parametros!$A$6<>"Sim","",IF(NOT(ISNUMBER(parametros!$F$6)),"",IF(parametros!$A$3="Sim",1+parametros!$F$3,1)*IF(parametros!$A$4="Sim",1+parametros!$F$4,1)*IF(parametros!$A$5="Sim",1+parametros!$F$5,1)*(1+parametros!$F$6))),"")))))) | E6: =IF(OR(C6="",NOT(ISNUMBER(D6))),"",ROUND(C6*D6,2)) | F6: =IF(OR(C6="",E6=""),"",IF(G6<>"Sim",0,ROUND(E6-C6,2)))
D7: =IF(B7="","",IF(B7="c0",1,IF(B7="c1",IF(parametros!$A$3<>"Sim","",IF(NOT(ISNUMBER(parametros!$F$3)),"",1+parametros!$F$3)),IF(B7="c2",IF(parametros!$A$4<>"Sim","",IF(NOT(ISNUMBER(parametros!$F$4)),"",IF(parametros!$A$3="Sim",1+parametros!$F$3,1)*(1+parametros!$F$4))),IF(B7="c3",IF(parametros!$A$5<>"Sim","",IF(NOT(ISNUMBER(parametros!$F$5)),"",IF(parametros!$A$3="Sim",1+parametros!$F$3,1)*IF(parametros!$A$4="Sim",1+parametros!$F$4,1)*(1+parametros!$F$5))),IF(B7="c4",IF(parametros!$A$6<>"Sim","",IF(NOT(ISNUMBER(parametros!$F$6)),"",IF(parametros!$A$3="Sim",1+parametros!$F$3,1)*IF(parametros!$A$4="Sim",1+parametros!$F$4,1)*IF(parametros!$A$5="Sim",1+parametros!$F$5,1)*(1+parametros!$F$6))),"")))))) | E7: =IF(OR(C7="",NOT(ISNUMBER(D7))),"",ROUND(C7*D7,2)) | F7: =IF(OR(C7="",E7=""),"",IF(G7<>"Sim",0,ROUND(E7-C7,2)))
D8: =IF(B8="","",IF(B8="c0",1,IF(B8="c1",IF(parametros!$A$3<>"Sim","",IF(NOT(ISNUMBER(parametros!$F$3)),"",1+parametros!$F$3)),IF(B8="c2",IF(parametros!$A$4<>"Sim","",IF(NOT(ISNUMBER(parametros!$F$4)),"",IF(parametros!$A$3="Sim",1+parametros!$F$3,1)*(1+parametros!$F$4))),IF(B8="c3",IF(parametros!$A$5<>"Sim","",IF(NOT(ISNUMBER(parametros!$F$5)),"",IF(parametros!$A$3="Sim",1+parametros!$F$3,1)*IF(parametros!$A$4="Sim",1+parametros!$F$4,1)*(1+parametros!$F$5))),IF(B8="c4",IF(parametros!$A$6<>"Sim","",IF(NOT(ISNUMBER(parametros!$F$6)),"",IF(parametros!$A$3="Sim",1+parametros!$F$3,1)*IF(parametros!$A$4="Sim",1+parametros!$F$4,1)*IF(parametros!$A$5="Sim",1+parametros!$F$5,1)*(1+parametros!$F$6))),"")))))) | E8: =IF(OR(C8="",NOT(ISNUMBER(D8))),"",ROUND(C8*D8,2)) | F8: =IF(OR(C8="",E8=""),"",IF(G8<>"Sim",0,ROUND(E8-C8,2)))
D9: =IF(B9="","",IF(B9="c0",1,IF(B9="c1",IF(parametros!$A$3<>"Sim","",IF(NOT(ISNUMBER(parametros!$F$3)),"",1+parametros!$F$3)),IF(B9="c2",IF(parametros!$A$4<>"Sim","",IF(NOT(ISNUMBER(parametros!$F$4)),"",IF(parametros!$A$3="Sim",1+parametros!$F$3,1)*(1+parametros!$F$4))),IF(B9="c3",IF(parametros!$A$5<>"Sim","",IF(NOT(ISNUMBER(parametros!$F$5)),"",IF(parametros!$A$3="Sim",1+parametros!$F$3,1)*IF(parametros!$A$4="Sim",1+parametros!$F$4,1)*(1+parametros!$F$5))),IF(B9="c4",IF(parametros!$A$6<>"Sim","",IF(NOT(ISNUMBER(parametros!$F$6)),"",IF(parametros!$A$3="Sim",1+parametros!$F$3,1)*IF(parametros!$A$4="Sim",1+parametros!$F$4,1)*IF(parametros!$A$5="Sim",1+parametros!$F$5,1)*(1+parametros!$F$6))),"")))))) | E9: =IF(OR(C9="",NOT(ISNUMBER(D9))),"",ROUND(C9*D9,2)) | F9: =IF(OR(C9="",E9=""),"",IF(G9<>"Sim",0,ROUND(E9-C9,2)))
D10: =IF(B10="","",IF(B10="c0",1,IF(B10="c1",IF(parametros!$A$3<>"Sim","",IF(NOT(ISNUMBER(parametros!$F$3)),"",1+parametros!$F$3)),IF(B10="c2",IF(parametros!$A$4<>"Sim","",IF(NOT(ISNUMBER(parametros!$F$4)),"",IF(parametros!$A$3="Sim",1+parametros!$F$3,1)*(1+parametros!$F$4))),IF(B10="c3",IF(parametros!$A$5<>"Sim","",IF(NOT(ISNUMBER(parametros!$F$5)),"",IF(parametros!$A$3="Sim",1+parametros!$F$3,1)*IF(parametros!$A$4="Sim",1+parametros!$F$4,1)*(1+parametros!$F$5))),IF(B10="c4",IF(parametros!$A$6<>"Sim","",IF(NOT(ISNUMBER(parametros!$F$6)),"",IF(parametros!$A$3="Sim",1+parametros!$F$3,1)*IF(parametros!$A$4="Sim",1+parametros!$F$4,1)*IF(parametros!$A$5="Sim",1+parametros!$F$5,1)*(1+parametros!$F$6))),"")))))) | E10: =IF(OR(C10="",NOT(ISNUMBER(D10))),"",ROUND(C10*D10,2)) | F10: =IF(OR(C10="",E10=""),"",IF(G10<>"Sim",0,ROUND(E10-C10,2)))
D11: =IF(B11="","",IF(B11="c0",1,IF(B11="c1",IF(parametros!$A$3<>"Sim","",IF(NOT(ISNUMBER(parametros!$F$3)),"",1+parametros!$F$3)),IF(B11="c2",IF(parametros!$A$4<>"Sim","",IF(NOT(ISNUMBER(parametros!$F$4)),"",IF(parametros!$A$3="Sim",1+parametros!$F$3,1)*(1+parametros!$F$4))),IF(B11="c3",IF(parametros!$A$5<>"Sim","",IF(NOT(ISNUMBER(parametros!$F$5)),"",IF(parametros!$A$3="Sim",1+parametros!$F$3,1)*IF(parametros!$A$4="Sim",1+parametros!$F$4,1)*(1+parametros!$F$5))),IF(B11="c4",IF(parametros!$A$6<>"Sim","",IF(NOT(ISNUMBER(parametros!$F$6)),"",IF(parametros!$A$3="Sim",1+parametros!$F$3,1)*IF(parametros!$A$4="Sim",1+parametros!$F$4,1)*IF(parametros!$A$5="Sim",1+parametros!$F$5,1)*(1+parametros!$F$6))),"")))))) | E11: =IF(OR(C11="",NOT(ISNUMBER(D11))),"",ROUND(C11*D11,2)) | F11: =IF(OR(C11="",E11=""),"",IF(G11<>"Sim",0,ROUND(E11-C11,2)))
D12: =IF(B12="","",IF(B12="c0",1,IF(B12="c1",IF(parametros!$A$3<>"Sim","",IF(NOT(ISNUMBER(parametros!$F$3)),"",1+parametros!$F$3)),IF(B12="c2",IF(parametros!$A$4<>"Sim","",IF(NOT(ISNUMBER(parametros!$F$4)),"",IF(parametros!$A$3="Sim",1+parametros!$F$3,1)*(1+parametros!$F$4))),IF(B12="c3",IF(parametros!$A$5<>"Sim","",IF(NOT(ISNUMBER(parametros!$F$5)),"",IF(parametros!$A$3="Sim",1+parametros!$F$3,1)*IF(parametros!$A$4="Sim",1+parametros!$F$4,1)*(1+parametros!$F$5))),IF(B12="c4",IF(parametros!$A$6<>"Sim","",IF(NOT(ISNUMBER(parametros!$F$6)),"",IF(parametros!$A$3="Sim",1+parametros!$F$3,1)*IF(parametros!$A$4="Sim",1+parametros!$F$4,1)*IF(parametros!$A$5="Sim",1+parametros!$F$5,1)*(1+parametros!$F$6))),"")))))) | E12: =IF(OR(C12="",NOT(ISNUMBER(D12))),"",ROUND(C12*D12,2)) | F12: =IF(OR(C12="",E12=""),"",IF(G12<>"Sim",0,ROUND(E12-C12,2)))
D13: =IF(B13="","",IF(B13="c0",1,IF(B13="c1",IF(parametros!$A$3<>"Sim","",IF(NOT(ISNUMBER(parametros!$F$3)),"",1+parametros!$F$3)),IF(B13="c2",IF(parametros!$A$4<>"Sim","",IF(NOT(ISNUMBER(parametros!$F$4)),"",IF(parametros!$A$3="Sim",1+parametros!$F$3,1)*(1+parametros!$F$4))),IF(B13="c3",IF(parametros!$A$5<>"Sim","",IF(NOT(ISNUMBER(parametros!$F$5)),"",IF(parametros!$A$3="Sim",1+parametros!$F$3,1)*IF(parametros!$A$4="Sim",1+parametros!$F$4,1)*(1+parametros!$F$5))),IF(B13="c4",IF(parametros!$A$6<>"Sim","",IF(NOT(ISNUMBER(parametros!$F$6)),"",IF(parametros!$A$3="Sim",1+parametros!$F$3,1)*IF(parametros!$A$4="Sim",1+parametros!$F$4,1)*IF(parametros!$A$5="Sim",1+parametros!$F$5,1)*(1+parametros!$F$6))),"")))))) | E13: =IF(OR(C13="",NOT(ISNUMBER(D13))),"",ROUND(C13*D13,2)) | F13: =IF(OR(C13="",E13=""),"",IF(G13<>"Sim",0,ROUND(E13-C13,2)))
... D61: =IF(B61="","",IF(B61="c0",1,IF(B61="c1",IF(parametros!$A$3<>"Sim","",IF(NOT(ISNUMBER(parametros!$F$3)),"",1+parametros!$F$3)),IF(B61="c2",IF(parametros!$A$4<>"Sim","",IF(NOT(ISNUMBER(parametros!$F$4)),"",IF(parametros!$A$3="Sim",1+parametros!$F$3,1)*(1+parametros!$F$4))),IF(B61="c3",IF(parametros!$A$5<>"Sim","",IF(NOT(ISNUMBER(parametros!$F$5)),"",IF(parametros!$A$3="Sim",1+parametros!$F$3,1)*IF(parametros!$A$4="Sim",1+parametros!$F$4,1)*(1+parametros!$F$5))),IF(B61="c4",IF(parametros!$A$6<>"Sim","",IF(NOT(ISNUMBER(parametros!$F$6)),"",IF(parametros!$A$3="Sim",1+parametros!$F$3,1)*IF(parametros!$A$4="Sim",1+parametros!$F$4,1)*IF(parametros!$A$5="Sim",1+parametros!$F$5,1)*(1+parametros!$F$6))),"")))))) | E61: =IF(OR(C61="",NOT(ISNUMBER(D61))),"",ROUND(C61*D61,2)) | F61: =IF(OR(C61="",E61=""),"",IF(G61<>"Sim",0,ROUND(E61-C61,2)))

Sheet itens_Remanesc
A1: ITEM | B1: QTD_CONTRATADA | C1: VU_ORIGINAL | D1: VALOR_TOTAL | E1: =IF(parametros!$D$3="","QTD_REM_INICIO_C1","QTD_REM_INICIO_C1"&CHAR(10)&"Inicio: "&RIGHT("0"&DAY(parametros!$D$3),2)&"/"&RIGHT("0"&MONTH(parametros!$D$3),2)&"/"&YEAR(parametros!$D$3)) | F1: =IF(parametros!$D$3="","VALOR_REM_INICIO_C1","VALOR_REM_INICIO_C1"&CHAR(10)&"Inicio: "&RIGHT("0"&DAY(parametros!$D$3),2)&"/"&RIGHT("0"&MONTH(parametros!$D$3),2)&"/"&YEAR(parametros!$D$3)) | G1: =IF(parametros!$D$4="","QTD_REM_INICIO_C2","QTD_REM_INICIO_C2"&CHAR(10)&"Inicio: "&RIGHT("0"&DAY(parametros!$D$4),2)&"/"&RIGHT("0"&MONTH(parametros!$D$4),2)&"/"&YEAR(parametros!$D$4)) | H1: =IF(parametros!$D$4="","VALOR_REM_INICIO_C2","VALOR_REM_INICIO_C2"&CHAR(10)&"Inicio: "&RIGHT("0"&DAY(parametros!$D$4),2)&"/"&RIGHT("0"&MONTH(parametros!$D$4),2)&"/"&YEAR(parametros!$D$4)) | I1: =IF(parametros!$D$5="","QTD_REM_INICIO_C3","QTD_REM_INICIO_C3"&CHAR(10)&"Inicio: "&RIGHT("0"&DAY(parametros!$D$5),2)&"/"&RIGHT("0"&MONTH(parametros!$D$5),2)&"/"&YEAR(parametros!$D$5)) | J1: =IF(parametros!$D$5="","VALOR_REM_INICIO_C3","VALOR_REM_INICIO_C3"&CHAR(10)&"Inicio: "&RIGHT("0"&DAY(parametros!$D$5),2)&"/"&RIGHT("0"&MONTH(parametros!$D$5),2)&"/"&YEAR(parametros!$D$5)) | K1: =IF(parametros!$D$6="","QTD_REM_INICIO_C4","QTD_REM_INICIO_C4"&CHAR(10)&"Inicio: "&RIGHT("0"&DAY(parametros!$D$6),2)&"/"&RIGHT("0"&MONTH(parametros!$D$6),2)&"/"&YEAR(parametros!$D$6)) | L1: =IF(parametros!$D$6="","VALOR_REM_INICIO_C4","VALOR_REM_INICIO_C4"&CHAR(10)&"Inicio: "&RIGHT("0"&DAY(parametros!$D$6),2)&"/"&RIGHT("0"&MONTH(parametros!$D$6),2)&"/"&YEAR(parametros!$D$6)) | M1: =IF(parametros!$D$3="","QTD_EXECUTADA_C1","QTD_EXECUTADA_C1"&CHAR(10)&"Inicio: "&RIGHT("0"&DAY(parametros!$D$3),2)&"/"&RIGHT("0"&MONTH(parametros!$D$3),2)&"/"&YEAR(parametros!$D$3)) | N1: =IF(parametros!$D$3="","VALOR_EXECUTADO_C1","VALOR_EXECUTADO_C1"&CHAR(10)&"Inicio: "&RIGHT("0"&DAY(parametros!$D$3),2)&"/"&RIGHT("0"&MONTH(parametros!$D$3),2)&"/"&YEAR(parametros!$D$3)) | O1: =IF(parametros!$D$4="","QTD_EXECUTADA_C2","QTD_EXECUTADA_C2"&CHAR(10)&"Inicio: "&RIGHT("0"&DAY(parametros!$D$4),2)&"/"&RIGHT("0"&MONTH(parametros!$D$4),2)&"/"&YEAR(parametros!$D$4)) | P1: =IF(parametros!$D$4="","VALOR_EXECUTADO_C2","VALOR_EXECUTADO_C2"&CHAR(10)&"Inicio: "&RIGHT("0"&DAY(parametros!$D$4),2)&"/"&RIGHT("0"&MONTH(parametros!$D$4),2)&"/"&YEAR(parametros!$D$4)) | Q1: =IF(parametros!$D$5="","QTD_EXECUTADA_C3","QTD_EXECUTADA_C3"&CHAR(10)&"Inicio: "&RIGHT("0"&DAY(parametros!$D$5),2)&"/"&RIGHT("0"&MONTH(parametros!$D$5),2)&"/"&YEAR(parametros!$D$5)) | R1: =IF(parametros!$D$5="","VALOR_EXECUTADO_C3","VALOR_EXECUTADO_C3"&CHAR(10)&"Inicio: "&RIGHT("0"&DAY(parametros!$D$5),2)&"/"&RIGHT("0"&MONTH(parametros!$D$5),2)&"/"&YEAR(parametros!$D$5)) | S1: =IF(parametros!$D$6="","QTD_EXECUTADA_C4","QTD_EXECUTADA_C4"&CHAR(10)&"Inicio: "&RIGHT("0"&DAY(parametros!$D$6),2)&"/"&RIGHT("0"&MONTH(parametros!$D$6),2)&"/"&YEAR(parametros!$D$6)) | T1: =IF(parametros!$D$6="","VALOR_EXECUTADO_C4","VALOR_EXECUTADO_C4"&CHAR(10)&"Inicio: "&RIGHT("0"&DAY(parametros!$D$6),2)&"/"&RIGHT("0"&MONTH(parametros!$D$6),2)&"/"&YEAR(parametros!$D$6)) | U1: CHECK | V1: CHECK_QTD | W1: CICLO | X1: COMPUTAR_NESTA_APURACAO | Y1: FATOR_PROPRIO | Z1: FATOR_ACUMULADO | AA1: EXECUÇÃO IMPLÍCITA C0 — INFORMATIVO | AB1: QTD_EXECUTADA_C0 | AC1: VALOR_EXECUTADO_C0
D2: =IF(OR(A2="",B2="",C2=""),"",ROUND(B2*C2,2)) | F2: =IF(OR(A2="",E2="",C2="",NOT(ISNUMBER($Z$3))),"",ROUND(E2*C2*$Z$3,2)) | H2: =IF(OR(A2="",G2="",C2="",NOT(ISNUMBER($Z$4))),"",ROUND(G2*C2*$Z$4,2)) | J2: =IF(OR(A2="",I2="",C2="",NOT(ISNUMBER($Z$5))),"",ROUND(I2*C2*$Z$5,2)) | L2: =IF(OR(A2="",K2="",C2="",NOT(ISNUMBER($Z$6))),"",ROUND(K2*C2*$Z$6,2)) | M2: =IF(OR(E2="",G2=""),"",ROUND(MAX(E2-G2,0),2)) | N2: =IF(OR(M2="",C2="",NOT(ISNUMBER($Z$3))),"",ROUND(M2*C2*$Z$3,2)) | O2: =IF(OR(G2="",I2=""),"",ROUND(MAX(G2-I2,0),2)) | P2: =IF(OR(O2="",C2="",NOT(ISNUMBER($Z$4))),"",ROUND(O2*C2*$Z$4,2)) | Q2: =IF(OR(I2="",K2=""),"",ROUND(MAX(I2-K2,0),2)) | R2: =IF(OR(Q2="",C2="",NOT(ISNUMBER($Z$5))),"",ROUND(Q2*C2*$Z$5,2)) | U2: =IF(A2="","",IF(AND(G2<>"",E2<>"",G2>E2),"ALERTA: REM_C2>REM_C1",IF(AND(I2<>"",G2<>"",I2>G2),"ALERTA: REM_C3>REM_C2",IF(AND(K2<>"",I2<>"",K2>I2),"ALERTA: REM_C4>REM_C3","OK")))) | V2: =IF(A2="","",IF(B2="","",IF(OR(B2<0,E2>B2,G2>B2,I2>B2,K2>B2),"ALERTA: QTD_INVALIDA","OK"))) | W2: C0 | X2: =parametros!$A$2 | Y2: =IF(ISNUMBER(parametros!$F$2),parametros!$F$2,"") | Z2: =IF(ISNUMBER(parametros!$G$2),parametros!$G$2,"") | AB2: =IF(OR(A2="",E2=""),"",ROUND(B2-E2,2)) | AC2: =IF(OR(A2="",E2=""),"",ROUND(D2-E2*C2,2))
D3: =IF(OR(A3="",B3="",C3=""),"",ROUND(B3*C3,2)) | F3: =IF(OR(A3="",E3="",C3="",NOT(ISNUMBER($Z$3))),"",ROUND(E3*C3*$Z$3,2)) | H3: =IF(OR(A3="",G3="",C3="",NOT(ISNUMBER($Z$4))),"",ROUND(G3*C3*$Z$4,2)) | J3: =IF(OR(A3="",I3="",C3="",NOT(ISNUMBER($Z$5))),"",ROUND(I3*C3*$Z$5,2)) | L3: =IF(OR(A3="",K3="",C3="",NOT(ISNUMBER($Z$6))),"",ROUND(K3*C3*$Z$6,2)) | M3: =IF(OR(E3="",G3=""),"",ROUND(MAX(E3-G3,0),2)) | N3: =IF(OR(M3="",C3="",NOT(ISNUMBER($Z$3))),"",ROUND(M3*C3*$Z$3,2)) | O3: =IF(OR(G3="",I3=""),"",ROUND(MAX(G3-I3,0),2)) | P3: =IF(OR(O3="",C3="",NOT(ISNUMBER($Z$4))),"",ROUND(O3*C3*$Z$4,2)) | Q3: =IF(OR(I3="",K3=""),"",ROUND(MAX(I3-K3,0),2)) | R3: =IF(OR(Q3="",C3="",NOT(ISNUMBER($Z$5))),"",ROUND(Q3*C3*$Z$5,2)) | U3: =IF(A3="","",IF(AND(G3<>"",E3<>"",G3>E3),"ALERTA: REM_C2>REM_C1",IF(AND(I3<>"",G3<>"",I3>G3),"ALERTA: REM_C3>REM_C2",IF(AND(K3<>"",I3<>"",K3>I3),"ALERTA: REM_C4>REM_C3","OK")))) | V3: =IF(A3="","",IF(B3="","",IF(OR(B3<0,E3>B3,G3>B3,I3>B3,K3>B3),"ALERTA: QTD_INVALIDA","OK"))) | W3: C1 | X3: =parametros!$A$3 | Y3: =IF(ISNUMBER(parametros!$F$3),parametros!$F$3,"") | Z3: =IF(ISNUMBER(parametros!$G$3),parametros!$G$3,"") | AB3: =IF(OR(A3="",E3=""),"",ROUND(B3-E3,2)) | AC3: =IF(OR(A3="",E3=""),"",ROUND(D3-E3*C3,2))
D4: =IF(OR(A4="",B4="",C4=""),"",ROUND(B4*C4,2)) | F4: =IF(OR(A4="",E4="",C4="",NOT(ISNUMBER($Z$3))),"",ROUND(E4*C4*$Z$3,2)) | H4: =IF(OR(A4="",G4="",C4="",NOT(ISNUMBER($Z$4))),"",ROUND(G4*C4*$Z$4,2)) | J4: =IF(OR(A4="",I4="",C4="",NOT(ISNUMBER($Z$5))),"",ROUND(I4*C4*$Z$5,2)) | L4: =IF(OR(A4="",K4="",C4="",NOT(ISNUMBER($Z$6))),"",ROUND(K4*C4*$Z$6,2)) | M4: =IF(OR(E4="",G4=""),"",ROUND(MAX(E4-G4,0),2)) | N4: =IF(OR(M4="",C4="",NOT(ISNUMBER($Z$3))),"",ROUND(M4*C4*$Z$3,2)) | O4: =IF(OR(G4="",I4=""),"",ROUND(MAX(G4-I4,0),2)) | P4: =IF(OR(O4="",C4="",NOT(ISNUMBER($Z$4))),"",ROUND(O4*C4*$Z$4,2)) | Q4: =IF(OR(I4="",K4=""),"",ROUND(MAX(I4-K4,0),2)) | R4: =IF(OR(Q4="",C4="",NOT(ISNUMBER($Z$5))),"",ROUND(Q4*C4*$Z$5,2)) | U4: =IF(A4="","",IF(AND(G4<>"",E4<>"",G4>E4),"ALERTA: REM_C2>REM_C1",IF(AND(I4<>"",G4<>"",I4>G4),"ALERTA: REM_C3>REM_C2",IF(AND(K4<>"",I4<>"",K4>I4),"ALERTA: REM_C4>REM_C3","OK")))) | V4: =IF(A4="","",IF(B4="","",IF(OR(B4<0,E4>B4,G4>B4,I4>B4,K4>B4),"ALERTA: QTD_INVALIDA","OK"))) | W4: C2 | X4: =parametros!$A$4 | Y4: =IF(ISNUMBER(parametros!$F$4),parametros!$F$4,"") | Z4: =IF(ISNUMBER(parametros!$G$4),parametros!$G$4,"") | AB4: =IF(OR(A4="",E4=""),"",ROUND(B4-E4,2)) | AC4: =IF(OR(A4="",E4=""),"",ROUND(D4-E4*C4,2))
D5: =IF(OR(A5="",B5="",C5=""),"",ROUND(B5*C5,2)) | F5: =IF(OR(A5="",E5="",C5="",NOT(ISNUMBER($Z$3))),"",ROUND(E5*C5*$Z$3,2)) | H5: =IF(OR(A5="",G5="",C5="",NOT(ISNUMBER($Z$4))),"",ROUND(G5*C5*$Z$4,2)) | J5: =IF(OR(A5="",I5="",C5="",NOT(ISNUMBER($Z$5))),"",ROUND(I5*C5*$Z$5,2)) | L5: =IF(OR(A5="",K5="",C5="",NOT(ISNUMBER($Z$6))),"",ROUND(K5*C5*$Z$6,2)) | M5: =IF(OR(E5="",G5=""),"",ROUND(MAX(E5-G5,0),2)) | N5: =IF(OR(M5="",C5="",NOT(ISNUMBER($Z$3))),"",ROUND(M5*C5*$Z$3,2)) | O5: =IF(OR(G5="",I5=""),"",ROUND(MAX(G5-I5,0),2)) | P5: =IF(OR(O5="",C5="",NOT(ISNUMBER($Z$4))),"",ROUND(O5*C5*$Z$4,2)) | Q5: =IF(OR(I5="",K5=""),"",ROUND(MAX(I5-K5,0),2)) | R5: =IF(OR(Q5="",C5="",NOT(ISNUMBER($Z$5))),"",ROUND(Q5*C5*$Z$5,2)) | U5: =IF(A5="","",IF(AND(G5<>"",E5<>"",G5>E5),"ALERTA: REM_C2>REM_C1",IF(AND(I5<>"",G5<>"",I5>G5),"ALERTA: REM_C3>REM_C2",IF(AND(K5<>"",I5<>"",K5>I5),"ALERTA: REM_C4>REM_C3","OK")))) | V5: =IF(A5="","",IF(B5="","",IF(OR(B5<0,E5>B5,G5>B5,I5>B5,K5>B5),"ALERTA: QTD_INVALIDA","OK"))) | W5: C3 | X5: =parametros!$A$5 | Y5: =IF(ISNUMBER(parametros!$F$5),parametros!$F$5,"") | Z5: =IF(ISNUMBER(parametros!$G$5),parametros!$G$5,"") | AB5: =IF(OR(A5="",E5=""),"",ROUND(B5-E5,2)) | AC5: =IF(OR(A5="",E5=""),"",ROUND(D5-E5*C5,2))
D6: =IF(OR(A6="",B6="",C6=""),"",ROUND(B6*C6,2)) | F6: =IF(OR(A6="",E6="",C6="",NOT(ISNUMBER($Z$3))),"",ROUND(E6*C6*$Z$3,2)) | H6: =IF(OR(A6="",G6="",C6="",NOT(ISNUMBER($Z$4))),"",ROUND(G6*C6*$Z$4,2)) | J6: =IF(OR(A6="",I6="",C6="",NOT(ISNUMBER($Z$5))),"",ROUND(I6*C6*$Z$5,2)) | L6: =IF(OR(A6="",K6="",C6="",NOT(ISNUMBER($Z$6))),"",ROUND(K6*C6*$Z$6,2)) | M6: =IF(OR(E6="",G6=""),"",ROUND(MAX(E6-G6,0),2)) | N6: =IF(OR(M6="",C6="",NOT(ISNUMBER($Z$3))),"",ROUND(M6*C6*$Z$3,2)) | O6: =IF(OR(G6="",I6=""),"",ROUND(MAX(G6-I6,0),2)) | P6: =IF(OR(O6="",C6="",NOT(ISNUMBER($Z$4))),"",ROUND(O6*C6*$Z$4,2)) | Q6: =IF(OR(I6="",K6=""),"",ROUND(MAX(I6-K6,0),2)) | R6: =IF(OR(Q6="",C6="",NOT(ISNUMBER($Z$5))),"",ROUND(Q6*C6*$Z$5,2)) | U6: =IF(A6="","",IF(AND(G6<>"",E6<>"",G6>E6),"ALERTA: REM_C2>REM_C1",IF(AND(I6<>"",G6<>"",I6>G6),"ALERTA: REM_C3>REM_C2",IF(AND(K6<>"",I6<>"",K6>I6),"ALERTA: REM_C4>REM_C3","OK")))) | V6: =IF(A6="","",IF(B6="","",IF(OR(B6<0,E6>B6,G6>B6,I6>B6,K6>B6),"ALERTA: QTD_INVALIDA","OK"))) | W6: C4 | X6: =parametros!$A$6 | Y6: =IF(ISNUMBER(parametros!$F$6),parametros!$F$6,"") | Z6: =IF(ISNUMBER(parametros!$G$6),parametros!$G$6,"") | AB6: =IF(OR(A6="",E6=""),"",ROUND(B6-E6,2)) | AC6: =IF(OR(A6="",E6=""),"",ROUND(D6-E6*C6,2))
D7: =IF(OR(A7="",B7="",C7=""),"",ROUND(B7*C7,2)) | F7: =IF(OR(A7="",E7="",C7="",NOT(ISNUMBER($Z$3))),"",ROUND(E7*C7*$Z$3,2)) | H7: =IF(OR(A7="",G7="",C7="",NOT(ISNUMBER($Z$4))),"",ROUND(G7*C7*$Z$4,2)) | J7: =IF(OR(A7="",I7="",C7="",NOT(ISNUMBER($Z$5))),"",ROUND(I7*C7*$Z$5,2)) | L7: =IF(OR(A7="",K7="",C7="",NOT(ISNUMBER($Z$6))),"",ROUND(K7*C7*$Z$6,2)) | M7: =IF(OR(E7="",G7=""),"",ROUND(MAX(E7-G7,0),2)) | N7: =IF(OR(M7="",C7="",NOT(ISNUMBER($Z$3))),"",ROUND(M7*C7*$Z$3,2)) | O7: =IF(OR(G7="",I7=""),"",ROUND(MAX(G7-I7,0),2)) | P7: =IF(OR(O7="",C7="",NOT(ISNUMBER($Z$4))),"",ROUND(O7*C7*$Z$4,2)) | Q7: =IF(OR(I7="",K7=""),"",ROUND(MAX(I7-K7,0),2)) | R7: =IF(OR(Q7="",C7="",NOT(ISNUMBER($Z$5))),"",ROUND(Q7*C7*$Z$5,2)) | U7: =IF(A7="","",IF(AND(G7<>"",E7<>"",G7>E7),"ALERTA: REM_C2>REM_C1",IF(AND(I7<>"",G7<>"",I7>G7),"ALERTA: REM_C3>REM_C2",IF(AND(K7<>"",I7<>"",K7>I7),"ALERTA: REM_C4>REM_C3","OK")))) | V7: =IF(A7="","",IF(B7="","",IF(OR(B7<0,E7>B7,G7>B7,I7>B7,K7>B7),"ALERTA: QTD_INVALIDA","OK"))) | AB7: =IF(OR(A7="",E7=""),"",ROUND(B7-E7,2)) | AC7: =IF(OR(A7="",E7=""),"",ROUND(D7-E7*C7,2))
D8: =IF(OR(A8="",B8="",C8=""),"",ROUND(B8*C8,2)) | F8: =IF(OR(A8="",E8="",C8="",NOT(ISNUMBER($Z$3))),"",ROUND(E8*C8*$Z$3,2)) | H8: =IF(OR(A8="",G8="",C8="",NOT(ISNUMBER($Z$4))),"",ROUND(G8*C8*$Z$4,2)) | J8: =IF(OR(A8="",I8="",C8="",NOT(ISNUMBER($Z$5))),"",ROUND(I8*C8*$Z$5,2)) | L8: =IF(OR(A8="",K8="",C8="",NOT(ISNUMBER($Z$6))),"",ROUND(K8*C8*$Z$6,2)) | M8: =IF(OR(E8="",G8=""),"",ROUND(MAX(E8-G8,0),2)) | N8: =IF(OR(M8="",C8="",NOT(ISNUMBER($Z$3))),"",ROUND(M8*C8*$Z$3,2)) | O8: =IF(OR(G8="",I8=""),"",ROUND(MAX(G8-I8,0),2)) | P8: =IF(OR(O8="",C8="",NOT(ISNUMBER($Z$4))),"",ROUND(O8*C8*$Z$4,2)) | Q8: =IF(OR(I8="",K8=""),"",ROUND(MAX(I8-K8,0),2)) | R8: =IF(OR(Q8="",C8="",NOT(ISNUMBER($Z$5))),"",ROUND(Q8*C8*$Z$5,2)) | U8: =IF(A8="","",IF(AND(G8<>"",E8<>"",G8>E8),"ALERTA: REM_C2>REM_C1",IF(AND(I8<>"",G8<>"",I8>G8),"ALERTA: REM_C3>REM_C2",IF(AND(K8<>"",I8<>"",K8>I8),"ALERTA: REM_C4>REM_C3","OK")))) | V8: =IF(A8="","",IF(B8="","",IF(OR(B8<0,E8>B8,G8>B8,I8>B8,K8>B8),"ALERTA: QTD_INVALIDA","OK"))) | AB8: =IF(OR(A8="",E8=""),"",ROUND(B8-E8,2)) | AC8: =IF(OR(A8="",E8=""),"",ROUND(D8-E8*C8,2))
D9: =IF(OR(A9="",B9="",C9=""),"",ROUND(B9*C9,2)) | F9: =IF(OR(A9="",E9="",C9="",NOT(ISNUMBER($Z$3))),"",ROUND(E9*C9*$Z$3,2)) | H9: =IF(OR(A9="",G9="",C9="",NOT(ISNUMBER($Z$4))),"",ROUND(G9*C9*$Z$4,2)) | J9: =IF(OR(A9="",I9="",C9="",NOT(ISNUMBER($Z$5))),"",ROUND(I9*C9*$Z$5,2)) | L9: =IF(OR(A9="",K9="",C9="",NOT(ISNUMBER($Z$6))),"",ROUND(K9*C9*$Z$6,2)) | M9: =IF(OR(E9="",G9=""),"",ROUND(MAX(E9-G9,0),2)) | N9: =IF(OR(M9="",C9="",NOT(ISNUMBER($Z$3))),"",ROUND(M9*C9*$Z$3,2)) | O9: =IF(OR(G9="",I9=""),"",ROUND(MAX(G9-I9,0),2)) | P9: =IF(OR(O9="",C9="",NOT(ISNUMBER($Z$4))),"",ROUND(O9*C9*$Z$4,2)) | Q9: =IF(OR(I9="",K9=""),"",ROUND(MAX(I9-K9,0),2)) | R9: =IF(OR(Q9="",C9="",NOT(ISNUMBER($Z$5))),"",ROUND(Q9*C9*$Z$5,2)) | U9: =IF(A9="","",IF(AND(G9<>"",E9<>"",G9>E9),"ALERTA: REM_C2>REM_C1",IF(AND(I9<>"",G9<>"",I9>G9),"ALERTA: REM_C3>REM_C2",IF(AND(K9<>"",I9<>"",K9>I9),"ALERTA: REM_C4>REM_C3","OK")))) | V9: =IF(A9="","",IF(B9="","",IF(OR(B9<0,E9>B9,G9>B9,I9>B9,K9>B9),"ALERTA: QTD_INVALIDA","OK"))) | AB9: =IF(OR(A9="",E9=""),"",ROUND(B9-E9,2)) | AC9: =IF(OR(A9="",E9=""),"",ROUND(D9-E9*C9,2))
D10: =IF(OR(A10="",B10="",C10=""),"",ROUND(B10*C10,2)) | F10: =IF(OR(A10="",E10="",C10="",NOT(ISNUMBER($Z$3))),"",ROUND(E10*C10*$Z$3,2)) | H10: =IF(OR(A10="",G10="",C10="",NOT(ISNUMBER($Z$4))),"",ROUND(G10*C10*$Z$4,2)) | J10: =IF(OR(A10="",I10="",C10="",NOT(ISNUMBER($Z$5))),"",ROUND(I10*C10*$Z$5,2)) | L10: =IF(OR(A10="",K10="",C10="",NOT(ISNUMBER($Z$6))),"",ROUND(K10*C10*$Z$6,2)) | M10: =IF(OR(E10="",G10=""),"",ROUND(MAX(E10-G10,0),2)) | N10: =IF(OR(M10="",C10="",NOT(ISNUMBER($Z$3))),"",ROUND(M10*C10*$Z$3,2)) | O10: =IF(OR(G10="",I10=""),"",ROUND(MAX(G10-I10,0),2)) | P10: =IF(OR(O10="",C10="",NOT(ISNUMBER($Z$4))),"",ROUND(O10*C10*$Z$4,2)) | Q10: =IF(OR(I10="",K10=""),"",ROUND(MAX(I10-K10,0),2)) | R10: =IF(OR(Q10="",C10="",NOT(ISNUMBER($Z$5))),"",ROUND(Q10*C10*$Z$5,2)) | U10: =IF(A10="","",IF(AND(G10<>"",E10<>"",G10>E10),"ALERTA: REM_C2>REM_C1",IF(AND(I10<>"",G10<>"",I10>G10),"ALERTA: REM_C3>REM_C2",IF(AND(K10<>"",I10<>"",K10>I10),"ALERTA: REM_C4>REM_C3","OK")))) | V10: =IF(A10="","",IF(B10="","",IF(OR(B10<0,E10>B10,G10>B10,I10>B10,K10>B10),"ALERTA: QTD_INVALIDA","OK"))) | AB10: =IF(OR(A10="",E10=""),"",ROUND(B10-E10,2)) | AC10: =IF(OR(A10="",E10=""),"",ROUND(D10-E10*C10,2))
D11: =IF(OR(A11="",B11="",C11=""),"",ROUND(B11*C11,2)) | F11: =IF(OR(A11="",E11="",C11="",NOT(ISNUMBER($Z$3))),"",ROUND(E11*C11*$Z$3,2)) | H11: =IF(OR(A11="",G11="",C11="",NOT(ISNUMBER($Z$4))),"",ROUND(G11*C11*$Z$4,2)) | J11: =IF(OR(A11="",I11="",C11="",NOT(ISNUMBER($Z$5))),"",ROUND(I11*C11*$Z$5,2)) | L11: =IF(OR(A11="",K11="",C11="",NOT(ISNUMBER($Z$6))),"",ROUND(K11*C11*$Z$6,2)) | M11: =IF(OR(E11="",G11=""),"",ROUND(MAX(E11-G11,0),2)) | N11: =IF(OR(M11="",C11="",NOT(ISNUMBER($Z$3))),"",ROUND(M11*C11*$Z$3,2)) | O11: =IF(OR(G11="",I11=""),"",ROUND(MAX(G11-I11,0),2)) | P11: =IF(OR(O11="",C11="",NOT(ISNUMBER($Z$4))),"",ROUND(O11*C11*$Z$4,2)) | Q11: =IF(OR(I11="",K11=""),"",ROUND(MAX(I11-K11,0),2)) | R11: =IF(OR(Q11="",C11="",NOT(ISNUMBER($Z$5))),"",ROUND(Q11*C11*$Z$5,2)) | U11: =IF(A11="","",IF(AND(G11<>"",E11<>"",G11>E11),"ALERTA: REM_C2>REM_C1",IF(AND(I11<>"",G11<>"",I11>G11),"ALERTA: REM_C3>REM_C2",IF(AND(K11<>"",I11<>"",K11>I11),"ALERTA: REM_C4>REM_C3","OK")))) | V11: =IF(A11="","",IF(B11="","",IF(OR(B11<0,E11>B11,G11>B11,I11>B11,K11>B11),"ALERTA: QTD_INVALIDA","OK"))) | AB11: =IF(OR(A11="",E11=""),"",ROUND(B11-E11,2)) | AC11: =IF(OR(A11="",E11=""),"",ROUND(D11-E11*C11,2))
D12: =IF(OR(A12="",B12="",C12=""),"",ROUND(B12*C12,2)) | F12: =IF(OR(A12="",E12="",C12="",NOT(ISNUMBER($Z$3))),"",ROUND(E12*C12*$Z$3,2)) | H12: =IF(OR(A12="",G12="",C12="",NOT(ISNUMBER($Z$4))),"",ROUND(G12*C12*$Z$4,2)) | J12: =IF(OR(A12="",I12="",C12="",NOT(ISNUMBER($Z$5))),"",ROUND(I12*C12*$Z$5,2)) | L12: =IF(OR(A12="",K12="",C12="",NOT(ISNUMBER($Z$6))),"",ROUND(K12*C12*$Z$6,2)) | M12: =IF(OR(E12="",G12=""),"",ROUND(MAX(E12-G12,0),2)) | N12: =IF(OR(M12="",C12="",NOT(ISNUMBER($Z$3))),"",ROUND(M12*C12*$Z$3,2)) | O12: =IF(OR(G12="",I12=""),"",ROUND(MAX(G12-I12,0),2)) | P12: =IF(OR(O12="",C12="",NOT(ISNUMBER($Z$4))),"",ROUND(O12*C12*$Z$4,2)) | Q12: =IF(OR(I12="",K12=""),"",ROUND(MAX(I12-K12,0),2)) | R12: =IF(OR(Q12="",C12="",NOT(ISNUMBER($Z$5))),"",ROUND(Q12*C12*$Z$5,2)) | U12: =IF(A12="","",IF(AND(G12<>"",E12<>"",G12>E12),"ALERTA: REM_C2>REM_C1",IF(AND(I12<>"",G12<>"",I12>G12),"ALERTA: REM_C3>REM_C2",IF(AND(K12<>"",I12<>"",K12>I12),"ALERTA: REM_C4>REM_C3","OK")))) | V12: =IF(A12="","",IF(B12="","",IF(OR(B12<0,E12>B12,G12>B12,I12>B12,K12>B12),"ALERTA: QTD_INVALIDA","OK"))) | AB12: =IF(OR(A12="",E12=""),"",ROUND(B12-E12,2)) | AC12: =IF(OR(A12="",E12=""),"",ROUND(D12-E12*C12,2))
D13: =IF(OR(A13="",B13="",C13=""),"",ROUND(B13*C13,2)) | F13: =IF(OR(A13="",E13="",C13="",NOT(ISNUMBER($Z$3))),"",ROUND(E13*C13*$Z$3,2)) | H13: =IF(OR(A13="",G13="",C13="",NOT(ISNUMBER($Z$4))),"",ROUND(G13*C13*$Z$4,2)) | J13: =IF(OR(A13="",I13="",C13="",NOT(ISNUMBER($Z$5))),"",ROUND(I13*C13*$Z$5,2)) | L13: =IF(OR(A13="",K13="",C13="",NOT(ISNUMBER($Z$6))),"",ROUND(K13*C13*$Z$6,2)) | M13: =IF(OR(E13="",G13=""),"",ROUND(MAX(E13-G13,0),2)) | N13: =IF(OR(M13="",C13="",NOT(ISNUMBER($Z$3))),"",ROUND(M13*C13*$Z$3,2)) | O13: =IF(OR(G13="",I13=""),"",ROUND(MAX(G13-I13,0),2)) | P13: =IF(OR(O13="",C13="",NOT(ISNUMBER($Z$4))),"",ROUND(O13*C13*$Z$4,2)) | Q13: =IF(OR(I13="",K13=""),"",ROUND(MAX(I13-K13,0),2)) | R13: =IF(OR(Q13="",C13="",NOT(ISNUMBER($Z$5))),"",ROUND(Q13*C13*$Z$5,2)) | U13: =IF(A13="","",IF(AND(G13<>"",E13<>"",G13>E13),"ALERTA: REM_C2>REM_C1",IF(AND(I13<>"",G13<>"",I13>G13),"ALERTA: REM_C3>REM_C2",IF(AND(K13<>"",I13<>"",K13>I13),"ALERTA: REM_C4>REM_C3","OK")))) | V13: =IF(A13="","",IF(B13="","",IF(OR(B13<0,E13>B13,G13>B13,I13>B13,K13>B13),"ALERTA: QTD_INVALIDA","OK"))) | AB13: =IF(OR(A13="",E13=""),"",ROUND(B13-E13,2)) | AC13: =IF(OR(A13="",E13=""),"",ROUND(D13-E13*C13,2))
D14: =IF(OR(A14="",B14="",C14=""),"",ROUND(B14*C14,2)) | F14: =IF(OR(A14="",E14="",C14="",NOT(ISNUMBER($Z$3))),"",ROUND(E14*C14*$Z$3,2)) | H14: =IF(OR(A14="",G14="",C14="",NOT(ISNUMBER($Z$4))),"",ROUND(G14*C14*$Z$4,2)) | J14: =IF(OR(A14="",I14="",C14="",NOT(ISNUMBER($Z$5))),"",ROUND(I14*C14*$Z$5,2)) | L14: =IF(OR(A14="",K14="",C14="",NOT(ISNUMBER($Z$6))),"",ROUND(K14*C14*$Z$6,2)) | M14: =IF(OR(E14="",G14=""),"",ROUND(MAX(E14-G14,0),2)) | N14: =IF(OR(M14="",C14="",NOT(ISNUMBER($Z$3))),"",ROUND(M14*C14*$Z$3,2)) | O14: =IF(OR(G14="",I14=""),"",ROUND(MAX(G14-I14,0),2)) | P14: =IF(OR(O14="",C14="",NOT(ISNUMBER($Z$4))),"",ROUND(O14*C14*$Z$4,2)) | Q14: =IF(OR(I14="",K14=""),"",ROUND(MAX(I14-K14,0),2)) | R14: =IF(OR(Q14="",C14="",NOT(ISNUMBER($Z$5))),"",ROUND(Q14*C14*$Z$5,2)) | U14: =IF(A14="","",IF(AND(G14<>"",E14<>"",G14>E14),"ALERTA: REM_C2>REM_C1",IF(AND(I14<>"",G14<>"",I14>G14),"ALERTA: REM_C3>REM_C2",IF(AND(K14<>"",I14<>"",K14>I14),"ALERTA: REM_C4>REM_C3","OK")))) | V14: =IF(A14="","",IF(B14="","",IF(OR(B14<0,E14>B14,G14>B14,I14>B14,K14>B14),"ALERTA: QTD_INVALIDA","OK"))) | AB14: =IF(OR(A14="",E14=""),"",ROUND(B14-E14,2)) | AC14: =IF(OR(A14="",E14=""),"",ROUND(D14-E14*C14,2))
D15: =IF(OR(A15="",B15="",C15=""),"",ROUND(B15*C15,2)) | F15: =IF(OR(A15="",E15="",C15="",NOT(ISNUMBER($Z$3))),"",ROUND(E15*C15*$Z$3,2)) | H15: =IF(OR(A15="",G15="",C15="",NOT(ISNUMBER($Z$4))),"",ROUND(G15*C15*$Z$4,2)) | J15: =IF(OR(A15="",I15="",C15="",NOT(ISNUMBER($Z$5))),"",ROUND(I15*C15*$Z$5,2)) | L15: =IF(OR(A15="",K15="",C15="",NOT(ISNUMBER($Z$6))),"",ROUND(K15*C15*$Z$6,2)) | M15: =IF(OR(E15="",G15=""),"",ROUND(MAX(E15-G15,0),2)) | N15: =IF(OR(M15="",C15="",NOT(ISNUMBER($Z$3))),"",ROUND(M15*C15*$Z$3,2)) | O15: =IF(OR(G15="",I15=""),"",ROUND(MAX(G15-I15,0),2)) | P15: =IF(OR(O15="",C15="",NOT(ISNUMBER($Z$4))),"",ROUND(O15*C15*$Z$4,2)) | Q15: =IF(OR(I15="",K15=""),"",ROUND(MAX(I15-K15,0),2)) | R15: =IF(OR(Q15="",C15="",NOT(ISNUMBER($Z$5))),"",ROUND(Q15*C15*$Z$5,2)) | U15: =IF(A15="","",IF(AND(G15<>"",E15<>"",G15>E15),"ALERTA: REM_C2>REM_C1",IF(AND(I15<>"",G15<>"",I15>G15),"ALERTA: REM_C3>REM_C2",IF(AND(K15<>"",I15<>"",K15>I15),"ALERTA: REM_C4>REM_C3","OK")))) | V15: =IF(A15="","",IF(B15="","",IF(OR(B15<0,E15>B15,G15>B15,I15>B15,K15>B15),"ALERTA: QTD_INVALIDA","OK"))) | AB15: =IF(OR(A15="",E15=""),"",ROUND(B15-E15,2)) | AC15: =IF(OR(A15="",E15=""),"",ROUND(D15-E15*C15,2))
D16: =IF(OR(A16="",B16="",C16=""),"",ROUND(B16*C16,2)) | F16: =IF(OR(A16="",E16="",C16="",NOT(ISNUMBER($Z$3))),"",ROUND(E16*C16*$Z$3,2)) | H16: =IF(OR(A16="",G16="",C16="",NOT(ISNUMBER($Z$4))),"",ROUND(G16*C16*$Z$4,2)) | J16: =IF(OR(A16="",I16="",C16="",NOT(ISNUMBER($Z$5))),"",ROUND(I16*C16*$Z$5,2)) | L16: =IF(OR(A16="",K16="",C16="",NOT(ISNUMBER($Z$6))),"",ROUND(K16*C16*$Z$6,2)) | M16: =IF(OR(E16="",G16=""),"",ROUND(MAX(E16-G16,0),2)) | N16: =IF(OR(M16="",C16="",NOT(ISNUMBER($Z$3))),"",ROUND(M16*C16*$Z$3,2)) | O16: =IF(OR(G16="",I16=""),"",ROUND(MAX(G16-I16,0),2)) | P16: =IF(OR(O16="",C16="",NOT(ISNUMBER($Z$4))),"",ROUND(O16*C16*$Z$4,2)) | Q16: =IF(OR(I16="",K16=""),"",ROUND(MAX(I16-K16,0),2)) | R16: =IF(OR(Q16="",C16="",NOT(ISNUMBER($Z$5))),"",ROUND(Q16*C16*$Z$5,2)) | U16: =IF(A16="","",IF(AND(G16<>"",E16<>"",G16>E16),"ALERTA: REM_C2>REM_C1",IF(AND(I16<>"",G16<>"",I16>G16),"ALERTA: REM_C3>REM_C2",IF(AND(K16<>"",I16<>"",K16>I16),"ALERTA: REM_C4>REM_C3","OK")))) | V16: =IF(A16="","",IF(B16="","",IF(OR(B16<0,E16>B16,G16>B16,I16>B16,K16>B16),"ALERTA: QTD_INVALIDA","OK"))) | AB16: =IF(OR(A16="",E16=""),"",ROUND(B16-E16,2)) | AC16: =IF(OR(A16="",E16=""),"",ROUND(D16-E16*C16,2))
D17: =IF(OR(A17="",B17="",C17=""),"",ROUND(B17*C17,2)) | F17: =IF(OR(A17="",E17="",C17="",NOT(ISNUMBER($Z$3))),"",ROUND(E17*C17*$Z$3,2)) | H17: =IF(OR(A17="",G17="",C17="",NOT(ISNUMBER($Z$4))),"",ROUND(G17*C17*$Z$4,2)) | J17: =IF(OR(A17="",I17="",C17="",NOT(ISNUMBER($Z$5))),"",ROUND(I17*C17*$Z$5,2)) | L17: =IF(OR(A17="",K17="",C17="",NOT(ISNUMBER($Z$6))),"",ROUND(K17*C17*$Z$6,2)) | M17: =IF(OR(E17="",G17=""),"",ROUND(MAX(E17-G17,0),2)) | N17: =IF(OR(M17="",C17="",NOT(ISNUMBER($Z$3))),"",ROUND(M17*C17*$Z$3,2)) | O17: =IF(OR(G17="",I17=""),"",ROUND(MAX(G17-I17,0),2)) | P17: =IF(OR(O17="",C17="",NOT(ISNUMBER($Z$4))),"",ROUND(O17*C17*$Z$4,2)) | Q17: =IF(OR(I17="",K17=""),"",ROUND(MAX(I17-K17,0),2)) | R17: =IF(OR(Q17="",C17="",NOT(ISNUMBER($Z$5))),"",ROUND(Q17*C17*$Z$5,2)) | U17: =IF(A17="","",IF(AND(G17<>"",E17<>"",G17>E17),"ALERTA: REM_C2>REM_C1",IF(AND(I17<>"",G17<>"",I17>G17),"ALERTA: REM_C3>REM_C2",IF(AND(K17<>"",I17<>"",K17>I17),"ALERTA: REM_C4>REM_C3","OK")))) | V17: =IF(A17="","",IF(B17="","",IF(OR(B17<0,E17>B17,G17>B17,I17>B17,K17>B17),"ALERTA: QTD_INVALIDA","OK"))) | AB17: =IF(OR(A17="",E17=""),"",ROUND(B17-E17,2)) | AC17: =IF(OR(A17="",E17=""),"",ROUND(D17-E17*C17,2))
D18: =IF(OR(A18="",B18="",C18=""),"",ROUND(B18*C18,2)) | F18: =IF(OR(A18="",E18="",C18="",NOT(ISNUMBER($Z$3))),"",ROUND(E18*C18*$Z$3,2)) | H18: =IF(OR(A18="",G18="",C18="",NOT(ISNUMBER($Z$4))),"",ROUND(G18*C18*$Z$4,2)) | J18: =IF(OR(A18="",I18="",C18="",NOT(ISNUMBER($Z$5))),"",ROUND(I18*C18*$Z$5,2)) | L18: =IF(OR(A18="",K18="",C18="",NOT(ISNUMBER($Z$6))),"",ROUND(K18*C18*$Z$6,2)) | M18: =IF(OR(E18="",G18=""),"",ROUND(MAX(E18-G18,0),2)) | N18: =IF(OR(M18="",C18="",NOT(ISNUMBER($Z$3))),"",ROUND(M18*C18*$Z$3,2)) | O18: =IF(OR(G18="",I18=""),"",ROUND(MAX(G18-I18,0),2)) | P18: =IF(OR(O18="",C18="",NOT(ISNUMBER($Z$4))),"",ROUND(O18*C18*$Z$4,2)) | Q18: =IF(OR(I18="",K18=""),"",ROUND(MAX(I18-K18,0),2)) | R18: =IF(OR(Q18="",C18="",NOT(ISNUMBER($Z$5))),"",ROUND(Q18*C18*$Z$5,2)) | U18: =IF(A18="","",IF(AND(G18<>"",E18<>"",G18>E18),"ALERTA: REM_C2>REM_C1",IF(AND(I18<>"",G18<>"",I18>G18),"ALERTA: REM_C3>REM_C2",IF(AND(K18<>"",I18<>"",K18>I18),"ALERTA: REM_C4>REM_C3","OK")))) | V18: =IF(A18="","",IF(B18="","",IF(OR(B18<0,E18>B18,G18>B18,I18>B18,K18>B18),"ALERTA: QTD_INVALIDA","OK"))) | AB18: =IF(OR(A18="",E18=""),"",ROUND(B18-E18,2)) | AC18: =IF(OR(A18="",E18=""),"",ROUND(D18-E18*C18,2))
... D200: =IF(OR(A200="",B200="",C200=""),"",ROUND(B200*C200,2)) | F200: =IF(OR(A200="",E200="",C200="",NOT(ISNUMBER($Z$3))),"",ROUND(E200*C200*$Z$3,2)) | H200: =IF(OR(A200="",G200="",C200="",NOT(ISNUMBER($Z$4))),"",ROUND(G200*C200*$Z$4,2)) | J200: =IF(OR(A200="",I200="",C200="",NOT(ISNUMBER($Z$5))),"",ROUND(I200*C200*$Z$5,2)) | L200: =IF(OR(A200="",K200="",C200="",NOT(ISNUMBER($Z$6))),"",ROUND(K200*C200*$Z$6,2)) | M200: =IF(OR(E200="",G200=""),"",ROUND(MAX(E200-G200,0),2)) | N200: =IF(OR(M200="",C200="",NOT(ISNUMBER($Z$3))),"",ROUND(M200*C200*$Z$3,2)) | O200: =IF(OR(G200="",I200=""),"",ROUND(MAX(G200-I200,0),2)) | P200: =IF(OR(O200="",C200="",NOT(ISNUMBER($Z$4))),"",ROUND(O200*C200*$Z$4,2)) | Q200: =IF(OR(I200="",K200=""),"",ROUND(MAX(I200-K200,0),2)) | R200: =IF(OR(Q200="",C200="",NOT(ISNUMBER($Z$5))),"",ROUND(Q200*C200*$Z$5,2)) | U200: =IF(A200="","",IF(AND(G200<>"",E200<>"",G200>E200),"ALERTA: REM_C2>REM_C1",IF(AND(I200<>"",G200<>"",I200>G200),"ALERTA: REM_C3>REM_C2",IF(AND(K200<>"",I200<>"",K200>I200),"ALERTA: REM_C4>REM_C3","OK")))) | V200: =IF(A200="","",IF(B200="","",IF(OR(B200<0,E200>B200,G200>B200,I200>B200,K200>B200),"ALERTA: QTD_INVALIDA","OK"))) | AB200: =IF(OR(A200="",E200=""),"",ROUND(B200-E200,2)) | AC200: =IF(OR(A200="",E200=""),"",ROUND(D200-E200*C200,2))

Sheet itens_Consumidos
A1: ITEM | B1: QTD_CONTRATADA | C1: VU_ORIGINAL | D1: VALOR_TOTAL | E1: QTD_CONS_C0 | F1: VALOR_CONS_C0 | G1: QTD_CONS_C1 | H1: VALOR_CONS_C1 | I1: QTD_CONS_C2 | J1: VALOR_CONS_C2 | K1: QTD_CONS_C3 | L1: VALOR_CONS_C3 | M1: QTD_CONS_C4 | N1: VALOR_CONS_C4 | O1: CONS_QTD_TOTAL | P1: CONS_VALOR_TOTAL | Q1: CHECK | R1: CICLO | S1: COMPUTAR_NESTA_APURACAO | T1: FATOR_PROPRIO | U1: FATOR_ACUMULADO
D2: =IF(OR(A2="",B2="",C2=""),"",ROUND(B2*C2,2)) | F2: =IF(OR(A2="",E2="",C2="",NOT(ISNUMBER($U$2))),"",ROUND(E2*C2*$U$2,2)) | H2: =IF(OR(A2="",G2="",C2="",NOT(ISNUMBER($U$3))),"",ROUND(G2*C2*$U$3,2)) | J2: =IF(OR(A2="",I2="",C2="",NOT(ISNUMBER($U$4))),"",ROUND(I2*C2*$U$4,2)) | L2: =IF(OR(A2="",K2="",C2="",NOT(ISNUMBER($U$5))),"",ROUND(K2*C2*$U$5,2)) | N2: =IF(OR(A2="",M2="",C2="",NOT(ISNUMBER($U$6))),"",ROUND(M2*C2*$U$6,2)) | O2: =IF(A2="","",SUM(E2,G2,I2,K2,M2)) | P2: =IF(A2="","",SUM(F2,H2,J2,L2,N2)) | Q2: =IF(A2="","",IF(O2>B2,"DIVERGENCIA: CONSUMO MAIOR QUE CONTRATADO","OK")) | R2: C0 | S2: =parametros!$A$2 | T2: =IF(ISNUMBER(parametros!$F$2),parametros!$F$2,"") | U2: =IF(ISNUMBER(parametros!$G$2),parametros!$G$2,"")
D3: =IF(OR(A3="",B3="",C3=""),"",ROUND(B3*C3,2)) | F3: =IF(OR(A3="",E3="",C3="",NOT(ISNUMBER($U$2))),"",ROUND(E3*C3*$U$2,2)) | H3: =IF(OR(A3="",G3="",C3="",NOT(ISNUMBER($U$3))),"",ROUND(G3*C3*$U$3,2)) | J3: =IF(OR(A3="",I3="",C3="",NOT(ISNUMBER($U$4))),"",ROUND(I3*C3*$U$4,2)) | L3: =IF(OR(A3="",K3="",C3="",NOT(ISNUMBER($U$5))),"",ROUND(K3*C3*$U$5,2)) | N3: =IF(OR(A3="",M3="",C3="",NOT(ISNUMBER($U$6))),"",ROUND(M3*C3*$U$6,2)) | O3: =IF(A3="","",SUM(E3,G3,I3,K3,M3)) | P3: =IF(A3="","",SUM(F3,H3,J3,L3,N3)) | Q3: =IF(A3="","",IF(O3>B3,"DIVERGENCIA: CONSUMO MAIOR QUE CONTRATADO","OK")) | R3: C1 | S3: =parametros!$A$3 | T3: =IF(ISNUMBER(parametros!$F$3),parametros!$F$3,"") | U3: =IF(ISNUMBER(parametros!$G$3),parametros!$G$3,"")
D4: =IF(OR(A4="",B4="",C4=""),"",ROUND(B4*C4,2)) | F4: =IF(OR(A4="",E4="",C4="",NOT(ISNUMBER($U$2))),"",ROUND(E4*C4*$U$2,2)) | H4: =IF(OR(A4="",G4="",C4="",NOT(ISNUMBER($U$3))),"",ROUND(G4*C4*$U$3,2)) | J4: =IF(OR(A4="",I4="",C4="",NOT(ISNUMBER($U$4))),"",ROUND(I4*C4*$U$4,2)) | L4: =IF(OR(A4="",K4="",C4="",NOT(ISNUMBER($U$5))),"",ROUND(K4*C4*$U$5,2)) | N4: =IF(OR(A4="",M4="",C4="",NOT(ISNUMBER($U$6))),"",ROUND(M4*C4*$U$6,2)) | O4: =IF(A4="","",SUM(E4,G4,I4,K4,M4)) | P4: =IF(A4="","",SUM(F4,H4,J4,L4,N4)) | Q4: =IF(A4="","",IF(O4>B4,"DIVERGENCIA: CONSUMO MAIOR QUE CONTRATADO","OK")) | R4: C2 | S4: =parametros!$A$4 | T4: =IF(ISNUMBER(parametros!$F$4),parametros!$F$4,"") | U4: =IF(ISNUMBER(parametros!$G$4),parametros!$G$4,"")
D5: =IF(OR(A5="",B5="",C5=""),"",ROUND(B5*C5,2)) | F5: =IF(OR(A5="",E5="",C5="",NOT(ISNUMBER($U$2))),"",ROUND(E5*C5*$U$2,2)) | H5: =IF(OR(A5="",G5="",C5="",NOT(ISNUMBER($U$3))),"",ROUND(G5*C5*$U$3,2)) | J5: =IF(OR(A5="",I5="",C5="",NOT(ISNUMBER($U$4))),"",ROUND(I5*C5*$U$4,2)) | L5: =IF(OR(A5="",K5="",C5="",NOT(ISNUMBER($U$5))),"",ROUND(K5*C5*$U$5,2)) | N5: =IF(OR(A5="",M5="",C5="",NOT(ISNUMBER($U$6))),"",ROUND(M5*C5*$U$6,2)) | O5: =IF(A5="","",SUM(E5,G5,I5,K5,M5)) | P5: =IF(A5="","",SUM(F5,H5,J5,L5,N5)) | Q5: =IF(A5="","",IF(O5>B5,"DIVERGENCIA: CONSUMO MAIOR QUE CONTRATADO","OK")) | R5: C3 | S5: =parametros!$A$5 | T5: =IF(ISNUMBER(parametros!$F$5),parametros!$F$5,"") | U5: =IF(ISNUMBER(parametros!$G$5),parametros!$G$5,"")
D6: =IF(OR(A6="",B6="",C6=""),"",ROUND(B6*C6,2)) | F6: =IF(OR(A6="",E6="",C6="",NOT(ISNUMBER($U$2))),"",ROUND(E6*C6*$U$2,2)) | H6: =IF(OR(A6="",G6="",C6="",NOT(ISNUMBER($U$3))),"",ROUND(G6*C6*$U$3,2)) | J6: =IF(OR(A6="",I6="",C6="",NOT(ISNUMBER($U$4))),"",ROUND(I6*C6*$U$4,2)) | L6: =IF(OR(A6="",K6="",C6="",NOT(ISNUMBER($U$5))),"",ROUND(K6*C6*$U$5,2)) | N6: =IF(OR(A6="",M6="",C6="",NOT(ISNUMBER($U$6))),"",ROUND(M6*C6*$U$6,2)) | O6: =IF(A6="","",SUM(E6,G6,I6,K6,M6)) | P6: =IF(A6="","",SUM(F6,H6,J6,L6,N6)) | Q6: =IF(A6="","",IF(O6>B6,"DIVERGENCIA: CONSUMO MAIOR QUE CONTRATADO","OK")) | R6: C4 | S6: =parametros!$A$6 | T6: =IF(ISNUMBER(parametros!$F$6),parametros!$F$6,"") | U6: =IF(ISNUMBER(parametros!$G$6),parametros!$G$6,"")
D7: =IF(OR(A7="",B7="",C7=""),"",ROUND(B7*C7,2)) | F7: =IF(OR(A7="",E7="",C7="",NOT(ISNUMBER($U$2))),"",ROUND(E7*C7*$U$2,2)) | H7: =IF(OR(A7="",G7="",C7="",NOT(ISNUMBER($U$3))),"",ROUND(G7*C7*$U$3,2)) | J7: =IF(OR(A7="",I7="",C7="",NOT(ISNUMBER($U$4))),"",ROUND(I7*C7*$U$4,2)) | L7: =IF(OR(A7="",K7="",C7="",NOT(ISNUMBER($U$5))),"",ROUND(K7*C7*$U$5,2)) | N7: =IF(OR(A7="",M7="",C7="",NOT(ISNUMBER($U$6))),"",ROUND(M7*C7*$U$6,2)) | O7: =IF(A7="","",SUM(E7,G7,I7,K7,M7)) | P7: =IF(A7="","",SUM(F7,H7,J7,L7,N7)) | Q7: =IF(A7="","",IF(O7>B7,"DIVERGENCIA: CONSUMO MAIOR QUE CONTRATADO","OK"))
D8: =IF(OR(A8="",B8="",C8=""),"",ROUND(B8*C8,2)) | F8: =IF(OR(A8="",E8="",C8="",NOT(ISNUMBER($U$2))),"",ROUND(E8*C8*$U$2,2)) | H8: =IF(OR(A8="",G8="",C8="",NOT(ISNUMBER($U$3))),"",ROUND(G8*C8*$U$3,2)) | J8: =IF(OR(A8="",I8="",C8="",NOT(ISNUMBER($U$4))),"",ROUND(I8*C8*$U$4,2)) | L8: =IF(OR(A8="",K8="",C8="",NOT(ISNUMBER($U$5))),"",ROUND(K8*C8*$U$5,2)) | N8: =IF(OR(A8="",M8="",C8="",NOT(ISNUMBER($U$6))),"",ROUND(M8*C8*$U$6,2)) | O8: =IF(A8="","",SUM(E8,G8,I8,K8,M8)) | P8: =IF(A8="","",SUM(F8,H8,J8,L8,N8)) | Q8: =IF(A8="","",IF(O8>B8,"DIVERGENCIA: CONSUMO MAIOR QUE CONTRATADO","OK"))
D9: =IF(OR(A9="",B9="",C9=""),"",ROUND(B9*C9,2)) | F9: =IF(OR(A9="",E9="",C9="",NOT(ISNUMBER($U$2))),"",ROUND(E9*C9*$U$2,2)) | H9: =IF(OR(A9="",G9="",C9="",NOT(ISNUMBER($U$3))),"",ROUND(G9*C9*$U$3,2)) | J9: =IF(OR(A9="",I9="",C9="",NOT(ISNUMBER($U$4))),"",ROUND(I9*C9*$U$4,2)) | L9: =IF(OR(A9="",K9="",C9="",NOT(ISNUMBER($U$5))),"",ROUND(K9*C9*$U$5,2)) | N9: =IF(OR(A9="",M9="",C9="",NOT(ISNUMBER($U$6))),"",ROUND(M9*C9*$U$6,2)) | O9: =IF(A9="","",SUM(E9,G9,I9,K9,M9)) | P9: =IF(A9="","",SUM(F9,H9,J9,L9,N9)) | Q9: =IF(A9="","",IF(O9>B9,"DIVERGENCIA: CONSUMO MAIOR QUE CONTRATADO","OK"))
D10: =IF(OR(A10="",B10="",C10=""),"",ROUND(B10*C10,2)) | F10: =IF(OR(A10="",E10="",C10="",NOT(ISNUMBER($U$2))),"",ROUND(E10*C10*$U$2,2)) | H10: =IF(OR(A10="",G10="",C10="",NOT(ISNUMBER($U$3))),"",ROUND(G10*C10*$U$3,2)) | J10: =IF(OR(A10="",I10="",C10="",NOT(ISNUMBER($U$4))),"",ROUND(I10*C10*$U$4,2)) | L10: =IF(OR(A10="",K10="",C10="",NOT(ISNUMBER($U$5))),"",ROUND(K10*C10*$U$5,2)) | N10: =IF(OR(A10="",M10="",C10="",NOT(ISNUMBER($U$6))),"",ROUND(M10*C10*$U$6,2)) | O10: =IF(A10="","",SUM(E10,G10,I10,K10,M10)) | P10: =IF(A10="","",SUM(F10,H10,J10,L10,N10)) | Q10: =IF(A10="","",IF(O10>B10,"DIVERGENCIA: CONSUMO MAIOR QUE CONTRATADO","OK"))
D11: =IF(OR(A11="",B11="",C11=""),"",ROUND(B11*C11,2)) | F11: =IF(OR(A11="",E11="",C11="",NOT(ISNUMBER($U$2))),"",ROUND(E11*C11*$U$2,2)) | H11: =IF(OR(A11="",G11="",C11="",NOT(ISNUMBER($U$3))),"",ROUND(G11*C11*$U$3,2)) | J11: =IF(OR(A11="",I11="",C11="",NOT(ISNUMBER($U$4))),"",ROUND(I11*C11*$U$4,2)) | L11: =IF(OR(A11="",K11="",C11="",NOT(ISNUMBER($U$5))),"",ROUND(K11*C11*$U$5,2)) | N11: =IF(OR(A11="",M11="",C11="",NOT(ISNUMBER($U$6))),"",ROUND(M11*C11*$U$6,2)) | O11: =IF(A11="","",SUM(E11,G11,I11,K11,M11)) | P11: =IF(A11="","",SUM(F11,H11,J11,L11,N11)) | Q11: =IF(A11="","",IF(O11>B11,"DIVERGENCIA: CONSUMO MAIOR QUE CONTRATADO","OK"))
D12: =IF(OR(A12="",B12="",C12=""),"",ROUND(B12*C12,2)) | F12: =IF(OR(A12="",E12="",C12="",NOT(ISNUMBER($U$2))),"",ROUND(E12*C12*$U$2,2)) | H12: =IF(OR(A12="",G12="",C12="",NOT(ISNUMBER($U$3))),"",ROUND(G12*C12*$U$3,2)) | J12: =IF(OR(A12="",I12="",C12="",NOT(ISNUMBER($U$4))),"",ROUND(I12*C12*$U$4,2)) | L12: =IF(OR(A12="",K12="",C12="",NOT(ISNUMBER($U$5))),"",ROUND(K12*C12*$U$5,2)) | N12: =IF(OR(A12="",M12="",C12="",NOT(ISNUMBER($U$6))),"",ROUND(M12*C12*$U$6,2)) | O12: =IF(A12="","",SUM(E12,G12,I12,K12,M12)) | P12: =IF(A12="","",SUM(F12,H12,J12,L12,N12)) | Q12: =IF(A12="","",IF(O12>B12,"DIVERGENCIA: CONSUMO MAIOR QUE CONTRATADO","OK"))
D13: =IF(OR(A13="",B13="",C13=""),"",ROUND(B13*C13,2)) | F13: =IF(OR(A13="",E13="",C13="",NOT(ISNUMBER($U$2))),"",ROUND(E13*C13*$U$2,2)) | H13: =IF(OR(A13="",G13="",C13="",NOT(ISNUMBER($U$3))),"",ROUND(G13*C13*$U$3,2)) | J13: =IF(OR(A13="",I13="",C13="",NOT(ISNUMBER($U$4))),"",ROUND(I13*C13*$U$4,2)) | L13: =IF(OR(A13="",K13="",C13="",NOT(ISNUMBER($U$5))),"",ROUND(K13*C13*$U$5,2)) | N13: =IF(OR(A13="",M13="",C13="",NOT(ISNUMBER($U$6))),"",ROUND(M13*C13*$U$6,2)) | O13: =IF(A13="","",SUM(E13,G13,I13,K13,M13)) | P13: =IF(A13="","",SUM(F13,H13,J13,L13,N13)) | Q13: =IF(A13="","",IF(O13>B13,"DIVERGENCIA: CONSUMO MAIOR QUE CONTRATADO","OK"))
D14: =IF(OR(A14="",B14="",C14=""),"",ROUND(B14*C14,2)) | F14: =IF(OR(A14="",E14="",C14="",NOT(ISNUMBER($U$2))),"",ROUND(E14*C14*$U$2,2)) | H14: =IF(OR(A14="",G14="",C14="",NOT(ISNUMBER($U$3))),"",ROUND(G14*C14*$U$3,2)) | J14: =IF(OR(A14="",I14="",C14="",NOT(ISNUMBER($U$4))),"",ROUND(I14*C14*$U$4,2)) | L14: =IF(OR(A14="",K14="",C14="",NOT(ISNUMBER($U$5))),"",ROUND(K14*C14*$U$5,2)) | N14: =IF(OR(A14="",M14="",C14="",NOT(ISNUMBER($U$6))),"",ROUND(M14*C14*$U$6,2)) | O14: =IF(A14="","",SUM(E14,G14,I14,K14,M14)) | P14: =IF(A14="","",SUM(F14,H14,J14,L14,N14)) | Q14: =IF(A14="","",IF(O14>B14,"DIVERGENCIA: CONSUMO MAIOR QUE CONTRATADO","OK"))
D15: =IF(OR(A15="",B15="",C15=""),"",ROUND(B15*C15,2)) | F15: =IF(OR(A15="",E15="",C15="",NOT(ISNUMBER($U$2))),"",ROUND(E15*C15*$U$2,2)) | H15: =IF(OR(A15="",G15="",C15="",NOT(ISNUMBER($U$3))),"",ROUND(G15*C15*$U$3,2)) | J15: =IF(OR(A15="",I15="",C15="",NOT(ISNUMBER($U$4))),"",ROUND(I15*C15*$U$4,2)) | L15: =IF(OR(A15="",K15="",C15="",NOT(ISNUMBER($U$5))),"",ROUND(K15*C15*$U$5,2)) | N15: =IF(OR(A15="",M15="",C15="",NOT(ISNUMBER($U$6))),"",ROUND(M15*C15*$U$6,2)) | O15: =IF(A15="","",SUM(E15,G15,I15,K15,M15)) | P15: =IF(A15="","",SUM(F15,H15,J15,L15,N15)) | Q15: =IF(A15="","",IF(O15>B15,"DIVERGENCIA: CONSUMO MAIOR QUE CONTRATADO","OK"))
D16: =IF(OR(A16="",B16="",C16=""),"",ROUND(B16*C16,2)) | F16: =IF(OR(A16="",E16="",C16="",NOT(ISNUMBER($U$2))),"",ROUND(E16*C16*$U$2,2)) | H16: =IF(OR(A16="",G16="",C16="",NOT(ISNUMBER($U$3))),"",ROUND(G16*C16*$U$3,2)) | J16: =IF(OR(A16="",I16="",C16="",NOT(ISNUMBER($U$4))),"",ROUND(I16*C16*$U$4,2)) | L16: =IF(OR(A16="",K16="",C16="",NOT(ISNUMBER($U$5))),"",ROUND(K16*C16*$U$5,2)) | N16: =IF(OR(A16="",M16="",C16="",NOT(ISNUMBER($U$6))),"",ROUND(M16*C16*$U$6,2)) | O16: =IF(A16="","",SUM(E16,G16,I16,K16,M16)) | P16: =IF(A16="","",SUM(F16,H16,J16,L16,N16)) | Q16: =IF(A16="","",IF(O16>B16,"DIVERGENCIA: CONSUMO MAIOR QUE CONTRATADO","OK"))
D17: =IF(OR(A17="",B17="",C17=""),"",ROUND(B17*C17,2)) | F17: =IF(OR(A17="",E17="",C17="",NOT(ISNUMBER($U$2))),"",ROUND(E17*C17*$U$2,2)) | H17: =IF(OR(A17="",G17="",C17="",NOT(ISNUMBER($U$3))),"",ROUND(G17*C17*$U$3,2)) | J17: =IF(OR(A17="",I17="",C17="",NOT(ISNUMBER($U$4))),"",ROUND(I17*C17*$U$4,2)) | L17: =IF(OR(A17="",K17="",C17="",NOT(ISNUMBER($U$5))),"",ROUND(K17*C17*$U$5,2)) | N17: =IF(OR(A17="",M17="",C17="",NOT(ISNUMBER($U$6))),"",ROUND(M17*C17*$U$6,2)) | O17: =IF(A17="","",SUM(E17,G17,I17,K17,M17)) | P17: =IF(A17="","",SUM(F17,H17,J17,L17,N17)) | Q17: =IF(A17="","",IF(O17>B17,"DIVERGENCIA: CONSUMO MAIOR QUE CONTRATADO","OK"))
D18: =IF(OR(A18="",B18="",C18=""),"",ROUND(B18*C18,2)) | F18: =IF(OR(A18="",E18="",C18="",NOT(ISNUMBER($U$2))),"",ROUND(E18*C18*$U$2,2)) | H18: =IF(OR(A18="",G18="",C18="",NOT(ISNUMBER($U$3))),"",ROUND(G18*C18*$U$3,2)) | J18: =IF(OR(A18="",I18="",C18="",NOT(ISNUMBER($U$4))),"",ROUND(I18*C18*$U$4,2)) | L18: =IF(OR(A18="",K18="",C18="",NOT(ISNUMBER($U$5))),"",ROUND(K18*C18*$U$5,2)) | N18: =IF(OR(A18="",M18="",C18="",NOT(ISNUMBER($U$6))),"",ROUND(M18*C18*$U$6,2)) | O18: =IF(A18="","",SUM(E18,G18,I18,K18,M18)) | P18: =IF(A18="","",SUM(F18,H18,J18,L18,N18)) | Q18: =IF(A18="","",IF(O18>B18,"DIVERGENCIA: CONSUMO MAIOR QUE CONTRATADO","OK"))
... D200: =IF(OR(A200="",B200="",C200=""),"",ROUND(B200*C200,2)) | F200: =IF(OR(A200="",E200="",C200="",NOT(ISNUMBER($U$2))),"",ROUND(E200*C200*$U$2,2)) | H200: =IF(OR(A200="",G200="",C200="",NOT(ISNUMBER($U$3))),"",ROUND(G200*C200*$U$3,2)) | J200: =IF(OR(A200="",I200="",C200="",NOT(ISNUMBER($U$4))),"",ROUND(I200*C200*$U$4,2)) | L200: =IF(OR(A200="",K200="",C200="",NOT(ISNUMBER($U$5))),"",ROUND(K200*C200*$U$5,2)) | N200: =IF(OR(A200="",M200="",C200="",NOT(ISNUMBER($U$6))),"",ROUND(M200*C200*$U$6,2)) | O200: =IF(A200="","",SUM(E200,G200,I200,K200,M200)) | P200: =IF(A200="","",SUM(F200,H200,J200,L200,N200)) | Q200: =IF(A200="","",IF(O200>B200,"DIVERGENCIA: CONSUMO MAIOR QUE CONTRATADO","OK"))

Sheet itens_PC
A1: ITEM | B1: NUMERO_PC | C1: DATA_PC | D1: CICLO_PC | E1: VALOR_PC | F1: FATOR_ACUMULADO | G1: VALOR_ATUALIZADO | H1: PC_PAGO_A_CONTRATADA | I1: RETROATIVO_RECONHECIDO_A_PAGAR | J1: VALOR_ATUALIZADO_EM_ANALISE | K1: DELTA_POTENCIAL | L1: CHECK_PC_FINANCEIRO | N1: CICLO | O1: QTD_PC | P1: VALOR_PC_TOTAL | Q1: VALOR_ATUALIZADO_TOTAL | R1: RETROATIVO_RECONHECIDO_A_PAGAR | S1: VALOR_ATUALIZADO_EM_ANALISE | T1: DELTA_POTENCIAL | U1: QTD_COM_CHECK | W1: COMPUTA_VTA | X1: TIPO_PARCELA | Y1: ORIGEM_DADO | Z1: TIPO_FINANCEIRO | AA1: FONTE_PARCELA | AB1: JA_REFLETIDO_EM | AC1: STATUS_CONSOLIDACAO | AD1: JUSTIFICATIVA_VTA
D2: =IF(C2="","",IF(OR(C2<MIN(parametros!$D$2:$D$6),C2>MAX(parametros!$E$2:$E$6)),"Fora dos ciclos",LOOKUP(C2,parametros!$D$2:$D$6,parametros!$B$2:$B$6))) | F2: =IF(D2="","",IFERROR(VLOOKUP(D2,parametros!$A$11:$E$15,5,0),"")) | G2: =IF(OR(E2="",F2=""),"",ROUND(E2*F2,2)) | I2: =IF(H2="Sim",IF(OR(G2="",E2=""),"",ROUND(G2-E2,2)),0) | J2: =IF(H2="Nao",IF(G2="","",G2),0) | K2: =IF(H2="Nao",IF(OR(G2="",E2=""),"",ROUND(G2-E2,2)),0) | L2: =IF(COUNTA(A2:H2)=0,"",IF(C2="","DATA_PC vazia",IF(OR(D2="",D2="Fora dos ciclos"),"CICLO_PC nao identificado",IF(OR(E2="",E2=0),"VALOR_PC vazio ou zero",IF(AND(H2<>"Sim",H2<>"Nao"),"PC_PAGO_A_CONTRATADA invalido","OK"))))) | N2: C0 | O2: =COUNTIF($D$2:$D$100,N2) | P2: =SUMIF($D$2:$D$100,N2,$E$2:$E$100) | Q2: =SUMIF($D$2:$D$100,N2,$G$2:$G$100) | R2: =SUMIF($D$2:$D$100,N2,$I$2:$I$100) | S2: =SUMIF($D$2:$D$100,N2,$J$2:$J$100) | T2: =SUMIF($D$2:$D$100,N2,$K$2:$K$100) | U2: =COUNTIFS($D$2:$D$100,N2,$L$2:$L$100,"<>OK",$L$2:$L$100,"<>") | W2: Nao | X2: PC em analise | Y2: Pedido de Compra | Z2: Impacto Potencial | AA2: PC | AB2: Nao | AC2: NAO_COMPUTADO | AD2: Estrutura Fase 1: sem impacto no VTA oficial
D3: =IF(C3="","",IF(OR(C3<MIN(parametros!$D$2:$D$6),C3>MAX(parametros!$E$2:$E$6)),"Fora dos ciclos",LOOKUP(C3,parametros!$D$2:$D$6,parametros!$B$2:$B$6))) | F3: =IF(D3="","",IFERROR(VLOOKUP(D3,parametros!$A$11:$E$15,5,0),"")) | G3: =IF(OR(E3="",F3=""),"",ROUND(E3*F3,2)) | I3: =IF(H3="Sim",IF(OR(G3="",E3=""),"",ROUND(G3-E3,2)),0) | J3: =IF(H3="Nao",IF(G3="","",G3),0) | K3: =IF(H3="Nao",IF(OR(G3="",E3=""),"",ROUND(G3-E3,2)),0) | L3: =IF(COUNTA(A3:H3)=0,"",IF(C3="","DATA_PC vazia",IF(OR(D3="",D3="Fora dos ciclos"),"CICLO_PC nao identificado",IF(OR(E3="",E3=0),"VALOR_PC vazio ou zero",IF(AND(H3<>"Sim",H3<>"Nao"),"PC_PAGO_A_CONTRATADA invalido","OK"))))) | N3: C1 | O3: =COUNTIF($D$2:$D$100,N3) | P3: =SUMIF($D$2:$D$100,N3,$E$2:$E$100) | Q3: =SUMIF($D$2:$D$100,N3,$G$2:$G$100) | R3: =SUMIF($D$2:$D$100,N3,$I$2:$I$100) | S3: =SUMIF($D$2:$D$100,N3,$J$2:$J$100) | T3: =SUMIF($D$2:$D$100,N3,$K$2:$K$100) | U3: =COUNTIFS($D$2:$D$100,N3,$L$2:$L$100,"<>OK",$L$2:$L$100,"<>") | W3: Nao | X3: PC em analise | Y3: Pedido de Compra | Z3: Impacto Potencial | AA3: PC | AB3: Nao | AC3: NAO_COMPUTADO | AD3: Estrutura Fase 1: sem impacto no VTA oficial
D4: =IF(C4="","",IF(OR(C4<MIN(parametros!$D$2:$D$6),C4>MAX(parametros!$E$2:$E$6)),"Fora dos ciclos",LOOKUP(C4,parametros!$D$2:$D$6,parametros!$B$2:$B$6))) | F4: =IF(D4="","",IFERROR(VLOOKUP(D4,parametros!$A$11:$E$15,5,0),"")) | G4: =IF(OR(E4="",F4=""),"",ROUND(E4*F4,2)) | I4: =IF(H4="Sim",IF(OR(G4="",E4=""),"",ROUND(G4-E4,2)),0) | J4: =IF(H4="Nao",IF(G4="","",G4),0) | K4: =IF(H4="Nao",IF(OR(G4="",E4=""),"",ROUND(G4-E4,2)),0) | L4: =IF(COUNTA(A4:H4)=0,"",IF(C4="","DATA_PC vazia",IF(OR(D4="",D4="Fora dos ciclos"),"CICLO_PC nao identificado",IF(OR(E4="",E4=0),"VALOR_PC vazio ou zero",IF(AND(H4<>"Sim",H4<>"Nao"),"PC_PAGO_A_CONTRATADA invalido","OK"))))) | N4: C2 | O4: =COUNTIF($D$2:$D$100,N4) | P4: =SUMIF($D$2:$D$100,N4,$E$2:$E$100) | Q4: =SUMIF($D$2:$D$100,N4,$G$2:$G$100) | R4: =SUMIF($D$2:$D$100,N4,$I$2:$I$100) | S4: =SUMIF($D$2:$D$100,N4,$J$2:$J$100) | T4: =SUMIF($D$2:$D$100,N4,$K$2:$K$100) | U4: =COUNTIFS($D$2:$D$100,N4,$L$2:$L$100,"<>OK",$L$2:$L$100,"<>") | W4: Nao | X4: PC em analise | Y4: Pedido de Compra | Z4: Impacto Potencial | AA4: PC | AB4: Nao | AC4: NAO_COMPUTADO | AD4: Estrutura Fase 1: sem impacto no VTA oficial
D5: =IF(C5="","",IF(OR(C5<MIN(parametros!$D$2:$D$6),C5>MAX(parametros!$E$2:$E$6)),"Fora dos ciclos",LOOKUP(C5,parametros!$D$2:$D$6,parametros!$B$2:$B$6))) | F5: =IF(D5="","",IFERROR(VLOOKUP(D5,parametros!$A$11:$E$15,5,0),"")) | G5: =IF(OR(E5="",F5=""),"",ROUND(E5*F5,2)) | I5: =IF(H5="Sim",IF(OR(G5="",E5=""),"",ROUND(G5-E5,2)),0) | J5: =IF(H5="Nao",IF(G5="","",G5),0) | K5: =IF(H5="Nao",IF(OR(G5="",E5=""),"",ROUND(G5-E5,2)),0) | L5: =IF(COUNTA(A5:H5)=0,"",IF(C5="","DATA_PC vazia",IF(OR(D5="",D5="Fora dos ciclos"),"CICLO_PC nao identificado",IF(OR(E5="",E5=0),"VALOR_PC vazio ou zero",IF(AND(H5<>"Sim",H5<>"Nao"),"PC_PAGO_A_CONTRATADA invalido","OK"))))) | N5: C3 | O5: =COUNTIF($D$2:$D$100,N5) | P5: =SUMIF($D$2:$D$100,N5,$E$2:$E$100) | Q5: =SUMIF($D$2:$D$100,N5,$G$2:$G$100) | R5: =SUMIF($D$2:$D$100,N5,$I$2:$I$100) | S5: =SUMIF($D$2:$D$100,N5,$J$2:$J$100) | T5: =SUMIF($D$2:$D$100,N5,$K$2:$K$100) | U5: =COUNTIFS($D$2:$D$100,N5,$L$2:$L$100,"<>OK",$L$2:$L$100,"<>") | W5: Nao | X5: PC em analise | Y5: Pedido de Compra | Z5: Impacto Potencial | AA5: PC | AB5: Nao | AC5: NAO_COMPUTADO | AD5: Estrutura Fase 1: sem impacto no VTA oficial
D6: =IF(C6="","",IF(OR(C6<MIN(parametros!$D$2:$D$6),C6>MAX(parametros!$E$2:$E$6)),"Fora dos ciclos",LOOKUP(C6,parametros!$D$2:$D$6,parametros!$B$2:$B$6))) | F6: =IF(D6="","",IFERROR(VLOOKUP(D6,parametros!$A$11:$E$15,5,0),"")) | G6: =IF(OR(E6="",F6=""),"",ROUND(E6*F6,2)) | I6: =IF(H6="Sim",IF(OR(G6="",E6=""),"",ROUND(G6-E6,2)),0) | J6: =IF(H6="Nao",IF(G6="","",G6),0) | K6: =IF(H6="Nao",IF(OR(G6="",E6=""),"",ROUND(G6-E6,2)),0) | L6: =IF(COUNTA(A6:H6)=0,"",IF(C6="","DATA_PC vazia",IF(OR(D6="",D6="Fora dos ciclos"),"CICLO_PC nao identificado",IF(OR(E6="",E6=0),"VALOR_PC vazio ou zero",IF(AND(H6<>"Sim",H6<>"Nao"),"PC_PAGO_A_CONTRATADA invalido","OK"))))) | N6: C4 | O6: =COUNTIF($D$2:$D$100,N6) | P6: =SUMIF($D$2:$D$100,N6,$E$2:$E$100) | Q6: =SUMIF($D$2:$D$100,N6,$G$2:$G$100) | R6: =SUMIF($D$2:$D$100,N6,$I$2:$I$100) | S6: =SUMIF($D$2:$D$100,N6,$J$2:$J$100) | T6: =SUMIF($D$2:$D$100,N6,$K$2:$K$100) | U6: =COUNTIFS($D$2:$D$100,N6,$L$2:$L$100,"<>OK",$L$2:$L$100,"<>") | W6: Nao | X6: PC em analise | Y6: Pedido de Compra | Z6: Impacto Potencial | AA6: PC | AB6: Nao | AC6: NAO_COMPUTADO | AD6: Estrutura Fase 1: sem impacto no VTA oficial
D7: =IF(C7="","",IF(OR(C7<MIN(parametros!$D$2:$D$6),C7>MAX(parametros!$E$2:$E$6)),"Fora dos ciclos",LOOKUP(C7,parametros!$D$2:$D$6,parametros!$B$2:$B$6))) | F7: =IF(D7="","",IFERROR(VLOOKUP(D7,parametros!$A$11:$E$15,5,0),"")) | G7: =IF(OR(E7="",F7=""),"",ROUND(E7*F7,2)) | I7: =IF(H7="Sim",IF(OR(G7="",E7=""),"",ROUND(G7-E7,2)),0) | J7: =IF(H7="Nao",IF(G7="","",G7),0) | K7: =IF(H7="Nao",IF(OR(G7="",E7=""),"",ROUND(G7-E7,2)),0) | L7: =IF(COUNTA(A7:H7)=0,"",IF(C7="","DATA_PC vazia",IF(OR(D7="",D7="Fora dos ciclos"),"CICLO_PC nao identificado",IF(OR(E7="",E7=0),"VALOR_PC vazio ou zero",IF(AND(H7<>"Sim",H7<>"Nao"),"PC_PAGO_A_CONTRATADA invalido","OK"))))) | N7: TOTAL | O7: =SUM(O2:O6) | P7: =SUM(P2:P6) | Q7: =SUM(Q2:Q6) | R7: =SUM(R2:R6) | S7: =SUM(S2:S6) | T7: =SUM(T2:T6) | U7: =SUM(U2:U6) | W7: Nao | X7: PC em analise | Y7: Pedido de Compra | Z7: Impacto Potencial | AA7: PC | AB7: Nao | AC7: NAO_COMPUTADO | AD7: Estrutura Fase 1: sem impacto no VTA oficial
D8: =IF(C8="","",IF(OR(C8<MIN(parametros!$D$2:$D$6),C8>MAX(parametros!$E$2:$E$6)),"Fora dos ciclos",LOOKUP(C8,parametros!$D$2:$D$6,parametros!$B$2:$B$6))) | F8: =IF(D8="","",IFERROR(VLOOKUP(D8,parametros!$A$11:$E$15,5,0),"")) | G8: =IF(OR(E8="",F8=""),"",ROUND(E8*F8,2)) | I8: =IF(H8="Sim",IF(OR(G8="",E8=""),"",ROUND(G8-E8,2)),0) | J8: =IF(H8="Nao",IF(G8="","",G8),0) | K8: =IF(H8="Nao",IF(OR(G8="",E8=""),"",ROUND(G8-E8,2)),0) | L8: =IF(COUNTA(A8:H8)=0,"",IF(C8="","DATA_PC vazia",IF(OR(D8="",D8="Fora dos ciclos"),"CICLO_PC nao identificado",IF(OR(E8="",E8=0),"VALOR_PC vazio ou zero",IF(AND(H8<>"Sim",H8<>"Nao"),"PC_PAGO_A_CONTRATADA invalido","OK"))))) | W8: Nao | X8: PC em analise | Y8: Pedido de Compra | Z8: Impacto Potencial | AA8: PC | AB8: Nao | AC8: NAO_COMPUTADO | AD8: Estrutura Fase 1: sem impacto no VTA oficial
